Workbook
Name compound_period: Seller_Note_Schedule!$D$17
Name fpdate: Seller_Note_Schedule!$D$11
Name loan_amount: Seller_Note_Schedule!$D$8
Name months_per_period: Seller_Note_Schedule!$D$19
Name nper: Seller_Note_Schedule!$D$20
Name payment: Seller_Note_Schedule!$D$23
Name periods_per_year: Seller_Note_Schedule!$D$16
Name pmtType: Seller_Note_Schedule!$D$18
Name rate: Seller_Note_Schedule!$H$8
Name roundOpt: Seller_Note_Schedule!$D$21
Name term: Seller_Note_Schedule!$D$10

Sheet Summary
B2: Summary
Q17: Estimated 10 minute driving distance from Organic Farms
Q22: Estimated 20-30 minute driving distance from Organic Farms
Q28: Pistil Data Report Summary | T28: Latest 3-months | U28: Annualized Revenue (based on latest 3-months)
Q29: Cuzzie's Dispensary | T29: 200100 | U29: =T29*4 -> 800400
Q30: Indigo | T30: 6680200 | U30: =T30*4 -> 26720800
Q31: Curaleaf - Belmawr | T31: 2889200 | U31: =T31*4 -> 11556800
Q32: Nova Farms | T32: 3751700 | U32: =T32*4 -> 15006800
Q33: Organic Farms | T33: 825000 | U33: =T33*4 -> 3300000
Q34: *Data as of 7/15/25
B40: Current Terms

Sheet Offering & Cap Table
B2: CAP TABLE
B4: Capital Needs | F4: Shareholder | G4: Investment Amount | H4: Ownership % | I4: Shares*
B5: Equity Acquisition | C5: 700000 | F5: Rich Existing | G5: 0 | H5: 0.05 | I5: 50000
B6: Working Capital | C6: 300000 | F6: Rich | G6: 250000 | H6: =G6/$I$11 -> 0.2375 | I6: 237500
B7: Total | C7: =SUM(C5:C6) -> 1000000 | F7: Rob | G7: 350000 | H7: =G7/$I$11 -> 0.3325 | I7: 237500
F8: Anand | G8: 100000 | H8: =G8/$I$11 -> 0.095 | I8: 95000
F9: Other | G9: 300000 | H9: =G9/$I$11 -> 0.285 | I9: 380000
F10: Total | G10: =SUM(G5:G9) -> 1000000 | H10: 1 | I10: =SUM(I5:I9) -> 1000000
F11: Valuation | I11: =G10/0.95 -> 1052631.6 | J11: (1M coming in for 95% since RJ gets 5% out of the gate)
C13: Return on Invested Capital
B14: Net Revenues | C14: ='P&L 2025Q1'!X10 -> 2995998.8 | D14: ='P&L 2025Q1'!Y10 -> 3445398.6 | E14: ='P&L 2025Q1'!Z10 -> 3744998.5 | F14: ='P&L 2025Q1'!AA10 -> 4044598.3 | G14: ='P&L 2025Q1'!AB10 -> 5093197.9 | H14: ='P&L 2025Q1'!AC10 -> 8987996.3
B15: Valuation Min | C15: ='P&L 2025Q1'!X55 -> 1881157.2 | D15: ='P&L 2025Q1'!Y55 -> 2503648.8 | E15: ='P&L 2025Q1'!Z55 -> 2938483.2 | F15: ='P&L 2025Q1'!AA55 -> 3373317.5 | G15: ='P&L 2025Q1'!AB55 -> 4895237.8 | H15: ='P&L 2025Q1'!AC55 -> 8987996.3
B16: Equity Investor Payback | C16: =$I$11 -> 1052631.6 | D16: =$I$11 -> 1052631.6 | E16: =$I$11 -> 1052631.6 | F16: =$I$11 -> 1052631.6 | G16: =$I$11 -> 1052631.6 | H16: =$I$11 -> 1052631.6
B17: Management Fee* (30%) | C17: =0.3*(C15-C16) -> 248557.68 | D17: =0.3*(D15-D16) -> 435305.17 | E17: =0.3*(E15-E16) -> 565755.47 | F17: =0.3*(F15-F16) -> 696205.78 | G17: =0.3*(G15-G16) -> 1152781.9 | H17: =0.3*(H15-H16) -> 2380609.4
B18: Net Return to Investors | C18: =C15-C17 -> 1632599.5 | D18: =D15-D17 -> 2068343.6 | E18: =E15-E17 -> 2372727.7 | F18: =F15-F17 -> 2677111.7 | G18: =G15-G17 -> 3742455.9 | H18: =H15-H17 -> 6607386.9
B19: ROIC for Investors | C19: =C18/$I$10 -> 1.6325995 | D19: =D18/$I$10 -> 2.0683436 | E19: =E18/$I$10 -> 2.3727277 | F19: =F18/$I$10 -> 2.6771117 | G19: =G18/$I$10 -> 3.7424559 | H19: =H18/$I$10 -> 6.6073869
C21: *Management would get 30% of capital gains beyond the initial capital return to investor as carried interest.
C22: Above analysis assumes that the full Seller Note has been paid back from cash flows already

Sheet P&L 2025Q1
A1: Net Revenue Growth | W1: Net Revenue Growth | X1: 0 | Y1: 0.15 | Z1: 0.25 | AA1: 0.35 | AB1: 0.7 | AC1: 2
A2: Improvement Multiple | W2: Improvement Multiple | X2: =1+X1 -> 1 | Y2: =1+Y1 -> 1.15 | Z2: =1+Z1 -> 1.25 | AA2: =1+AA1 -> 1.35 | AB2: =1+AB1 -> 1.7 | AC2: =1+AC1 -> 3
A3: Net Cash Flow Margin | W3: Net Cash Flow Margin | X3: =X49/X13 -> -0.018778914 | Y3: =Y49/Y13 -> 0.025958375 | Z3: =Z49/Z13 -> 0.051058231 | AA3: =AA49/AA13 -> 0.07243959 | AB3: =AB49/AB13 -> 0.12746515 | AC3: =AC49/AC13 -> 0.21943643
A5: Net Revenue | W5: Net Revenue | X5: =X10 -> 2995998.8 | Y5: =Y10 -> 3445398.6 | Z5: =Z10 -> 3744998.5 | AA5: =AA10 -> 4044598.3 | AB5: =AB10 -> 5093197.9 | AC5: =AC10 -> 8987996.3
A6: Net Cash Flow (after seller note & taxes) | W6: Net Cash Flow (after seller note & taxes) | X6: =X49 -> -56688.579 | Y6: =Y49 -> 90115.693 | Z6: =Z49 -> 192664.13 | AA6: =AA49 -> 295212.57 | AB6: =AB49 -> 654132.1 | AC6: =AC49 -> 1987261.8
A7: Organic Farms Corporation Profit and Loss
D8: Q1 2024 | I8: Q2 2024 | N8: Q3 2024 | R8: Q4 2024 | T8: Q1 2025 | V8: Full Year 2024 | W8: Notes | X8: Annualized Estimates Post Acquisition | Y8: Annualized Estimates Post Acquisition | Z8: Annualized Estimates Post Acquisition | AA8: Annualized Estimates Post Acquisition | AB8: Annualized Estimates Post Acquisition | AC8: Annualized Estimates Post Acquisition
A9: Income
A10: Sales of Cannabis Product Income* | D10: 755693.88 | I10: 757536.42 | N10: 742164.78 | R10: 740603.68 | T10: 740598.18 | V10: =SUM(D10:R10) -> 2995998.8 | W10: *Net of sales discounts, NJ revenue tax at 6.625% and municipal tax of 2% of gross revenues. Taxes are based on what you receive in net of discounts. | X10: =$V$10*X2 -> 2995998.8 | Y10: =$V$10*Y2 -> 3445398.6 | Z10: =$V$10*Z2 -> 3744998.5 | AA10: =$V$10*AA2 -> 4044598.3 | AB10: =$V$10*AB2 -> 5093197.9 | AC10: =$V$10*AC2 -> 8987996.3
A11: Accessory Sales | D11: 6244.7 | I11: 6831.22 | N11: 5455.42 | R11: 4205.59 | T11: 5142.41 | V11: =SUM(D11:R11) -> 22736.93 | X11: =$V$11*X2 -> 22736.93 | Y11: =$V$11*Y2 -> 26147.469 | Z11: =$V$11*Z2 -> 28421.162 | AA11: =$V$11*AA2 -> 30694.856 | AB11: =$V$11*AB2 -> 38652.781 | AC11: =$V$11*AC2 -> 68210.79
A12: Card Activation Fees | D12: 8280 | I12: 9571.5 | N12: 7098 | R12: 1501.5 | T12: 0 | V12: =SUM(D12:R12) -> 26451 | W12: Should not apply going forward | X12: 0 | Y12: 0 | Z12: 0 | AA12: 0 | AB12: 0 | AC12: 0
A13: Total Income | D13: 770218.58 | I13: 773939.14 | N13: 754718.2 | R13: 746310.77 | T13: 745740.59 | V13: =SUM(V10:V12) -> 3045186.7 | X13: =SUM(X10:X12) -> 3018735.7 | Y13: =SUM(Y10:Y12) -> 3471546 | Z13: =SUM(Z10:Z12) -> 3773419.6 | AA13: =SUM(AA10:AA12) -> 4075293.2 | AB13: =SUM(AB10:AB12) -> 5131850.7 | AC13: =SUM(AC10:AC12) -> 9056207.1
A14: Cost of Goods Sold | D14: 460435.61 | I14: 453744.3 | N14: 441475.63 | R14: 456057.64 | T14: 451526.24 | V14: =SUM(D14:R14) -> 1811713.2 | X14: =+X13*0.5 -> 1509367.8 | Y14: =+Y13*0.5 -> 1735773 | Z14: =+Z13*0.5 -> 1886709.8 | AA14: =+AA13*0.5 -> 2037646.6 | AB14: =+AB13*0.5 -> 2565925.3 | AC14: =+AC13*0.5 -> 4528103.5
A15: Gross Profit | D15: 309782.97 | I15: 320194.84 | N15: 313242.57 | R15: 290253.13 | T15: 294214.35 | V15: =SUM(D15:R15) -> 1233473.5 | X15: =X13-X14 -> 1509367.8 | Y15: =Y13-Y14 -> 1735773 | Z15: =Z13-Z14 -> 1886709.8 | AA15: =AA13-AA14 -> 2037646.6 | AB15: =AB13-AB14 -> 2565925.3 | AC15: =AC13-AC14 -> 4528103.5
A17: Expenses
A18: Advertising Expense | D18: 21986.78 | I18: 21717.74 | N18: 19697.42 | R18: 7346.64 | T18: 2448.16 | V18: =SUM(D18:R18) -> 70748.58 | W18: We will deploy in $50k increments as long as it is returning proper revenue bump | X18: 50000 | Y18: =Y10*0.02 -> 68907.971 | Z18: =Z10*0.02 -> 74899.969 | AA18: =AA10*0.02 -> 80891.967 | AB18: =AB10*0.02 -> 101863.96 | AC18: =AC10*0.02 -> 179759.93
A19: Bank Fees and Cash Services | D19: 3650.14 | I19: 1811.26 | N19: 1865.53 | R19: 2361.12 | T19: 3933.43 | V19: =SUM(D19:R19) -> 9688.05 | X19: =$V$19 -> 9688.05 | Y19: =$V$19 -> 9688.05 | Z19: =$V$19 -> 9688.05 | AA19: =$V$19 -> 9688.05 | AB19: =$V$19 -> 9688.05 | AC19: =$V$19 -> 9688.05
A20: Communication | D20: 874.11 | I20: 1607.71 | N20: 1470.19 | R20: 2631 | T20: 1494.27 | V20: =SUM(D20:R20) -> 6583.01 | X20: =$V$20 -> 6583.01 | Y20: =$V$20 -> 6583.01 | Z20: =$V$20 -> 6583.01 | AA20: =$V$20 -> 6583.01 | AB20: =$V$20 -> 6583.01 | AC20: =$V$20 -> 6583.01
A21: Insurance | D21: 5295 | I21: 15040.56 | N21: 1765 | R21: 6399.52 | T21: 17110.5 | V21: =SUM(D21:R21) -> 28500.08 | X21: =$V$21 -> 28500.08 | Y21: =$V$21 -> 28500.08 | Z21: =$V$21 -> 28500.08 | AA21: =$V$21 -> 28500.08 | AB21: =$V$21 -> 28500.08 | AC21: =$V$21 -> 28500.08
A22: Legal & Professional Fees | D22: 5650 | I22: 27111 | N22: 12054 | R22: 8950 | T22: 8352.07 | V22: =SUM(D22:R22) -> 53765 | X22: =$V$22 -> 53765 | Y22: =$V$22 -> 53765 | Z22: =$V$22 -> 53765 | AA22: =$V$22 -> 53765 | AB22: =$V$22 -> 53765 | AC22: =$V$22 -> 53765
A23: Office/General Administrative Expenses | D23: 43833.34 | I23: 13011.75 | N23: 9426.01 | R23: 13180.84 | T23: 7983.97 | V23: =SUM(D23:R23) -> 79451.94 | X23: =$V$23 -> 79451.94 | Y23: =$V$23 -> 79451.94 | Z23: =$V$23 -> 79451.94 | AA23: =$V$23 -> 79451.94 | AB23: =$V$23 -> 79451.94 | AC23: =$V$23 -> 79451.94
A24: Payroll Expense | D24: 108593.48 | I24: 79464.91 | N24: 75542.84 | R24: 59312.63 | T24: 82773.52 | V24: =SUM(D24:R24) -> 322913.86 | W24: Sunday/Monday/Tuesday is really slow and 90% of business is in the drive thru | X24: =$V$24 -> 322913.86 | Y24: =$V$24 -> 322913.86 | Z24: =$V$24 -> 322913.86 | AA24: =$V$24 -> 322913.86 | AB24: =$V$24 -> 322913.86 | AC24: =$V$24 -> 322913.86
A25: Payroll Taxes | D25: 14994.96 | I25: 10282.88 | N25: 8051.49 | R25: 6106.64 | T25: 10227.23 | V25: =SUM(D25:R25) -> 39435.97 | X25: =$V$25 -> 39435.97 | Y25: =$V$25 -> 39435.97 | Z25: =$V$25 -> 39435.97 | AA25: =$V$25 -> 39435.97 | AB25: =$V$25 -> 39435.97 | AC25: =$V$25 -> 39435.97
A26: Rent or Lease of Buildings | D26: 15659.43 | I26: 16465.53 | N26: 16244.04 | R26: 16244.04 | T26: 16986.57 | V26: =SUM(D26:R26) -> 64613.04 | X26: =$V$26 -> 64613.04 | Y26: =$V$26 -> 64613.04 | Z26: =$V$26 -> 64613.04 | AA26: =$V$26 -> 64613.04 | AB26: =$V$26 -> 64613.04 | AC26: =$V$26 -> 64613.04
A27: Repairs and Maintenance | D27: 1499.01 | I27: 2263.29 | N27: 2456.4 | R27: 2193.5 | T27: 6960.43 | V27: =SUM(D27:R27) -> 8412.2 | X27: =$V$27 -> 8412.2 | Y27: =$V$27 -> 8412.2 | Z27: =$V$27 -> 8412.2 | AA27: =$V$27 -> 8412.2 | AB27: =$V$27 -> 8412.2 | AC27: =$V$27 -> 8412.2
A28: Software | D28: 10028.11 | I28: 4778.16 | N28: 506.88 | R28: 11302.37 | T28: 7003.01 | V28: =SUM(D28:R28) -> 26615.52 | X28: =$V$28 -> 26615.52 | Y28: =$V$28 -> 26615.52 | Z28: =$V$28 -> 26615.52 | AA28: =$V$28 -> 26615.52 | AB28: =$V$28 -> 26615.52 | AC28: =$V$28 -> 26615.52
A29: Utilities | D29: 2404.76 | I29: 2587.72 | N29: 2618.92 | R29: 725.38 | T29: 3453.67 | V29: =SUM(D29:R29) -> 8336.78 | X29: =$V$29 -> 8336.78 | Y29: =$V$29 -> 8336.78 | Z29: =$V$29 -> 8336.78 | AA29: =$V$29 -> 8336.78 | AB29: =$V$29 -> 8336.78 | AC29: =$V$29 -> 8336.78
A30: Total Expenses | D30: 234469.12 | I30: 196142.51 | N30: 151698.72 | R30: 136753.68 | T30: 168726.83 | V30: =SUM(D30:R30) -> 719064.03 | X30: =SUM(X18:X29) -> 698315.45 | Y30: =SUM(Y18:Y29) -> 717223.42 | Z30: =SUM(Z18:Z29) -> 723215.42 | AA30: =SUM(AA18:AA29) -> 729207.42 | AB30: =SUM(AB18:AB29) -> 750179.41 | AC30: =SUM(AC18:AC29) -> 828075.38
A31: Net Operating Income | D31: 75313.85 | I31: 124052.33 | N31: 161543.85 | R31: 153499.45 | T31: 125487.52 | V31: =SUM(D31:R31) -> 514409.48 | X31: =X15-X30 -> 811052.4 | Y31: =Y15-Y30 -> 1018549.6 | Z31: =Z15-Z30 -> 1163494.4 | AA31: =AA15-AA30 -> 1308439.2 | AB31: =AB15-AB30 -> 1815745.9 | AC31: =AC15-AC30 -> 3700028.2
A33: Management Expenses
A34: Consulting - Pharma Pro | D34: 44200 | I34: 44200 | N34: 44200 | R34: 45400 | T34: 30600 | V34: =SUM(D34:R34) -> 178000 | W34: Reduced due to Seller's personal staff being removed and replaced | X34: 50000 | Y34: 50000 | Z34: 50000 | AA34: 50000 | AB34: 50000 | AC34: 50000
A35: Officer Compensation | D35: 14743.62 | I35: 12796.34 | N35: 13855.33 | R35: 11886.48 | T35: 13630.57 | V35: =SUM(D35:R35) -> 53281.77 | W35: Dominic, social equity licenseholder salary expenses 64k. | X35: 64000 | Y35: 64000 | Z35: 64000 | AA35: 64000 | AB35: 64000 | AC35: 64000
A36: Security Expense | D36: 29245.52 | I36: 41802.84 | N36: 52949.29 | R36: 52240.52 | T36: 64895.34 | V36: =SUM(D36:R36) -> 176238.17 | W36: They had done too much security spend in the beginning but have paired it down now to a non-armed/non-police officer staff | X36: 70000 | Y36: 70000 | Z36: 70000 | AA36: 70000 | AB36: 70000 | AC36: 70000
A37: Total Total Management Expenses | D37: 88189.14 | I37: 98799.18 | N37: 111004.62 | R37: 109527 | T37: 109125.91 | V37: =SUM(D37:R37) -> 407519.94 | X37: =SUM(X34:X36) -> 184000 | Y37: =SUM(Y34:Y36) -> 184000 | Z37: =SUM(Z34:Z36) -> 184000 | AA37: =SUM(AA34:AA36) -> 184000 | AB37: =SUM(AB34:AB36) -> 184000 | AC37: =SUM(AC34:AC36) -> 184000
A38: EBITDA | D38: -12875.29 | I38: 25253.15 | N38: 50539.23 | R38: 43972.45 | T38: 16361.61 | V38: =SUM(D38:R38) -> 106889.54 | X38: =X31-X37 -> 627052.4 | Y38: =Y31-Y37 -> 834549.6 | Z38: =Z31-Z37 -> 979494.39 | AA38: =AA31-AA37 -> 1124439.2 | AB38: =AB31-AB37 -> 1631745.9 | AC38: =AC31-AC37 -> 3516028.2
A40: Other Expenses
A41: Amortization | D41: 1074.99 | I41: 1074.99 | N41: 1074.99 | R41: 1075.03 | T41: 1075.11 | V41: =SUM(D41:R41) -> 4300 | X41: =$V$41 -> 4300 | Y41: =$V$41 -> 4300 | Z41: =$V$41 -> 4300 | AA41: =$V$41 -> 4300 | AB41: =$V$41 -> 4300 | AC41: =$V$41 -> 4300
A42: Depreciation | D42: 10829.76 | I42: 10829.76 | N42: 10863.09 | R42: 10929.71 | T42: 10929.63 | V42: =SUM(D42:R42) -> 43452.32 | X42: =$V$42 -> 43452.32 | Y42: =$V$42 -> 43452.32 | Z42: =$V$42 -> 43452.32 | AA42: =$V$42 -> 43452.32 | AB42: =$V$42 -> 43452.32 | AC42: =$V$42 -> 43452.32
A43: Interest | D43: 37194.83 | I43: 36783.23 | N43: 35732.49 | R43: 27010.2 | T43: 25586.5 | V43: =SUM(D43:R43) -> 136720.75 | W43: Restructured seller note interest used here for tax calculation | X43: =SUM(Seller_Note_Schedule!$F$63:$F$74) -> 100965.53 | Y43: =SUM(Seller_Note_Schedule!$F$63:$F$74) -> 100965.53 | Z43: =SUM(Seller_Note_Schedule!$F$63:$F$74) -> 100965.53 | AA43: =SUM(Seller_Note_Schedule!$F$63:$F$74) -> 100965.53 | AB43: =SUM(Seller_Note_Schedule!$F$63:$F$74) -> 100965.53 | AC43: =SUM(Seller_Note_Schedule!$F$63:$F$74) -> 100965.53
A44: Taxes | D44: 0 | I44: 0 | N44: 0 | R44: 2025.12 | T44: 0 | V44: =SUM(D44:R44) -> 2025.12 | W44: Full 280E Elimination (already implemented) | X44: =+((X38-X43-X41-X42)*0.2925) -> 139912.85 | Y44: =+((Y38-Y43-Y41-Y42)*0.2925) -> 200605.79 | Z44: =+((Z38-Z43-Z41-Z42)*0.2925) -> 243002.14 | AA44: =+((AA38-AA43-AA41-AA42)*0.2925) -> 285398.49 | AB44: =+((AB38-AB43-AB41-AB42)*0.2925) -> 433785.71 | AC44: =+((AC38-AC43-AC41-AC42)*0.2925) -> 984938.27
...

Sheet Balance Sheet 2024Q4
A1: Organic Farms Corporation Balance Sheet As of December 31, 2024
A2: Total ASSETS Current Assets
B3: Cash | J3: $ | L3: 178684.17
B4: Inventory | L4: 187239.33
B5: Prepaid Expenses Fixed Assets | L5: 7993.43
B6: Furniture & Fixtures | L6: 6912.99
B7: Leasehold Improvements | L7: 478833.89
B8: Technology | L8: 79595.36
B9: Accumulated Depreciation | L9: -54138.72
B10: Total Fixed Assets | J10: $ | L10: 511203.52
B11: Security Deposit | L11: 11166.67
B12: License Acquisition Costs | L12: 59483.33
B13: TOTAL ASSETS | J13: $ | L13: 955770.45
B14: LIABILITIES AND EQUITY
A15: Liabilities Current Liabilities Accounts Payable
B16: Accounts Payable (A/P) | J16: $ | L16: 178736.87
B17: Accrued Interest | L17: 203955.41
B18: Capital One Business 4666 | L18: 3867.84
B19: Sales Taxes | L19: 54163.37
B20: Short Term Loans | L20: 250001
B21: Total Current Liabilities Long-Term Liabilities Notes Payable | J21: $ | L21: 690,724.49 989,686.46
B22: Total Long-Term Liabilities | J22: $ | L22: 989686.46
B23: Total Liabilities | J23: $ | L23: 1680410.9
B24: Equity | L24: -724640.5
B25: TOTAL LIABILITIES AND EQUITY | J25: $ | L25: 955770.45
A26: Accrued Interest, Short Term Loans, and Notes Payable will be paid off in the closing purchase of the company and will not be assumed by new ownership.

Sheet Seller_Note_Schedule
A1: Loan Amortization Schedule
A2: http://www.vertex42.com/ExcelTemplates/loan-amortization-schedule.html | H2: ="© 2008-" & YEAR(TODAY()) & " Vertex42 LLC" -> © 2008-2025 Vertex42 LLC
A7: Loan Information | F7: Summary | J7: About This Worksheet | L7: Frequency
C8: Loan Amount | D8: 1300000 | G8: Rate (per period) | H8: =((1+D9/D17)^(D17/D16))-1 -> 0.0075 | J8: This spreadsheet creates an amortization schedule for a fixed-rate loan, with optional extra payments. See the Help worksheet for more details. Edit cells within gray borders. | L8: Annual
C9: Annual Interest Rate | D9: 0.09 | G9: Total Payments | H9: =SUM(F63:F842)+SUM(G63:G842) -> 1488227.5 | L9: Semi-Annual
C10: Term of Loan in Years | D10: 3 | G10: Total Interest | H10: =SUM(F62:F842) -> 188227.51 | L10: Quarterly
C11: First Payment Date | D11: 46143 | G11: Est. Interest Savings | H11: =IF(AND(SUM(D63:D842)=0,roundOpt)," - ",(nper*(-PMT(rate,nper,loan_amount,,pmtType))-loan_amount)-H10) -> -0.021514774 | L11: Bi-Monthly
C12: Payment Frequency | D12: Monthly | H12: =IF(AND(NOT(H842=""),H842>0.004),"ERROR: Limit is "&OFFSET(A843,-1,0,1,1)&" payments",".") -> . | L12: Monthly
C13: Compound Period | D13: Monthly | H13: =IF(D17>D16,"Warning: negative amortization",".") -> . | J13: An unlocked commercial version of this template is available: | L13: Semi-Monthly
C14: Payment Type | D14: End of Period | L14: Bi-Weekly
C15: Rounding | D15: On | J15: Purchase the Unlocked Version | L15: Weekly
C16: Periods Per Year | D16: =INDEX({1;2;4;6;12;24;26;52},MATCH(Seller_Note_Schedule!$D$12,$L$8:$L$15,0)) -> 12
C17: Compound Period | D17: =INDEX({1;2;4;6;12;24;26;52},MATCH(Seller_Note_Schedule!$D$13,$L$8:$L$15,0)) -> 12
C18: Payment Type | D18: =IF(Seller_Note_Schedule!$D$14="End of Period",0,1) -> 0
C19: Months Per Period | D19: =12/$D$16 -> 1
C20: Number of Periods | D20: =$D$10*$D$16 -> 36
C21: Rounding Option | D21: =(D15="On") -> TRUE
H22: [42]
C23: =D12&" Payment" -> Monthly Payment | D23: =IF(roundOpt,ROUND(-PMT(rate,nper,$D$8,,pmtType),2),-PMT(rate,nper,$D$8,,pmtType)) -> 41339.65
A25: Yearly Summary
B26: Year | C26: Payments | D26: Additional Payments | F26: Interest Paid | G26: Principal Paid | H26: Year-End Balance | J26: Hide rows in the summary table that you do not want to display.
H27: =loan_amount -> 1300000
B28: =YEAR(fpdate) -> 2026 | C28: =SUMIF($B$62:$B$843,"<="&DATE($B28,12,31),$C$62:$C$843)-SUM(C$27:C27) -> 330717.2 | D28: =SUMIF($B$62:$B$843,"<="&DATE($B28,12,31),$D$62:$D$843)-SUM(D$27:D27) -> 0 | F28: =SUMIF($B$62:$B$843,"<="&DATE($B28,12,31),$F$62:$F$843)-SUM(F$27:F27) -> 71265.74 | G28: =SUMIF($B$62:$B$843,"<="&DATE($B28,12,31),$G$62:$G$843)-SUM(G$27:G27) -> 259451.46 | H28: =H27-G28 -> 1040548.5
B29: =B28+1 -> 2027 | C29: =SUMIF($B$62:$B$843,"<="&DATE($B29,12,31),$C$62:$C$843)-SUM(C$27:C28) -> 496075.8 | D29: =SUMIF($B$62:$B$843,"<="&DATE($B29,12,31),$D$62:$D$843)-SUM(D$27:D28) -> 0 | F29: =SUMIF($B$62:$B$843,"<="&DATE($B29,12,31),$F$62:$F$843)-SUM(F$27:F28) -> 76627.17 | G29: =SUMIF($B$62:$B$843,"<="&DATE($B29,12,31),$G$62:$G$843)-SUM(G$27:G28) -> 419448.63 | H29: =H28-G29 -> 621099.91
B30: =B29+1 -> 2028 | C30: =SUMIF($B$62:$B$843,"<="&DATE($B30,12,31),$C$62:$C$843)-SUM(C$27:C29) -> 496075.8 | D30: =SUMIF($B$62:$B$843,"<="&DATE($B30,12,31),$D$62:$D$843)-SUM(D$27:D29) -> 0 | F30: =SUMIF($B$62:$B$843,"<="&DATE($B30,12,31),$F$62:$F$843)-SUM(F$27:F29) -> 37280.03 | G30: =SUMIF($B$62:$B$843,"<="&DATE($B30,12,31),$G$62:$G$843)-SUM(G$27:G29) -> 458795.77 | H30: =H29-G30 -> 162304.14
B31: =B30+1 -> 2029 | C31: =SUMIF($B$62:$B$843,"<="&DATE($B31,12,31),$C$62:$C$843)-SUM(C$27:C30) -> 165358.71 | D31: =SUMIF($B$62:$B$843,"<="&DATE($B31,12,31),$D$62:$D$843)-SUM(D$27:D30) -> 0 | F31: =SUMIF($B$62:$B$843,"<="&DATE($B31,12,31),$F$62:$F$843)-SUM(F$27:F30) -> 3054.57 | G31: =SUMIF($B$62:$B$843,"<="&DATE($B31,12,31),$G$62:$G$843)-SUM(G$27:G30) -> 162304.14 | H31: =H30-G31 -> 0
B32: =B31+1 -> 2030 | C32: =SUMIF($B$62:$B$843,"<="&DATE($B32,12,31),$C$62:$C$843)-SUM(C$27:C31) -> 0 | D32: =SUMIF($B$62:$B$843,"<="&DATE($B32,12,31),$D$62:$D$843)-SUM(D$27:D31) -> 0 | F32: =SUMIF($B$62:$B$843,"<="&DATE($B32,12,31),$F$62:$F$843)-SUM(F$27:F31) -> 0 | G32: =SUMIF($B$62:$B$843,"<="&DATE($B32,12,31),$G$62:$G$843)-SUM(G$27:G31) -> 0 | H32: =H31-G32 -> 0
B33: =B32+1 -> 2031 | C33: =SUMIF($B$62:$B$843,"<="&DATE($B33,12,31),$C$62:$C$843)-SUM(C$27:C32) -> 0 | D33: =SUMIF($B$62:$B$843,"<="&DATE($B33,12,31),$D$62:$D$843)-SUM(D$27:D32) -> 0 | F33: =SUMIF($B$62:$B$843,"<="&DATE($B33,12,31),$F$62:$F$843)-SUM(F$27:F32) -> 0 | G33: =SUMIF($B$62:$B$843,"<="&DATE($B33,12,31),$G$62:$G$843)-SUM(G$27:G32) -> 0 | H33: =H32-G33 -> 0
B34: =B33+1 -> 2032 | C34: =SUMIF($B$62:$B$843,"<="&DATE($B34,12,31),$C$62:$C$843)-SUM(C$27:C33) -> 0 | D34: =SUMIF($B$62:$B$843,"<="&DATE($B34,12,31),$D$62:$D$843)-SUM(D$27:D33) -> 0 | F34: =SUMIF($B$62:$B$843,"<="&DATE($B34,12,31),$F$62:$F$843)-SUM(F$27:F33) -> 0 | G34: =SUMIF($B$62:$B$843,"<="&DATE($B34,12,31),$G$62:$G$843)-SUM(G$27:G33) -> 0 | H34: =H33-G34 -> 0
B35: =B34+1 -> 2033 | C35: =SUMIF($B$62:$B$843,"<="&DATE($B35,12,31),$C$62:$C$843)-SUM(C$27:C34) -> 0 | D35: =SUMIF($B$62:$B$843,"<="&DATE($B35,12,31),$D$62:$D$843)-SUM(D$27:D34) -> 0 | F35: =SUMIF($B$62:$B$843,"<="&DATE($B35,12,31),$F$62:$F$843)-SUM(F$27:F34) -> 0 | G35: =SUMIF($B$62:$B$843,"<="&DATE($B35,12,31),$G$62:$G$843)-SUM(G$27:G34) -> 0 | H35: =H34-G35 -> 0
B36: =B35+1 -> 2034 | C36: =SUMIF($B$62:$B$843,"<="&DATE($B36,12,31),$C$62:$C$843)-SUM(C$27:C35) -> 0 | D36: =SUMIF($B$62:$B$843,"<="&DATE($B36,12,31),$D$62:$D$843)-SUM(D$27:D35) -> 0 | F36: =SUMIF($B$62:$B$843,"<="&DATE($B36,12,31),$F$62:$F$843)-SUM(F$27:F35) -> 0 | G36: =SUMIF($B$62:$B$843,"<="&DATE($B36,12,31),$G$62:$G$843)-SUM(G$27:G35) -> 0 | H36: =H35-G36 -> 0
B37: =B36+1 -> 2035 | C37: =SUMIF($B$62:$B$843,"<="&DATE($B37,12,31),$C$62:$C$843)-SUM(C$27:C36) -> 0 | D37: =SUMIF($B$62:$B$843,"<="&DATE($B37,12,31),$D$62:$D$843)-SUM(D$27:D36) -> 0 | F37: =SUMIF($B$62:$B$843,"<="&DATE($B37,12,31),$F$62:$F$843)-SUM(F$27:F36) -> 0 | G37: =SUMIF($B$62:$B$843,"<="&DATE($B37,12,31),$G$62:$G$843)-SUM(G$27:G36) -> 0 | H37: =H36-G37 -> 0
B38: =B37+1 -> 2036 | C38: =SUMIF($B$62:$B$843,"<="&DATE($B38,12,31),$C$62:$C$843)-SUM(C$27:C37) -> 0 | D38: =SUMIF($B$62:$B$843,"<="&DATE($B38,12,31),$D$62:$D$843)-SUM(D$27:D37) -> 0 | F38: =SUMIF($B$62:$B$843,"<="&DATE($B38,12,31),$F$62:$F$843)-SUM(F$27:F37) -> 0 | G38: =SUMIF($B$62:$B$843,"<="&DATE($B38,12,31),$G$62:$G$843)-SUM(G$27:G37) -> 0 | H38: =H37-G38 -> 0
B39: =B38+1 -> 2037 | C39: =SUMIF($B$62:$B$843,"<="&DATE($B39,12,31),$C$62:$C$843)-SUM(C$27:C38) -> 0 | D39: =SUMIF($B$62:$B$843,"<="&DATE($B39,12,31),$D$62:$D$843)-SUM(D$27:D38) -> 0 | F39: =SUMIF($B$62:$B$843,"<="&DATE($B39,12,31),$F$62:$F$843)-SUM(F$27:F38) -> 0 | G39: =SUMIF($B$62:$B$843,"<="&DATE($B39,12,31),$G$62:$G$843)-SUM(G$27:G38) -> 0 | H39: =H38-G39 -> 0
B40: =B39+1 -> 2038 | C40: =SUMIF($B$62:$B$843,"<="&DATE($B40,12,31),$C$62:$C$843)-SUM(C$27:C39) -> 0 | D40: =SUMIF($B$62:$B$843,"<="&DATE($B40,12,31),$D$62:$D$843)-SUM(D$27:D39) -> 0 | F40: =SUMIF($B$62:$B$843,"<="&DATE($B40,12,31),$F$62:$F$843)-SUM(F$27:F39) -> 0 | G40: =SUMIF($B$62:$B$843,"<="&DATE($B40,12,31),$G$62:$G$843)-SUM(G$27:G39) -> 0 | H40: =H39-G40 -> 0
... B58: =B57+1 -> 2056 | C58: =SUMIF($B$62:$B$843,"<="&DATE($B58,12,31),$C$62:$C$843)-SUM(C$27:C57) -> 0 | D58: =SUMIF($B$62:$B$843,"<="&DATE($B58,12,31),$D$62:$D$843)-SUM(D$27:D57) -> 0 | F58: =SUMIF($B$62:$B$843,"<="&DATE($B58,12,31),$F$62:$F$843)-SUM(F$27:F57) -> 0 | G58: =SUMIF($B$62:$B$843,"<="&DATE($B58,12,31),$G$62:$G$843)-SUM(G$27:G57) -> 0 | H58: =H57-G58 -> 0
A60: Amortization Schedule
A61: No. | B61: Due Date | C61: Payment Due | D61: Additional Payment | F61: Interest | G61: Principal | H61: Balance
H62: =$D$8 -> 1300000
A63: =IF(H62="","",IF(roundOpt,IF(OR(A62>=nper,ROUND(H62,2)<=0),"",A62+1),IF(OR(A62>=nper,H62<=0),"",A62+1))) -> 1 | B63: =IF(A63="","",IF(periods_per_year=26,IF(A63=1,fpdate,B62+14),IF(periods_per_year=52,IF(A63=1,fpdate,B62+7),IF(periods_per_year=24,IF(A63=1,fpdate,IF(fpdate=EOMONTH(fpdate,0),IF(ISODD(A63),EOMONTH(EDATE(fpdate,(A63-1)/2),0),EDATE(DATE(YEAR(fpdate),MONTH(fpdate)+1,15),(A63-1)/2)),IF(DAY(fpdate)=15,IF(ISODD(A63),EDATE(fpdate,(A63-1)/2),EOMONTH(EDATE(fpdate,(A63-1)/2),0)),IF(DAY(fpdate)<=14,IF(ISODD(A63),EDATE(fpdate,(A63-1)/2),EDATE(MIN(fpdate+15,EOMONTH(fpdate,0)),(A63-1)/2)),EDATE(IF(ISODD(A63),fpdate,fpdate-15),A63/2))))),IF(A63=1,fpdate,EDATE(fpdate,months_per_period*(A63-1))))))) -> 46143 | C63: =IF(A63="","",IF(roundOpt,IF(OR(A63=nper,payment>ROUND((1+rate)*H62,2)),ROUND((1+rate)*H62,2),payment),IF(OR(A63=nper,payment>(1+rate)*H62),(1+rate)*H62,payment))) -> 41339.65 | F63: =IF(A63="","",IF(AND(A63=1,pmtType=1),0,IF(roundOpt,ROUND(rate*H62,2),rate*H62))) -> 9750 | G63: =IF(A63="","",C63-F63+D63) -> 31589.65 | H63: =IF(A63="","",H62-G63) -> 1268410.4
...

Sheet General Disclosures
B2: GENERAL DISCLOSURES
B5: THIS EXECUTIVE SUMMARY HAS BEEN PREPARED BY BAR CAPITAL LLC (THE “COMPANY”) SOLELY FOR INFORMATIONAL PURPOSES AND IS NOT TO BE USED AS A BASIS FOR AN INVESTMENT DECISION. REFERENCES HEREIN TO “WE”, “US”, OR “OUR” REFER TO THE COMPANY. THIS EXECUTIVE SUMMARY IS NOT AN OFFERING DOCUMENT AND DOES NOT CONSTITUTE AN OFFER TO SELL OR A SOLICITATION OF AN OFFER TO PURCHASE SECURITIES. THIS EXECUTIVE SUMMARY CONSTITUTES PROPRIETARY INFORMATION OF THE COMPANY AND SHOULD NOT BE DISSEMINATED WITHOUT THE WRITTEN CONSENT OF THE COMPANY. THE INFORMATION CONTAINED IN THIS EXECUTIVE SUMMARY DOES NOT PURPORT TO BE ALL-INCLUSIVE OR TO CONTAIN ALL OF THE INFORMATION THAT A PROSPECTIVE INVESTOR MAY REQUIRE. THE INFORMATION PRESENTED IN THIS EXECUTIVE SUMMARY MAY ALSO CONTAIN CERTAIN FORWARD-LOOKING STATEMENTS REGARDING FUTURE FINANCIAL PERFORMANCE, WHICH ARE NOT HISTORICAL FACTS AND WHICH INVOLVE VARIOUS RISKS AND UNCERTAINTIES. WE INTEND SUCH FORWARD-LOOKING STATEMENTS TO BE COVERED BY THE SAFE HARBOR PROVISIONS FOR FORWARD-LOOKING STATEMENTS CONTAINED IN THE PRIVATE SECURITIES LITIGATION REFORM ACT OF 1995 AND ARE INCLUDING THIS STATEMENT FOR PURPOSES OF INVOKING THESE SAFE HARBOR PROVISIONS. THESE FORWARD-LOOKING STATEMENTS REPRESENT PLANS, ESTIMATES, OBJECTIVES, GOALS, GUIDELINES, EXPECTATIONS, INTENTIONS, PROJECTIONS AND STATEMENTS OF OUR BELIEFS CONCERNING FUTURE EVENTS, BUSINESS PLANS, OBJECTIVES, EXPECTED OPERATING RESULTS AND THE ASSUMPTIONS UPON WHICH THOSE STATEMENTS ARE BASED. THE WORDS “BELIEVES,” “EXPECTS,” “MAY,” “WILL,” “SHOULD,” “PROJECTS,” “CONTEMPLATES,” “ANTICIPATES,” “FORECASTS,” “INTENDS,” OR OTHER SIMILAR WORDS OR TERMS ARE INTENDED TO IDENTIFY FORWARD-LOOKING STATEMENTS. FORWARD-LOOKING STATEMENTS ARE NEITHER HISTORICAL FACTS NOR ASSURANCES OF FUTURE PERFORMANCE. INSTEAD, THEY ARE BASED ONLY ON OUR CURRENT BELIEFS, EXPECTATIONS AND ASSUMPTIONS REGARDING THE FUTURE OF OUR BUSINESS, FUTURE PLANS AND STRATEGIES, PROJECTIONS, ANTICIPATED EVENTS AND TRENDS, THE ECONOMY AND OTHER FUTURE CONDITIONS. BECAUSE FORWARD-LOOKING STATEMENTS RELATE TO THE FUTURE, THEY ARE SUBJECT TO INHERENT UNCERTAINTIES, RISKS AND CHANGES IN CIRCUMSTANCES THAT ARE DIFFICULT TO PREDICT AND MANY OF WHICH ARE OUTSIDE OF OUR CONTROL. OUR ACTUAL RESULTS AND FINANCIAL CONDITION MAY DIFFER MATERIALLY FROM THOSE INDICATED IN THE FORWARD-LOOKING STATEMENTS. THEREFORE, YOU SHOULD NOT RELY ON ANY OF THESE FORWARD-LOOKING STATEMENTS. NO OPINION IS EXPRESSED ON THE ACHIEVABILITY OF THOSE FORWARDLOOKING STATEMENTS. NO ASSURANCE CAN BE GIVEN THAT ANY OF THE ASSUMPTIONS RELATING TO THE FORWARD-LOOKING STATEMENTS SPECIFIED IN THE ENCLOSED MATERIAL ARE ACCURATE, AND THE COMPANY ASSUMES NO OBLIGATION TO UPDATE ANY SUCH FORWARD-LOOKING STATEMENTS. SOME OF THE ENTITIES LISTED MAY BE IN THE PROCESS OF FORMATION. THIS EXECUTIVE SUMMARY IS INTENDED ONLY FOR THE PARTY OR PARTIES TO WHOM IT WAS DIRECTED. IF YOU HAVE RECEIVED THE EXECUTIVE SUMMARY IN ERROR OR BY OTHER MEANS, IT MUST BE DESTROYED AND BY NO MEANS CIRCULATED, COPIED OR OTHERWISE DUPLICATED OR DISSEMINATED WITHOUT THE EXPRESS PERMISSION OF THE COMPANY. NOTHING IN THIS EXECUTIVE SUMMARY SHOULD BE CONSTRUED AS INVESTMENT ADVICE, NOR SHOULD IT BE USED TO MAKE INVESTMENT DECISIONS. READERS ARE ADVISED TO CONDUCT THEIR OWN DUE DILIGENCE PRIOR TO CONSIDERING BUYING OR SELLING ANY SECURITIES. NO REGULATORY AUTHORITY HAS APPROVED OR DISAPPROVED OF THE INFORMATION CONTAINED HEREIN.
