Workbook

Sheet Version
B2: MULTIFAMILY REDEVELOPMENT MODEL
B3: Model Resources | L3: =B15 -> v7.1
B4: Author: Michael Belasco | H4: Important Links:
B5: https://www.adventuresincre.com/ | H5: Visit this Model's Webpage
B7: Compatibility
B8: Excel 2013 | H8: Browse our entire Library of Real Estate Models
B9: Excel 2016
B10: Excel 365
B12: AdventuresinCRE.com and its affiliates do not provide tax, legal, investment, or accounting advice. This material has been prepared for informational purposes only, and is not intended to provide, and should not be relied on for, tax, legal or accounting advice. You should consult your own tax, legal and accounting advisors before engaging in any transaction. This model may contains errors. Verify all calculations being using this model to make investment decisions.
B13: LEARN TO BUILD INSTITUTIONAL-QUALITY REAL ESTATE MODELS FROM SCRATCH - CLICK HERE TO LEARN MORE -
B14: Changelog | I14: Disclaimer: This model may contain errors
B15: v7.1
B16: Total Renovation Duration Formula Update (Cell W22 – A&Rs Tab): Revised formula to calculate the total renovation period, measured in months from the start date to the completion of the last unit renovated.
B17: Date Completion Formula Update (Cell X22 – A&Rs Tab): Revised formula to reflect the construction completion date as one month after the final renovation is finished.
B18: Total Renovation Cost Formula Update (Cell Z22 – A&Rs Tab): Revised formula to reflect the aggregate cost of all renovations included in the budget.
B19: Placeholder value updates
B21: v7.0
B22: Added version tab for change tracking
B23: Adapted for use with A.CRE 'My Downloads' section
B24: Misc. formatting updates and enhancements

Sheet A&Rs
G3: Assumptions
G6: Date | H6: =TODAY() -> 46108 | J6: =IF(MAX($X$10:$X$22)>$K$11,"Your Redevelopment Time Exceeds Your Exit Date","")
G8: Property Info | J8: Essential Deal Assumptions | M8: Property Level Assumptions | Q8: Unit Level Assumprions
G9: Property Address | J9: Hold Period (Max 10 years) | K9: 5 | M9: Gross Rent Growth Assumptions | Q9: Unit # | R9: Type | S9: SQ FT | T9: Market Rent In Current Condition | U9: Rent SF | V9: Renovation Begin Date | W9: Duration of Rnovation (mos.) | X9: Date Complete | Y9: Year Complete | Z9: Cost Per renovation | AA9: Premium Added due to Renovation
G10: Street | H10: 123 Fake St. | J10: Acquisition Target Date | K10: 46174 | N10: Annual % Growth | Q10: 1 | R10: 1 Bed | S10: 800 | T10: 1170 | U10: =IFERROR(T10/S10,0) -> 1.4625 | V10: 46235 | W10: 2 | X10: =EDATE(V10,W10) -> 46296 | Y10: =INDEX(UnitsBreakdown!$E$21:$FE$21,MATCH(Table2[[#This Row],[Date Complete]],UnitsBreakdown!$E$23:$FE$23)) -> 1 | Z10: 12000 | AA10: 260
G11: City | H11: Springfield | J11: Disposition Date | K11: =EDATE(K10,K9*12) -> 48000 | M11: Rent at Acquisition | O11: =UnitsBreakdown!E37*12 -> 208956 | Q11: 2 | R11: 1 Bed | S11: 800 | T11: 1170 | U11: =IFERROR(T11/S11,0) -> 1.4625 | V11: 46235 | W11: 2 | X11: =EDATE(V11,W11) -> 46296 | Y11: =INDEX(UnitsBreakdown!$E$21:$FE$21,MATCH(Table2[[#This Row],[Date Complete]],UnitsBreakdown!$E$23:$FE$23)) -> 1 | Z11: 12000 | AA11: 260
G12: State | H12: Illinois | J12: Required Unlevered Return | K12: 0.11 | M12: 1 | N12: 0 | O12: =IF($K$9<M12,"",SUMIF(UnitsBreakdown!$F$21:$FE$21,M12,UnitsBreakdown!$F$37:$FE$37)) -> 177338 | Q12: 3 | R12: 1 Bed | S12: 800 | T12: 1200 | U12: =IFERROR(T12/S12,0) -> 1.5 | V12: 46235 | W12: 2 | X12: =EDATE(V12,W12) -> 46296 | Y12: =INDEX(UnitsBreakdown!$E$21:$FE$21,MATCH(Table2[[#This Row],[Date Complete]],UnitsBreakdown!$E$23:$FE$23)) -> 1 | Z12: 12000 | AA12: 260
G13: ZIP | H13: 12345 | J13: Going In Cap Rate (1st Year of Stabilized Rent) | K13: ='YearProForma&Returns'!E18/'A&Rs'!K18 -> 0.07 | M13: 2 | N13: 0.03 | O13: =IF($K$9<M13,"",SUMIF(UnitsBreakdown!$F$21:$FE$21,M13,UnitsBreakdown!$F$37:$FE$37)) -> 233587.48 | Q13: 4 | R13: 1 Bed | S13: 800 | T13: 1240 | U13: =IFERROR(T13/S13,0) -> 1.55 | V13: 46296 | W13: 3 | X13: =EDATE(V13,W13) -> 46388 | Y13: =INDEX(UnitsBreakdown!$E$21:$FE$21,MATCH(Table2[[#This Row],[Date Complete]],UnitsBreakdown!$E$23:$FE$23)) -> 1 | Z13: 11500 | AA13: 260
J14: Going Out Cap Rate | K14: 0.07 | M14: 3 | N14: 0.02 | O14: =IF($K$9<M14,"",SUMIF(UnitsBreakdown!$F$21:$FE$21,M14,UnitsBreakdown!$F$37:$FE$37)) -> 261196.58 | Q14: 5 | R14: 2 Bed | S14: 1000 | T14: 1312 | U14: =IFERROR(T14/S14,0) -> 1.312 | V14: 46296 | W14: 3 | X14: =EDATE(V14,W14) -> 46388 | Y14: =INDEX(UnitsBreakdown!$E$21:$FE$21,MATCH(Table2[[#This Row],[Date Complete]],UnitsBreakdown!$E$23:$FE$23)) -> 1 | Z14: 13000 | AA14: 280
G15: Units | H15: =SUM(H16:H19) -> 12 | J15: Selling Costs (% of Sales Price @ exit) | K15: 0.03 | M15: 4 | N15: 0.03 | O15: =IF($K$9<M15,"",SUMIF(UnitsBreakdown!$F$21:$FE$21,M15,UnitsBreakdown!$F$37:$FE$37)) -> 269032.48 | Q15: 6 | R15: 2 Bed | S15: 1000 | T15: 1346 | U15: =IFERROR(T15/S15,0) -> 1.346 | V15: 46357 | W15: 3 | X15: =EDATE(V15,W15) -> 46447 | Y15: =INDEX(UnitsBreakdown!$E$21:$FE$21,MATCH(Table2[[#This Row],[Date Complete]],UnitsBreakdown!$E$23:$FE$23)) -> 1 | Z15: 13000 | AA15: 280
G16: Studio | H16: =COUNTIF(Table2[Type],"Studio") -> 0 | J16: General Inflation Rate | K16: 0.02 | M16: 5 | N16: 0.03 | O16: =IF($K$9<M16,"",SUMIF(UnitsBreakdown!$F$21:$FE$21,M16,UnitsBreakdown!$F$37:$FE$37)) -> 277103.45 | Q16: 7 | R16: 2 Bed | S16: 1000 | T16: 1413 | U16: =IFERROR(T16/S16,0) -> 1.413 | V16: 46419 | W16: 4 | X16: =EDATE(V16,W16) -> 46539 | Y16: =INDEX(UnitsBreakdown!$E$21:$FE$21,MATCH(Table2[[#This Row],[Date Complete]],UnitsBreakdown!$E$23:$FE$23)) -> 1 | Z16: 13200 | AA16: 280
G17: 1-bed | H17: =COUNTIF(Table2[Type],"1 Bed") -> 4 | J17: Financing Assumptions | M17: 6 | N17: 0 | O17: =IF($K$9<M17,"",SUMIF(UnitsBreakdown!$F$21:$FE$21,M17,UnitsBreakdown!$F$37:$FE$37)) | Q17: 8 | R17: 2 Bed | S17: 1000 | T17: 1480 | U17: =IFERROR(T17/S17,0) -> 1.48 | V17: 46419 | W17: 4 | X17: =EDATE(V17,W17) -> 46539 | Y17: =INDEX(UnitsBreakdown!$E$21:$FE$21,MATCH(Table2[[#This Row],[Date Complete]],UnitsBreakdown!$E$23:$FE$23)) -> 1 | Z17: 14100 | AA17: 260
G18: 2-bed | H18: =COUNTIF(Table2[Type],"2 Bed") -> 4 | J18: Price Based on Required Unlevered IRR | K18: =H33 -> 1919701.4 | M18: 7 | N18: 0.01 | O18: =IF($K$9<M18,"",SUMIF(UnitsBreakdown!$F$21:$FE$21,M18,UnitsBreakdown!$F$37:$FE$37)) | Q18: 11 | R18: 3 Bed | S18: 1200 | T18: 1548 | U18: =IFERROR(T18/S18,0) -> 1.29 | V18: 46447 | W18: 4 | X18: =EDATE(V18,W18) -> 46569 | Y18: =INDEX(UnitsBreakdown!$E$21:$FE$21,MATCH(Table2[[#This Row],[Date Complete]],UnitsBreakdown!$E$23:$FE$23)) -> 2 | Z18: 14950 | AA18: 300
G19: 3-bed | H19: =COUNTIF(Table2[Type],"3 Bed") -> 4 | J19: Total Redevelopment Costs | K19: =SUM('A&Rs'!Z10:Z22) -> 321200 | M19: 8 | N19: 0.03 | O19: =IF($K$9<M19,"",SUMIF(UnitsBreakdown!$F$21:$FE$21,M19,UnitsBreakdown!$F$37:$FE$37)) | Q19: 10 | R19: 3 Bed | S19: 1200 | T19: 1750 | U19: =IFERROR(T19/S19,0) -> 1.4583333 | V19: 46447 | W19: 4 | X19: =EDATE(V19,W19) -> 46569 | Y19: =INDEX(UnitsBreakdown!$E$21:$FE$21,MATCH(Table2[[#This Row],[Date Complete]],UnitsBreakdown!$E$23:$FE$23)) -> 2 | Z19: 14950 | AA19: 300
J20: Construction Contingency | K20: =Z24 -> 16060 | M20: 9 | N20: 0.02 | O20: =IF($K$9<M20,"",SUMIF(UnitsBreakdown!$F$21:$FE$21,M20,UnitsBreakdown!$F$37:$FE$37)) | Q20: 9 | R20: 3 Bed | S20: 1200 | T20: 1884 | U20: =IFERROR(T20/S20,0) -> 1.57 | V20: 46569 | W20: 5 | X20: =EDATE(V20,W20) -> 46722 | Y20: =INDEX(UnitsBreakdown!$E$21:$FE$21,MATCH(Table2[[#This Row],[Date Complete]],UnitsBreakdown!$E$23:$FE$23)) -> 2 | Z20: 14950 | AA20: 300
G21: Vacant Units | H21: 2 | J21: Price for Property | K21: =K18-K19-K20 -> 1582441.4 | M21: 10 | N21: 0.01 | O21: =IF($K$9<M21,"",SUMIF(UnitsBreakdown!$F$21:$FE$21,M21,UnitsBreakdown!$F$37:$FE$37)) | Q21: 12 | R21: 3 Bed | S21: 1200 | T21: 1900 | U21: =IFERROR(T21/S21,0) -> 1.5833333 | V21: 46569 | W21: 5 | X21: =EDATE(V21,W21) -> 46722 | Y21: =INDEX(UnitsBreakdown!$E$21:$FE$21,MATCH(Table2[[#This Row],[Date Complete]],UnitsBreakdown!$E$23:$FE$23)) -> 2 | Z21: 14950 | AA21: 300
G22: Vacancy Rate | H22: =H21/H15 -> 0.16666667 | J22: Equity Requirements | Q22: Total Building | U22: Renovations End date | V22: =EDATE(MAX(Table2[Renovation Begin Date]),MAX(Table2[Duration of Rnovation (mos.)])) -> 46722 | W22: =DATEDIF(MIN(Table2[Renovation Begin Date]),MAX(Table2[Date Complete]),"M") -> 16 | X22: =EOMONTH(V22,1) -> 46783 | Y22: =INDEX(UnitsBreakdown!E21:FE21,MATCH('A&Rs'!X22,UnitsBreakdown!E23:FE23)) -> 2 | Z22: =SUM(Table2[Cost Per renovation]) -> 160600
J23: Percent down | K23: 0.3 | M23: NOI Growth in Following Year for Residual Value | N23: 0.03 | Q23: Total Square Feet | S23: =SUM(S10:S21) -> 12000
G24: Market Cap Rate | H24: 0.07 | J24: Cash Needed for Down Payment | K24: =K18*K23 -> 575910.43 | Q24: Construction Contingency | S24: 0.1 | Z24: =SUM(Z10:Z21)*$S$24 -> 16060
J25: Cash Required if Loan has Points or Fees | K25: ='Amortization Schedule'!C3*K37+'Amortization Schedule'!C3*K38 -> 0 | M25: Expected Average Annual Vacancy / Credit Loss | N25: 0.05
G26: Average SF per Unit | H26: =AVERAGE('A&Rs'!S10:S21) -> 1000 | J26: Closing Costs | K26: =K18*0.02 -> 38394.029 | U26: =IF(MAX($X$10:$X$22)>$K$11,"Your Redevelopment Time Exceeds Your Exit Date","")
G27: Total Rentable SF | H27: =SUM('A&Rs'!S10:S21) -> 12000 | J27: Total Equity In | K27: =SUM(K24:K26) -> 614304.46 | M27: Operating Expenses
G28: Average Rent | H28: =AVERAGE(Table2[Market Rent In Current Condition]) -> 1451.0833 | J28: Loan Info | M28: One time unexpected cost in year 1 | N28: 0.03 | O28: 5300
J29: Percent of Cost Needed for Loan | K29: =1-K23 -> 0.7 | M29: Monthly Tax Payments | N29: 0.03 | O29: 404
G30: Purchase Price Based On Market Cap Rate | H30: ='YearProForma&Returns'!E18/H24 -> 1919701.4 | J30: Loan Proceeds | K30: =K18-SUM(K24:K25) -> 1343791 | M30: Insurance | N30: 0.03 | O30: 1615
G31: Purchase Price Based On DCF | H31: ='YearProForma&Returns'!D30 -> 2647460.1 | J31: Interest Rate | K31: 0.055 | M31: Utilities | N31: 0.03 | O31: 572
J32: Amortization | K32: 30 | M32: Other Monthly Expense | N32: 0.03 | O32: 150
G33: Choose Purchase Price | H33: 1919701.4 | J33: Term | K33: =K9 -> 5 | M33: Other Monthly Expense | N33: 0.03 | O33: 100
J34: Payment | K34: ='Amortization Schedule'!C6 -> 7629.8975
J35: MinimumDSCR Required | K35: 1.15 | M35: Capital Reserve (% of Net Operating Income) | N35: 0.03
J36: Minimum DSCR Realized in Pro Forma | K36: =ROUND(MIN('Monthly Pro Forma'!O29:ED29),2) -> 1.19
J37: Points | K37: 0
J38: Origination Fees | K38: 0
G42: Results
G45: Returns | M45: Holding Period Sensitivity Analysis
G46: Sales Price at Exit Year | H46: =SUM('Monthly Pro Forma'!N33:ED33) -> 3308910.8 | M46: Disposition Date | N46: Levered IRR | O46: Equity Multiple | Q46: Net Gain (Loss) | R46: Duration
N47: =H54 -> 0.3709349 | O47: =H55 -> 3.9987143 | Q47: =H57 -> 1842123.6 | R47: =H56 -> 4.3693952
G48: Loan Repayment Amount | H48: =PV(K31/12,(K32*12)-(K9*12),K34) -> -1242477.3 | M48: 1 | N48: 0.02818519 | O48: 1.027298 | P48: 0 | Q48: 16769.264 | R48: 1
G49: Selling Expense | H49: =SUM('Monthly Pro Forma'!N35:ED35) -> -99267.325 | M49: 2 | N49: 0.58539767 | O49: 2.4221356 | P49: 0 | Q49: 873624.25 | R49: 1.9597251
G50: Sale Proceeds after Debt Repayment | H50: =SUM(H46:H49) -> 1967166.2 | M50: 3 | N50: 0.51779251 | O50: 3.2256048 | P50: 0 | Q50: 1367198.9 | R50: 2.8510176
...

Sheet UnitsBreakdown
D3: Monthly Rent With No Renovation | S3: Monthly Rent With Renovation
E4: 0 | F4: 1 | G4: 2 | H4: 3 | I4: 4 | J4: 5 | K4: 6 | L4: 7 | M4: 8 | N4: 9 | O4: 10 | P4: 11 | Q4: 12 | T4: 0 | U4: 1 | V4: 2 | W4: 3 | X4: 4 | Y4: 5 | Z4: 6 | AA4: 7 | AB4: 8 | AC4: 9 | AD4: 10 | AE4: 11 | AF4: 12
B6: 3 | D6: =D24 -> 1 | E6: =IF('A&Rs'!R10="","",'A&Rs'!T10) -> 1170 | F6: =IF('A&Rs'!R10="","",E6*(1+VLOOKUP(F$4,'A&Rs'!$M$12:$N$21,2))) -> 1170 | G6: =IF('A&Rs'!R10="","",F6*(1+VLOOKUP(G$4,'A&Rs'!$M$12:$N$21,2))) -> 1205.1 | H6: =IF('A&Rs'!R10="","",G6*(1+VLOOKUP(H$4,'A&Rs'!$M$12:$N$21,2))) -> 1229.202 | I6: =IF('A&Rs'!R10="","",H6*(1+VLOOKUP(I$4,'A&Rs'!$M$12:$N$21,2))) -> 1266.0781 | J6: =IF('A&Rs'!R10="","",I6*(1+VLOOKUP(J$4,'A&Rs'!$M$12:$N$21,2))) -> 1304.0604 | K6: =IF('A&Rs'!R10="","",J6*(1+VLOOKUP(K$4,'A&Rs'!$M$12:$N$21,2))) -> 1304.0604 | L6: =IF('A&Rs'!R10="","",K6*(1+VLOOKUP(L$4,'A&Rs'!$M$12:$N$21,2))) -> 1317.101 | M6: =IF('A&Rs'!R10="","",L6*(1+VLOOKUP(M$4,'A&Rs'!$M$12:$N$21,2))) -> 1356.614 | N6: =IF('A&Rs'!R10="","",M6*(1+VLOOKUP(N$4,'A&Rs'!$M$12:$N$21,2))) -> 1383.7463 | O6: =IF('A&Rs'!R10="","",N6*(1+VLOOKUP(O$4,'A&Rs'!$M$12:$N$21,2))) -> 1397.5838 | P6: =IF('A&Rs'!R10="","",O6*(1+VLOOKUP(P$4,'A&Rs'!$M$12:$N$21,2))) -> 1411.5596 | Q6: =IF('A&Rs'!R10="","",P6*(1+VLOOKUP(Q$4,'A&Rs'!$M$12:$N$21,2))) -> 1425.6752 | S6: =D24 -> 1 | T6: =IF('A&Rs'!R10="","",'A&Rs'!T10) -> 1170 | U6: =IF('A&Rs'!R10="","",T6*(1+VLOOKUP(U$4,'A&Rs'!$M$12:$N$21,2))+IF('A&Rs'!$Y10=U$4,'A&Rs'!$AA10,0)) -> 1430 | V6: =IF('A&Rs'!R10="","",U6*(1+VLOOKUP(V$4,'A&Rs'!$M$12:$N$21,2))+IF('A&Rs'!$Y10=V$4,'A&Rs'!$AA10,0)) -> 1472.9 | W6: =IF('A&Rs'!R10="","",V6*(1+VLOOKUP(W$4,'A&Rs'!$M$12:$N$21,2))+IF('A&Rs'!$Y10=W$4,'A&Rs'!$AA10,0)) -> 1502.358 | X6: =IF('A&Rs'!R10="","",W6*(1+VLOOKUP(X$4,'A&Rs'!$M$12:$N$21,2))+IF('A&Rs'!$Y10=X$4,'A&Rs'!$AA10,0)) -> 1547.4287 | Y6: =IF('A&Rs'!R10="","",X6*(1+VLOOKUP(Y$4,'A&Rs'!$M$12:$N$21,2))+IF('A&Rs'!$Y10=Y$4,'A&Rs'!$AA10,0)) -> 1593.8516 | Z6: =IF('A&Rs'!R10="","",Y6*(1+VLOOKUP(Z$4,'A&Rs'!$M$12:$N$21,2))+IF('A&Rs'!$Y10=Z$4,'A&Rs'!$AA10,0)) -> 1593.8516 | AA6: =IF('A&Rs'!R10="","",Z6*(1+VLOOKUP(AA$4,'A&Rs'!$M$12:$N$21,2))+IF('A&Rs'!$Y10=AA$4,'A&Rs'!$AA10,0)) -> 1609.7901 | AB6: =IF('A&Rs'!R10="","",AA6*(1+VLOOKUP(AB$4,'A&Rs'!$M$12:$N$21,2))+IF('A&Rs'!$Y10=AB$4,'A&Rs'!$AA10,0)) -> 1658.0838 | AC6: =IF('A&Rs'!R10="","",AB6*(1+VLOOKUP(AC$4,'A&Rs'!$M$12:$N$21,2))+IF('A&Rs'!$Y10=AC$4,'A&Rs'!$AA10,0)) -> 1691.2455 | AD6: =IF('A&Rs'!R10="","",AC6*(1+VLOOKUP(AD$4,'A&Rs'!$M$12:$N$21,2))+IF('A&Rs'!$Y10=AD$4,'A&Rs'!$AA10,0)) -> 1708.158 | AE6: =IF('A&Rs'!R10="","",AD6*(1+VLOOKUP(AE$4,'A&Rs'!$M$12:$N$21,2))+IF('A&Rs'!$Y10=AE$4,'A&Rs'!$AA10,0)) -> 1725.2395 | AF6: =IF('A&Rs'!R10="","",AE6*(1+VLOOKUP(AF$4,'A&Rs'!$M$12:$N$21,2))+IF('A&Rs'!$Y10=AF$4,'A&Rs'!$AA10,0)) -> 1742.4919
B7: 4 | D7: =D25 -> 2 | E7: =IF('A&Rs'!R11="","",'A&Rs'!T11) -> 1170 | F7: =IF('A&Rs'!R11="","",E7*(1+VLOOKUP(F$4,'A&Rs'!$M$12:$N$21,2))) -> 1170 | G7: =IF('A&Rs'!R11="","",F7*(1+VLOOKUP(G$4,'A&Rs'!$M$12:$N$21,2))) -> 1205.1 | H7: =IF('A&Rs'!R11="","",G7*(1+VLOOKUP(H$4,'A&Rs'!$M$12:$N$21,2))) -> 1229.202 | I7: =IF('A&Rs'!R11="","",H7*(1+VLOOKUP(I$4,'A&Rs'!$M$12:$N$21,2))) -> 1266.0781 | J7: =IF('A&Rs'!R11="","",I7*(1+VLOOKUP(J$4,'A&Rs'!$M$12:$N$21,2))) -> 1304.0604 | K7: =IF('A&Rs'!R11="","",J7*(1+VLOOKUP(K$4,'A&Rs'!$M$12:$N$21,2))) -> 1304.0604 | L7: =IF('A&Rs'!R11="","",K7*(1+VLOOKUP(L$4,'A&Rs'!$M$12:$N$21,2))) -> 1317.101 | M7: =IF('A&Rs'!R11="","",L7*(1+VLOOKUP(M$4,'A&Rs'!$M$12:$N$21,2))) -> 1356.614 | N7: =IF('A&Rs'!R11="","",M7*(1+VLOOKUP(N$4,'A&Rs'!$M$12:$N$21,2))) -> 1383.7463 | O7: =IF('A&Rs'!R11="","",N7*(1+VLOOKUP(O$4,'A&Rs'!$M$12:$N$21,2))) -> 1397.5838 | P7: =IF('A&Rs'!R11="","",O7*(1+VLOOKUP(P$4,'A&Rs'!$M$12:$N$21,2))) -> 1411.5596 | Q7: =IF('A&Rs'!R11="","",P7*(1+VLOOKUP(Q$4,'A&Rs'!$M$12:$N$21,2))) -> 1425.6752 | S7: =D25 -> 2 | T7: =IF('A&Rs'!R11="","",'A&Rs'!T11) -> 1170 | U7: =IF('A&Rs'!R11="","",T7*(1+VLOOKUP(U$4,'A&Rs'!$M$12:$N$21,2))+IF('A&Rs'!$Y11=U$4,'A&Rs'!$AA11,0)) -> 1430 | V7: =IF('A&Rs'!R11="","",U7*(1+VLOOKUP(V$4,'A&Rs'!$M$12:$N$21,2))+IF('A&Rs'!$Y11=V$4,'A&Rs'!$AA11,0)) -> 1472.9 | W7: =IF('A&Rs'!R11="","",V7*(1+VLOOKUP(W$4,'A&Rs'!$M$12:$N$21,2))+IF('A&Rs'!$Y11=W$4,'A&Rs'!$AA11,0)) -> 1502.358 | X7: =IF('A&Rs'!R11="","",W7*(1+VLOOKUP(X$4,'A&Rs'!$M$12:$N$21,2))+IF('A&Rs'!$Y11=X$4,'A&Rs'!$AA11,0)) -> 1547.4287 | Y7: =IF('A&Rs'!R11="","",X7*(1+VLOOKUP(Y$4,'A&Rs'!$M$12:$N$21,2))+IF('A&Rs'!$Y11=Y$4,'A&Rs'!$AA11,0)) -> 1593.8516 | Z7: =IF('A&Rs'!R11="","",Y7*(1+VLOOKUP(Z$4,'A&Rs'!$M$12:$N$21,2))+IF('A&Rs'!$Y11=Z$4,'A&Rs'!$AA11,0)) -> 1593.8516 | AA7: =IF('A&Rs'!R11="","",Z7*(1+VLOOKUP(AA$4,'A&Rs'!$M$12:$N$21,2))+IF('A&Rs'!$Y11=AA$4,'A&Rs'!$AA11,0)) -> 1609.7901 | AB7: =IF('A&Rs'!R11="","",AA7*(1+VLOOKUP(AB$4,'A&Rs'!$M$12:$N$21,2))+IF('A&Rs'!$Y11=AB$4,'A&Rs'!$AA11,0)) -> 1658.0838 | AC7: =IF('A&Rs'!R11="","",AB7*(1+VLOOKUP(AC$4,'A&Rs'!$M$12:$N$21,2))+IF('A&Rs'!$Y11=AC$4,'A&Rs'!$AA11,0)) -> 1691.2455 | AD7: =IF('A&Rs'!R11="","",AC7*(1+VLOOKUP(AD$4,'A&Rs'!$M$12:$N$21,2))+IF('A&Rs'!$Y11=AD$4,'A&Rs'!$AA11,0)) -> 1708.158 | AE7: =IF('A&Rs'!R11="","",AD7*(1+VLOOKUP(AE$4,'A&Rs'!$M$12:$N$21,2))+IF('A&Rs'!$Y11=AE$4,'A&Rs'!$AA11,0)) -> 1725.2395 | AF7: =IF('A&Rs'!R11="","",AE7*(1+VLOOKUP(AF$4,'A&Rs'!$M$12:$N$21,2))+IF('A&Rs'!$Y11=AF$4,'A&Rs'!$AA11,0)) -> 1742.4919 | AH7: =IF(AH$23<'A&Rs'!$T10,HLOOKUP(AH$21,$F$4:$Q$17,$B6),IF(AND(AH$23>='A&Rs'!$T10,AH$23<'A&Rs'!$V10),0,HLOOKUP(AH$21,$U$4:$AF$17,$B6)))
B8: 5 | D8: =D26 -> 3 | E8: =IF('A&Rs'!R12="","",'A&Rs'!T12) -> 1200 | F8: =IF('A&Rs'!R12="","",E8*(1+VLOOKUP(F$4,'A&Rs'!$M$12:$N$21,2))) -> 1200 | G8: =IF('A&Rs'!R12="","",F8*(1+VLOOKUP(G$4,'A&Rs'!$M$12:$N$21,2))) -> 1236 | H8: =IF('A&Rs'!R12="","",G8*(1+VLOOKUP(H$4,'A&Rs'!$M$12:$N$21,2))) -> 1260.72 | I8: =IF('A&Rs'!R12="","",H8*(1+VLOOKUP(I$4,'A&Rs'!$M$12:$N$21,2))) -> 1298.5416 | J8: =IF('A&Rs'!R12="","",I8*(1+VLOOKUP(J$4,'A&Rs'!$M$12:$N$21,2))) -> 1337.4978 | K8: =IF('A&Rs'!R12="","",J8*(1+VLOOKUP(K$4,'A&Rs'!$M$12:$N$21,2))) -> 1337.4978 | L8: =IF('A&Rs'!R12="","",K8*(1+VLOOKUP(L$4,'A&Rs'!$M$12:$N$21,2))) -> 1350.8728 | M8: =IF('A&Rs'!R12="","",L8*(1+VLOOKUP(M$4,'A&Rs'!$M$12:$N$21,2))) -> 1391.399 | N8: =IF('A&Rs'!R12="","",M8*(1+VLOOKUP(N$4,'A&Rs'!$M$12:$N$21,2))) -> 1419.227 | O8: =IF('A&Rs'!R12="","",N8*(1+VLOOKUP(O$4,'A&Rs'!$M$12:$N$21,2))) -> 1433.4193 | P8: =IF('A&Rs'!R12="","",O8*(1+VLOOKUP(P$4,'A&Rs'!$M$12:$N$21,2))) -> 1447.7535 | Q8: =IF('A&Rs'!R12="","",P8*(1+VLOOKUP(Q$4,'A&Rs'!$M$12:$N$21,2))) -> 1462.231 | S8: =D26 -> 3 | T8: =IF('A&Rs'!R12="","",'A&Rs'!T12) -> 1200 | U8: =IF('A&Rs'!R12="","",T8*(1+VLOOKUP(U$4,'A&Rs'!$M$12:$N$21,2))+IF('A&Rs'!$Y12=U$4,'A&Rs'!$AA12,0)) -> 1460 | V8: =IF('A&Rs'!R12="","",U8*(1+VLOOKUP(V$4,'A&Rs'!$M$12:$N$21,2))+IF('A&Rs'!$Y12=V$4,'A&Rs'!$AA12,0)) -> 1503.8 | W8: =IF('A&Rs'!R12="","",V8*(1+VLOOKUP(W$4,'A&Rs'!$M$12:$N$21,2))+IF('A&Rs'!$Y12=W$4,'A&Rs'!$AA12,0)) -> 1533.876 | X8: =IF('A&Rs'!R12="","",W8*(1+VLOOKUP(X$4,'A&Rs'!$M$12:$N$21,2))+IF('A&Rs'!$Y12=X$4,'A&Rs'!$AA12,0)) -> 1579.8923 | Y8: =IF('A&Rs'!R12="","",X8*(1+VLOOKUP(Y$4,'A&Rs'!$M$12:$N$21,2))+IF('A&Rs'!$Y12=Y$4,'A&Rs'!$AA12,0)) -> 1627.289 | Z8: =IF('A&Rs'!R12="","",Y8*(1+VLOOKUP(Z$4,'A&Rs'!$M$12:$N$21,2))+IF('A&Rs'!$Y12=Z$4,'A&Rs'!$AA12,0)) -> 1627.289 | AA8: =IF('A&Rs'!R12="","",Z8*(1+VLOOKUP(AA$4,'A&Rs'!$M$12:$N$21,2))+IF('A&Rs'!$Y12=AA$4,'A&Rs'!$AA12,0)) -> 1643.5619 | AB8: =IF('A&Rs'!R12="","",AA8*(1+VLOOKUP(AB$4,'A&Rs'!$M$12:$N$21,2))+IF('A&Rs'!$Y12=AB$4,'A&Rs'!$AA12,0)) -> 1692.8688 | AC8: =IF('A&Rs'!R12="","",AB8*(1+VLOOKUP(AC$4,'A&Rs'!$M$12:$N$21,2))+IF('A&Rs'!$Y12=AC$4,'A&Rs'!$AA12,0)) -> 1726.7262 | AD8: =IF('A&Rs'!R12="","",AC8*(1+VLOOKUP(AD$4,'A&Rs'!$M$12:$N$21,2))+IF('A&Rs'!$Y12=AD$4,'A&Rs'!$AA12,0)) -> 1743.9934 | AE8: =IF('A&Rs'!R12="","",AD8*(1+VLOOKUP(AE$4,'A&Rs'!$M$12:$N$21,2))+IF('A&Rs'!$Y12=AE$4,'A&Rs'!$AA12,0)) -> 1761.4334 | AF8: =IF('A&Rs'!R12="","",AE8*(1+VLOOKUP(AF$4,'A&Rs'!$M$12:$N$21,2))+IF('A&Rs'!$Y12=AF$4,'A&Rs'!$AA12,0)) -> 1779.0477
B9: 6 | D9: =D27 -> 4 | E9: =IF('A&Rs'!R13="","",'A&Rs'!T13) -> 1240 | F9: =IF('A&Rs'!R13="","",E9*(1+VLOOKUP(F$4,'A&Rs'!$M$12:$N$21,2))) -> 1240 | G9: =IF('A&Rs'!R13="","",F9*(1+VLOOKUP(G$4,'A&Rs'!$M$12:$N$21,2))) -> 1277.2 | H9: =IF('A&Rs'!R13="","",G9*(1+VLOOKUP(H$4,'A&Rs'!$M$12:$N$21,2))) -> 1302.744 | I9: =IF('A&Rs'!R13="","",H9*(1+VLOOKUP(I$4,'A&Rs'!$M$12:$N$21,2))) -> 1341.8263 | J9: =IF('A&Rs'!R13="","",I9*(1+VLOOKUP(J$4,'A&Rs'!$M$12:$N$21,2))) -> 1382.0811 | K9: =IF('A&Rs'!R13="","",J9*(1+VLOOKUP(K$4,'A&Rs'!$M$12:$N$21,2))) -> 1382.0811 | L9: =IF('A&Rs'!R13="","",K9*(1+VLOOKUP(L$4,'A&Rs'!$M$12:$N$21,2))) -> 1395.9019 | M9: =IF('A&Rs'!R13="","",L9*(1+VLOOKUP(M$4,'A&Rs'!$M$12:$N$21,2))) -> 1437.779 | N9: =IF('A&Rs'!R13="","",M9*(1+VLOOKUP(N$4,'A&Rs'!$M$12:$N$21,2))) -> 1466.5346 | O9: =IF('A&Rs'!R13="","",N9*(1+VLOOKUP(O$4,'A&Rs'!$M$12:$N$21,2))) -> 1481.1999 | P9: =IF('A&Rs'!R13="","",O9*(1+VLOOKUP(P$4,'A&Rs'!$M$12:$N$21,2))) -> 1496.0119 | Q9: =IF('A&Rs'!R13="","",P9*(1+VLOOKUP(Q$4,'A&Rs'!$M$12:$N$21,2))) -> 1510.972 | S9: =D27 -> 4 | T9: =IF('A&Rs'!R13="","",'A&Rs'!T13) -> 1240 | U9: =IF('A&Rs'!R13="","",T9*(1+VLOOKUP(U$4,'A&Rs'!$M$12:$N$21,2))+IF('A&Rs'!$Y13=U$4,'A&Rs'!$AA13,0)) -> 1500 | V9: =IF('A&Rs'!R13="","",U9*(1+VLOOKUP(V$4,'A&Rs'!$M$12:$N$21,2))+IF('A&Rs'!$Y13=V$4,'A&Rs'!$AA13,0)) -> 1545 | W9: =IF('A&Rs'!R13="","",V9*(1+VLOOKUP(W$4,'A&Rs'!$M$12:$N$21,2))+IF('A&Rs'!$Y13=W$4,'A&Rs'!$AA13,0)) -> 1575.9 | X9: =IF('A&Rs'!R13="","",W9*(1+VLOOKUP(X$4,'A&Rs'!$M$12:$N$21,2))+IF('A&Rs'!$Y13=X$4,'A&Rs'!$AA13,0)) -> 1623.177 | Y9: =IF('A&Rs'!R13="","",X9*(1+VLOOKUP(Y$4,'A&Rs'!$M$12:$N$21,2))+IF('A&Rs'!$Y13=Y$4,'A&Rs'!$AA13,0)) -> 1671.8723 | Z9: =IF('A&Rs'!R13="","",Y9*(1+VLOOKUP(Z$4,'A&Rs'!$M$12:$N$21,2))+IF('A&Rs'!$Y13=Z$4,'A&Rs'!$AA13,0)) -> 1671.8723 | AA9: =IF('A&Rs'!R13="","",Z9*(1+VLOOKUP(AA$4,'A&Rs'!$M$12:$N$21,2))+IF('A&Rs'!$Y13=AA$4,'A&Rs'!$AA13,0)) -> 1688.591 | AB9: =IF('A&Rs'!R13="","",AA9*(1+VLOOKUP(AB$4,'A&Rs'!$M$12:$N$21,2))+IF('A&Rs'!$Y13=AB$4,'A&Rs'!$AA13,0)) -> 1739.2488 | AC9: =IF('A&Rs'!R13="","",AB9*(1+VLOOKUP(AC$4,'A&Rs'!$M$12:$N$21,2))+IF('A&Rs'!$Y13=AC$4,'A&Rs'!$AA13,0)) -> 1774.0337 | AD9: =IF('A&Rs'!R13="","",AC9*(1+VLOOKUP(AD$4,'A&Rs'!$M$12:$N$21,2))+IF('A&Rs'!$Y13=AD$4,'A&Rs'!$AA13,0)) -> 1791.7741 | AE9: =IF('A&Rs'!R13="","",AD9*(1+VLOOKUP(AE$4,'A&Rs'!$M$12:$N$21,2))+IF('A&Rs'!$Y13=AE$4,'A&Rs'!$AA13,0)) -> 1809.6918 | AF9: =IF('A&Rs'!R13="","",AE9*(1+VLOOKUP(AF$4,'A&Rs'!$M$12:$N$21,2))+IF('A&Rs'!$Y13=AF$4,'A&Rs'!$AA13,0)) -> 1827.7887
B10: 7 | D10: =D28 -> 5 | E10: =IF('A&Rs'!R14="","",'A&Rs'!T14) -> 1312 | F10: =IF('A&Rs'!R14="","",E10*(1+VLOOKUP(F$4,'A&Rs'!$M$12:$N$21,2))) -> 1312 | G10: =IF('A&Rs'!R14="","",F10*(1+VLOOKUP(G$4,'A&Rs'!$M$12:$N$21,2))) -> 1351.36 | H10: =IF('A&Rs'!R14="","",G10*(1+VLOOKUP(H$4,'A&Rs'!$M$12:$N$21,2))) -> 1378.3872 | I10: =IF('A&Rs'!R14="","",H10*(1+VLOOKUP(I$4,'A&Rs'!$M$12:$N$21,2))) -> 1419.7388 | J10: =IF('A&Rs'!R14="","",I10*(1+VLOOKUP(J$4,'A&Rs'!$M$12:$N$21,2))) -> 1462.331 | K10: =IF('A&Rs'!R14="","",J10*(1+VLOOKUP(K$4,'A&Rs'!$M$12:$N$21,2))) -> 1462.331 | L10: =IF('A&Rs'!R14="","",K10*(1+VLOOKUP(L$4,'A&Rs'!$M$12:$N$21,2))) -> 1476.9543 | M10: =IF('A&Rs'!R14="","",L10*(1+VLOOKUP(M$4,'A&Rs'!$M$12:$N$21,2))) -> 1521.2629 | N10: =IF('A&Rs'!R14="","",M10*(1+VLOOKUP(N$4,'A&Rs'!$M$12:$N$21,2))) -> 1551.6882 | O10: =IF('A&Rs'!R14="","",N10*(1+VLOOKUP(O$4,'A&Rs'!$M$12:$N$21,2))) -> 1567.2051 | P10: =IF('A&Rs'!R14="","",O10*(1+VLOOKUP(P$4,'A&Rs'!$M$12:$N$21,2))) -> 1582.8771 | Q10: =IF('A&Rs'!R14="","",P10*(1+VLOOKUP(Q$4,'A&Rs'!$M$12:$N$21,2))) -> 1598.7059 | S10: =D28 -> 5 | T10: =IF('A&Rs'!R14="","",'A&Rs'!T14) -> 1312 | U10: =IF('A&Rs'!R14="","",T10*(1+VLOOKUP(U$4,'A&Rs'!$M$12:$N$21,2))+IF('A&Rs'!$Y14=U$4,'A&Rs'!$AA14,0)) -> 1592 | V10: =IF('A&Rs'!R14="","",U10*(1+VLOOKUP(V$4,'A&Rs'!$M$12:$N$21,2))+IF('A&Rs'!$Y14=V$4,'A&Rs'!$AA14,0)) -> 1639.76 | W10: =IF('A&Rs'!R14="","",V10*(1+VLOOKUP(W$4,'A&Rs'!$M$12:$N$21,2))+IF('A&Rs'!$Y14=W$4,'A&Rs'!$AA14,0)) -> 1672.5552 | X10: =IF('A&Rs'!R14="","",W10*(1+VLOOKUP(X$4,'A&Rs'!$M$12:$N$21,2))+IF('A&Rs'!$Y14=X$4,'A&Rs'!$AA14,0)) -> 1722.7319 | Y10: =IF('A&Rs'!R14="","",X10*(1+VLOOKUP(Y$4,'A&Rs'!$M$12:$N$21,2))+IF('A&Rs'!$Y14=Y$4,'A&Rs'!$AA14,0)) -> 1774.4138 | Z10: =IF('A&Rs'!R14="","",Y10*(1+VLOOKUP(Z$4,'A&Rs'!$M$12:$N$21,2))+IF('A&Rs'!$Y14=Z$4,'A&Rs'!$AA14,0)) -> 1774.4138 | AA10: =IF('A&Rs'!R14="","",Z10*(1+VLOOKUP(AA$4,'A&Rs'!$M$12:$N$21,2))+IF('A&Rs'!$Y14=AA$4,'A&Rs'!$AA14,0)) -> 1792.1579 | AB10: =IF('A&Rs'!R14="","",AA10*(1+VLOOKUP(AB$4,'A&Rs'!$M$12:$N$21,2))+IF('A&Rs'!$Y14=AB$4,'A&Rs'!$AA14,0)) -> 1845.9227 | AC10: =IF('A&Rs'!R14="","",AB10*(1+VLOOKUP(AC$4,'A&Rs'!$M$12:$N$21,2))+IF('A&Rs'!$Y14=AC$4,'A&Rs'!$AA14,0)) -> 1882.8411 | AD10: =IF('A&Rs'!R14="","",AC10*(1+VLOOKUP(AD$4,'A&Rs'!$M$12:$N$21,2))+IF('A&Rs'!$Y14=AD$4,'A&Rs'!$AA14,0)) -> 1901.6696 | AE10: =IF('A&Rs'!R14="","",AD10*(1+VLOOKUP(AE$4,'A&Rs'!$M$12:$N$21,2))+IF('A&Rs'!$Y14=AE$4,'A&Rs'!$AA14,0)) -> 1920.6862 | AF10: =IF('A&Rs'!R14="","",AE10*(1+VLOOKUP(AF$4,'A&Rs'!$M$12:$N$21,2))+IF('A&Rs'!$Y14=AF$4,'A&Rs'!$AA14,0)) -> 1939.8931
B11: 8 | D11: =D29 -> 6 | E11: =IF('A&Rs'!R15="","",'A&Rs'!T15) -> 1346 | F11: =IF('A&Rs'!R15="","",E11*(1+VLOOKUP(F$4,'A&Rs'!$M$12:$N$21,2))) -> 1346 | G11: =IF('A&Rs'!R15="","",F11*(1+VLOOKUP(G$4,'A&Rs'!$M$12:$N$21,2))) -> 1386.38 | H11: =IF('A&Rs'!R15="","",G11*(1+VLOOKUP(H$4,'A&Rs'!$M$12:$N$21,2))) -> 1414.1076 | I11: =IF('A&Rs'!R15="","",H11*(1+VLOOKUP(I$4,'A&Rs'!$M$12:$N$21,2))) -> 1456.5308 | J11: =IF('A&Rs'!R15="","",I11*(1+VLOOKUP(J$4,'A&Rs'!$M$12:$N$21,2))) -> 1500.2268 | K11: =IF('A&Rs'!R15="","",J11*(1+VLOOKUP(K$4,'A&Rs'!$M$12:$N$21,2))) -> 1500.2268 | L11: =IF('A&Rs'!R15="","",K11*(1+VLOOKUP(L$4,'A&Rs'!$M$12:$N$21,2))) -> 1515.229 | M11: =IF('A&Rs'!R15="","",L11*(1+VLOOKUP(M$4,'A&Rs'!$M$12:$N$21,2))) -> 1560.6859 | N11: =IF('A&Rs'!R15="","",M11*(1+VLOOKUP(N$4,'A&Rs'!$M$12:$N$21,2))) -> 1591.8996 | O11: =IF('A&Rs'!R15="","",N11*(1+VLOOKUP(O$4,'A&Rs'!$M$12:$N$21,2))) -> 1607.8186 | P11: =IF('A&Rs'!R15="","",O11*(1+VLOOKUP(P$4,'A&Rs'!$M$12:$N$21,2))) -> 1623.8968 | Q11: =IF('A&Rs'!R15="","",P11*(1+VLOOKUP(Q$4,'A&Rs'!$M$12:$N$21,2))) -> 1640.1358 | S11: =D29 -> 6 | T11: =IF('A&Rs'!R15="","",'A&Rs'!T15) -> 1346 | U11: =IF('A&Rs'!R15="","",T11*(1+VLOOKUP(U$4,'A&Rs'!$M$12:$N$21,2))+IF('A&Rs'!$Y15=U$4,'A&Rs'!$AA15,0)) -> 1626 | V11: =IF('A&Rs'!R15="","",U11*(1+VLOOKUP(V$4,'A&Rs'!$M$12:$N$21,2))+IF('A&Rs'!$Y15=V$4,'A&Rs'!$AA15,0)) -> 1674.78 | W11: =IF('A&Rs'!R15="","",V11*(1+VLOOKUP(W$4,'A&Rs'!$M$12:$N$21,2))+IF('A&Rs'!$Y15=W$4,'A&Rs'!$AA15,0)) -> 1708.2756 | X11: =IF('A&Rs'!R15="","",W11*(1+VLOOKUP(X$4,'A&Rs'!$M$12:$N$21,2))+IF('A&Rs'!$Y15=X$4,'A&Rs'!$AA15,0)) -> 1759.5239 | Y11: =IF('A&Rs'!R15="","",X11*(1+VLOOKUP(Y$4,'A&Rs'!$M$12:$N$21,2))+IF('A&Rs'!$Y15=Y$4,'A&Rs'!$AA15,0)) -> 1812.3096 | Z11: =IF('A&Rs'!R15="","",Y11*(1+VLOOKUP(Z$4,'A&Rs'!$M$12:$N$21,2))+IF('A&Rs'!$Y15=Z$4,'A&Rs'!$AA15,0)) -> 1812.3096 | AA11: =IF('A&Rs'!R15="","",Z11*(1+VLOOKUP(AA$4,'A&Rs'!$M$12:$N$21,2))+IF('A&Rs'!$Y15=AA$4,'A&Rs'!$AA15,0)) -> 1830.4327 | AB11: =IF('A&Rs'!R15="","",AA11*(1+VLOOKUP(AB$4,'A&Rs'!$M$12:$N$21,2))+IF('A&Rs'!$Y15=AB$4,'A&Rs'!$AA15,0)) -> 1885.3457 | AC11: =IF('A&Rs'!R15="","",AB11*(1+VLOOKUP(AC$4,'A&Rs'!$M$12:$N$21,2))+IF('A&Rs'!$Y15=AC$4,'A&Rs'!$AA15,0)) -> 1923.0526 | AD11: =IF('A&Rs'!R15="","",AC11*(1+VLOOKUP(AD$4,'A&Rs'!$M$12:$N$21,2))+IF('A&Rs'!$Y15=AD$4,'A&Rs'!$AA15,0)) -> 1942.2831 | AE11: =IF('A&Rs'!R15="","",AD11*(1+VLOOKUP(AE$4,'A&Rs'!$M$12:$N$21,2))+IF('A&Rs'!$Y15=AE$4,'A&Rs'!$AA15,0)) -> 1961.7059 | AF11: =IF('A&Rs'!R15="","",AE11*(1+VLOOKUP(AF$4,'A&Rs'!$M$12:$N$21,2))+IF('A&Rs'!$Y15=AF$4,'A&Rs'!$AA15,0)) -> 1981.323
B12: 9 | D12: =D30 -> 7 | E12: =IF('A&Rs'!R16="","",'A&Rs'!T16) -> 1413 | F12: =IF('A&Rs'!R16="","",E12*(1+VLOOKUP(F$4,'A&Rs'!$M$12:$N$21,2))) -> 1413 | G12: =IF('A&Rs'!R16="","",F12*(1+VLOOKUP(G$4,'A&Rs'!$M$12:$N$21,2))) -> 1455.39 | H12: =IF('A&Rs'!R16="","",G12*(1+VLOOKUP(H$4,'A&Rs'!$M$12:$N$21,2))) -> 1484.4978 | I12: =IF('A&Rs'!R16="","",H12*(1+VLOOKUP(I$4,'A&Rs'!$M$12:$N$21,2))) -> 1529.0327 | J12: =IF('A&Rs'!R16="","",I12*(1+VLOOKUP(J$4,'A&Rs'!$M$12:$N$21,2))) -> 1574.9037 | K12: =IF('A&Rs'!R16="","",J12*(1+VLOOKUP(K$4,'A&Rs'!$M$12:$N$21,2))) -> 1574.9037 | L12: =IF('A&Rs'!R16="","",K12*(1+VLOOKUP(L$4,'A&Rs'!$M$12:$N$21,2))) -> 1590.6528 | M12: =IF('A&Rs'!R16="","",L12*(1+VLOOKUP(M$4,'A&Rs'!$M$12:$N$21,2))) -> 1638.3723 | N12: =IF('A&Rs'!R16="","",M12*(1+VLOOKUP(N$4,'A&Rs'!$M$12:$N$21,2))) -> 1671.1398 | O12: =IF('A&Rs'!R16="","",N12*(1+VLOOKUP(O$4,'A&Rs'!$M$12:$N$21,2))) -> 1687.8512 | P12: =IF('A&Rs'!R16="","",O12*(1+VLOOKUP(P$4,'A&Rs'!$M$12:$N$21,2))) -> 1704.7297 | Q12: =IF('A&Rs'!R16="","",P12*(1+VLOOKUP(Q$4,'A&Rs'!$M$12:$N$21,2))) -> 1721.777 | S12: =D30 -> 7 | T12: =IF('A&Rs'!R16="","",'A&Rs'!T16) -> 1413 | U12: =IF('A&Rs'!R16="","",T12*(1+VLOOKUP(U$4,'A&Rs'!$M$12:$N$21,2))+IF('A&Rs'!$Y16=U$4,'A&Rs'!$AA16,0)) -> 1693 | V12: =IF('A&Rs'!R16="","",U12*(1+VLOOKUP(V$4,'A&Rs'!$M$12:$N$21,2))+IF('A&Rs'!$Y16=V$4,'A&Rs'!$AA16,0)) -> 1743.79 | W12: =IF('A&Rs'!R16="","",V12*(1+VLOOKUP(W$4,'A&Rs'!$M$12:$N$21,2))+IF('A&Rs'!$Y16=W$4,'A&Rs'!$AA16,0)) -> 1778.6658 | X12: =IF('A&Rs'!R16="","",W12*(1+VLOOKUP(X$4,'A&Rs'!$M$12:$N$21,2))+IF('A&Rs'!$Y16=X$4,'A&Rs'!$AA16,0)) -> 1832.0258 | Y12: =IF('A&Rs'!R16="","",X12*(1+VLOOKUP(Y$4,'A&Rs'!$M$12:$N$21,2))+IF('A&Rs'!$Y16=Y$4,'A&Rs'!$AA16,0)) -> 1886.9865 | Z12: =IF('A&Rs'!R16="","",Y12*(1+VLOOKUP(Z$4,'A&Rs'!$M$12:$N$21,2))+IF('A&Rs'!$Y16=Z$4,'A&Rs'!$AA16,0)) -> 1886.9865 | AA12: =IF('A&Rs'!R16="","",Z12*(1+VLOOKUP(AA$4,'A&Rs'!$M$12:$N$21,2))+IF('A&Rs'!$Y16=AA$4,'A&Rs'!$AA16,0)) -> 1905.8564 | AB12: =IF('A&Rs'!R16="","",AA12*(1+VLOOKUP(AB$4,'A&Rs'!$M$12:$N$21,2))+IF('A&Rs'!$Y16=AB$4,'A&Rs'!$AA16,0)) -> 1963.0321 | AC12: =IF('A&Rs'!R16="","",AB12*(1+VLOOKUP(AC$4,'A&Rs'!$M$12:$N$21,2))+IF('A&Rs'!$Y16=AC$4,'A&Rs'!$AA16,0)) -> 2002.2927 | AD12: =IF('A&Rs'!R16="","",AC12*(1+VLOOKUP(AD$4,'A&Rs'!$M$12:$N$21,2))+IF('A&Rs'!$Y16=AD$4,'A&Rs'!$AA16,0)) -> 2022.3157 | AE12: =IF('A&Rs'!R16="","",AD12*(1+VLOOKUP(AE$4,'A&Rs'!$M$12:$N$21,2))+IF('A&Rs'!$Y16=AE$4,'A&Rs'!$AA16,0)) -> 2042.5388 | AF12: =IF('A&Rs'!R16="","",AE12*(1+VLOOKUP(AF$4,'A&Rs'!$M$12:$N$21,2))+IF('A&Rs'!$Y16=AF$4,'A&Rs'!$AA16,0)) -> 2062.9642
B13: 10 | D13: =D31 -> 8 | E13: =IF('A&Rs'!R17="","",'A&Rs'!T17) -> 1480 | F13: =IF('A&Rs'!R17="","",E13*(1+VLOOKUP(F$4,'A&Rs'!$M$12:$N$21,2))) -> 1480 | G13: =IF('A&Rs'!R17="","",F13*(1+VLOOKUP(G$4,'A&Rs'!$M$12:$N$21,2))) -> 1524.4 | H13: =IF('A&Rs'!R17="","",G13*(1+VLOOKUP(H$4,'A&Rs'!$M$12:$N$21,2))) -> 1554.888 | I13: =IF('A&Rs'!R17="","",H13*(1+VLOOKUP(I$4,'A&Rs'!$M$12:$N$21,2))) -> 1601.5346 | J13: =IF('A&Rs'!R17="","",I13*(1+VLOOKUP(J$4,'A&Rs'!$M$12:$N$21,2))) -> 1649.5807 | K13: =IF('A&Rs'!R17="","",J13*(1+VLOOKUP(K$4,'A&Rs'!$M$12:$N$21,2))) -> 1649.5807 | L13: =IF('A&Rs'!R17="","",K13*(1+VLOOKUP(L$4,'A&Rs'!$M$12:$N$21,2))) -> 1666.0765 | M13: =IF('A&Rs'!R17="","",L13*(1+VLOOKUP(M$4,'A&Rs'!$M$12:$N$21,2))) -> 1716.0588 | N13: =IF('A&Rs'!R17="","",M13*(1+VLOOKUP(N$4,'A&Rs'!$M$12:$N$21,2))) -> 1750.38 | O13: =IF('A&Rs'!R17="","",N13*(1+VLOOKUP(O$4,'A&Rs'!$M$12:$N$21,2))) -> 1767.8838 | P13: =IF('A&Rs'!R17="","",O13*(1+VLOOKUP(P$4,'A&Rs'!$M$12:$N$21,2))) -> 1785.5626 | Q13: =IF('A&Rs'!R17="","",P13*(1+VLOOKUP(Q$4,'A&Rs'!$M$12:$N$21,2))) -> 1803.4182 | S13: =D31 -> 8 | T13: =IF('A&Rs'!R17="","",'A&Rs'!T17) -> 1480 | U13: =IF('A&Rs'!R17="","",T13*(1+VLOOKUP(U$4,'A&Rs'!$M$12:$N$21,2))+IF('A&Rs'!$Y17=U$4,'A&Rs'!$AA17,0)) -> 1740 | V13: =IF('A&Rs'!R17="","",U13*(1+VLOOKUP(V$4,'A&Rs'!$M$12:$N$21,2))+IF('A&Rs'!$Y17=V$4,'A&Rs'!$AA17,0)) -> 1792.2 | W13: =IF('A&Rs'!R17="","",V13*(1+VLOOKUP(W$4,'A&Rs'!$M$12:$N$21,2))+IF('A&Rs'!$Y17=W$4,'A&Rs'!$AA17,0)) -> 1828.044 | X13: =IF('A&Rs'!R17="","",W13*(1+VLOOKUP(X$4,'A&Rs'!$M$12:$N$21,2))+IF('A&Rs'!$Y17=X$4,'A&Rs'!$AA17,0)) -> 1882.8853 | Y13: =IF('A&Rs'!R17="","",X13*(1+VLOOKUP(Y$4,'A&Rs'!$M$12:$N$21,2))+IF('A&Rs'!$Y17=Y$4,'A&Rs'!$AA17,0)) -> 1939.3719 | Z13: =IF('A&Rs'!R17="","",Y13*(1+VLOOKUP(Z$4,'A&Rs'!$M$12:$N$21,2))+IF('A&Rs'!$Y17=Z$4,'A&Rs'!$AA17,0)) -> 1939.3719 | AA13: =IF('A&Rs'!R17="","",Z13*(1+VLOOKUP(AA$4,'A&Rs'!$M$12:$N$21,2))+IF('A&Rs'!$Y17=AA$4,'A&Rs'!$AA17,0)) -> 1958.7656 | AB13: =IF('A&Rs'!R17="","",AA13*(1+VLOOKUP(AB$4,'A&Rs'!$M$12:$N$21,2))+IF('A&Rs'!$Y17=AB$4,'A&Rs'!$AA17,0)) -> 2017.5286 | AC13: =IF('A&Rs'!R17="","",AB13*(1+VLOOKUP(AC$4,'A&Rs'!$M$12:$N$21,2))+IF('A&Rs'!$Y17=AC$4,'A&Rs'!$AA17,0)) -> 2057.8791 | AD13: =IF('A&Rs'!R17="","",AC13*(1+VLOOKUP(AD$4,'A&Rs'!$M$12:$N$21,2))+IF('A&Rs'!$Y17=AD$4,'A&Rs'!$AA17,0)) -> 2078.4579 | AE13: =IF('A&Rs'!R17="","",AD13*(1+VLOOKUP(AE$4,'A&Rs'!$M$12:$N$21,2))+IF('A&Rs'!$Y17=AE$4,'A&Rs'!$AA17,0)) -> 2099.2425 | AF13: =IF('A&Rs'!R17="","",AE13*(1+VLOOKUP(AF$4,'A&Rs'!$M$12:$N$21,2))+IF('A&Rs'!$Y17=AF$4,'A&Rs'!$AA17,0)) -> 2120.2349
B14: 11 | D14: =D32 -> 11 | E14: =IF('A&Rs'!R18="","",'A&Rs'!T18) -> 1548 | F14: =IF('A&Rs'!R18="","",E14*(1+VLOOKUP(F$4,'A&Rs'!$M$12:$N$21,2))) -> 1548 | G14: =IF('A&Rs'!R18="","",F14*(1+VLOOKUP(G$4,'A&Rs'!$M$12:$N$21,2))) -> 1594.44 | H14: =IF('A&Rs'!R18="","",G14*(1+VLOOKUP(H$4,'A&Rs'!$M$12:$N$21,2))) -> 1626.3288 | I14: =IF('A&Rs'!R18="","",H14*(1+VLOOKUP(I$4,'A&Rs'!$M$12:$N$21,2))) -> 1675.1187 | J14: =IF('A&Rs'!R18="","",I14*(1+VLOOKUP(J$4,'A&Rs'!$M$12:$N$21,2))) -> 1725.3722 | K14: =IF('A&Rs'!R18="","",J14*(1+VLOOKUP(K$4,'A&Rs'!$M$12:$N$21,2))) -> 1725.3722 | L14: =IF('A&Rs'!R18="","",K14*(1+VLOOKUP(L$4,'A&Rs'!$M$12:$N$21,2))) -> 1742.6259 | M14: =IF('A&Rs'!R18="","",L14*(1+VLOOKUP(M$4,'A&Rs'!$M$12:$N$21,2))) -> 1794.9047 | N14: =IF('A&Rs'!R18="","",M14*(1+VLOOKUP(N$4,'A&Rs'!$M$12:$N$21,2))) -> 1830.8028 | O14: =IF('A&Rs'!R18="","",N14*(1+VLOOKUP(O$4,'A&Rs'!$M$12:$N$21,2))) -> 1849.1108 | P14: =IF('A&Rs'!R18="","",O14*(1+VLOOKUP(P$4,'A&Rs'!$M$12:$N$21,2))) -> 1867.602 | Q14: =IF('A&Rs'!R18="","",P14*(1+VLOOKUP(Q$4,'A&Rs'!$M$12:$N$21,2))) -> 1886.278 | S14: =D32 -> 11 | T14: =IF('A&Rs'!R18="","",'A&Rs'!T18) -> 1548 | U14: =IF('A&Rs'!R18="","",T14*(1+VLOOKUP(U$4,'A&Rs'!$M$12:$N$21,2))+IF('A&Rs'!$Y18=U$4,'A&Rs'!$AA18,0)) -> 1548 | V14: =IF('A&Rs'!R18="","",U14*(1+VLOOKUP(V$4,'A&Rs'!$M$12:$N$21,2))+IF('A&Rs'!$Y18=V$4,'A&Rs'!$AA18,0)) -> 1894.44 | W14: =IF('A&Rs'!R18="","",V14*(1+VLOOKUP(W$4,'A&Rs'!$M$12:$N$21,2))+IF('A&Rs'!$Y18=W$4,'A&Rs'!$AA18,0)) -> 1932.3288 | X14: =IF('A&Rs'!R18="","",W14*(1+VLOOKUP(X$4,'A&Rs'!$M$12:$N$21,2))+IF('A&Rs'!$Y18=X$4,'A&Rs'!$AA18,0)) -> 1990.2987 | Y14: =IF('A&Rs'!R18="","",X14*(1+VLOOKUP(Y$4,'A&Rs'!$M$12:$N$21,2))+IF('A&Rs'!$Y18=Y$4,'A&Rs'!$AA18,0)) -> 2050.0076 | Z14: =IF('A&Rs'!R18="","",Y14*(1+VLOOKUP(Z$4,'A&Rs'!$M$12:$N$21,2))+IF('A&Rs'!$Y18=Z$4,'A&Rs'!$AA18,0)) -> 2050.0076 | AA14: =IF('A&Rs'!R18="","",Z14*(1+VLOOKUP(AA$4,'A&Rs'!$M$12:$N$21,2))+IF('A&Rs'!$Y18=AA$4,'A&Rs'!$AA18,0)) -> 2070.5077 | AB14: =IF('A&Rs'!R18="","",AA14*(1+VLOOKUP(AB$4,'A&Rs'!$M$12:$N$21,2))+IF('A&Rs'!$Y18=AB$4,'A&Rs'!$AA18,0)) -> 2132.6229 | AC14: =IF('A&Rs'!R18="","",AB14*(1+VLOOKUP(AC$4,'A&Rs'!$M$12:$N$21,2))+IF('A&Rs'!$Y18=AC$4,'A&Rs'!$AA18,0)) -> 2175.2754 | AD14: =IF('A&Rs'!R18="","",AC14*(1+VLOOKUP(AD$4,'A&Rs'!$M$12:$N$21,2))+IF('A&Rs'!$Y18=AD$4,'A&Rs'!$AA18,0)) -> 2197.0281 | AE14: =IF('A&Rs'!R18="","",AD14*(1+VLOOKUP(AE$4,'A&Rs'!$M$12:$N$21,2))+IF('A&Rs'!$Y18=AE$4,'A&Rs'!$AA18,0)) -> 2218.9984 | AF14: =IF('A&Rs'!R18="","",AE14*(1+VLOOKUP(AF$4,'A&Rs'!$M$12:$N$21,2))+IF('A&Rs'!$Y18=AF$4,'A&Rs'!$AA18,0)) -> 2241.1884
B15: 12 | D15: =D33 -> 10 | E15: =IF('A&Rs'!R19="","",'A&Rs'!T19) -> 1750 | F15: =IF('A&Rs'!R19="","",E15*(1+VLOOKUP(F$4,'A&Rs'!$M$12:$N$21,2))) -> 1750 | G15: =IF('A&Rs'!R19="","",F15*(1+VLOOKUP(G$4,'A&Rs'!$M$12:$N$21,2))) -> 1802.5 | H15: =IF('A&Rs'!R19="","",G15*(1+VLOOKUP(H$4,'A&Rs'!$M$12:$N$21,2))) -> 1838.55 | I15: =IF('A&Rs'!R19="","",H15*(1+VLOOKUP(I$4,'A&Rs'!$M$12:$N$21,2))) -> 1893.7065 | J15: =IF('A&Rs'!R19="","",I15*(1+VLOOKUP(J$4,'A&Rs'!$M$12:$N$21,2))) -> 1950.5177 | K15: =IF('A&Rs'!R19="","",J15*(1+VLOOKUP(K$4,'A&Rs'!$M$12:$N$21,2))) -> 1950.5177 | L15: =IF('A&Rs'!R19="","",K15*(1+VLOOKUP(L$4,'A&Rs'!$M$12:$N$21,2))) -> 1970.0229 | M15: =IF('A&Rs'!R19="","",L15*(1+VLOOKUP(M$4,'A&Rs'!$M$12:$N$21,2))) -> 2029.1236 | N15: =IF('A&Rs'!R19="","",M15*(1+VLOOKUP(N$4,'A&Rs'!$M$12:$N$21,2))) -> 2069.706 | O15: =IF('A&Rs'!R19="","",N15*(1+VLOOKUP(O$4,'A&Rs'!$M$12:$N$21,2))) -> 2090.4031 | P15: =IF('A&Rs'!R19="","",O15*(1+VLOOKUP(P$4,'A&Rs'!$M$12:$N$21,2))) -> 2111.3071 | Q15: =IF('A&Rs'!R19="","",P15*(1+VLOOKUP(Q$4,'A&Rs'!$M$12:$N$21,2))) -> 2132.4202 | S15: =D33 -> 10 | T15: =IF('A&Rs'!R19="","",'A&Rs'!T19) -> 1750 | U15: =IF('A&Rs'!R19="","",T15*(1+VLOOKUP(U$4,'A&Rs'!$M$12:$N$21,2))+IF('A&Rs'!$Y19=U$4,'A&Rs'!$AA19,0)) -> 1750 | V15: =IF('A&Rs'!R19="","",U15*(1+VLOOKUP(V$4,'A&Rs'!$M$12:$N$21,2))+IF('A&Rs'!$Y19=V$4,'A&Rs'!$AA19,0)) -> 2102.5 | W15: =IF('A&Rs'!R19="","",V15*(1+VLOOKUP(W$4,'A&Rs'!$M$12:$N$21,2))+IF('A&Rs'!$Y19=W$4,'A&Rs'!$AA19,0)) -> 2144.55 | X15: =IF('A&Rs'!R19="","",W15*(1+VLOOKUP(X$4,'A&Rs'!$M$12:$N$21,2))+IF('A&Rs'!$Y19=X$4,'A&Rs'!$AA19,0)) -> 2208.8865 | Y15: =IF('A&Rs'!R19="","",X15*(1+VLOOKUP(Y$4,'A&Rs'!$M$12:$N$21,2))+IF('A&Rs'!$Y19=Y$4,'A&Rs'!$AA19,0)) -> 2275.1531 | Z15: =IF('A&Rs'!R19="","",Y15*(1+VLOOKUP(Z$4,'A&Rs'!$M$12:$N$21,2))+IF('A&Rs'!$Y19=Z$4,'A&Rs'!$AA19,0)) -> 2275.1531 | AA15: =IF('A&Rs'!R19="","",Z15*(1+VLOOKUP(AA$4,'A&Rs'!$M$12:$N$21,2))+IF('A&Rs'!$Y19=AA$4,'A&Rs'!$AA19,0)) -> 2297.9046 | AB15: =IF('A&Rs'!R19="","",AA15*(1+VLOOKUP(AB$4,'A&Rs'!$M$12:$N$21,2))+IF('A&Rs'!$Y19=AB$4,'A&Rs'!$AA19,0)) -> 2366.8418 | AC15: =IF('A&Rs'!R19="","",AB15*(1+VLOOKUP(AC$4,'A&Rs'!$M$12:$N$21,2))+IF('A&Rs'!$Y19=AC$4,'A&Rs'!$AA19,0)) -> 2414.1786 | AD15: =IF('A&Rs'!R19="","",AC15*(1+VLOOKUP(AD$4,'A&Rs'!$M$12:$N$21,2))+IF('A&Rs'!$Y19=AD$4,'A&Rs'!$AA19,0)) -> 2438.3204 | AE15: =IF('A&Rs'!R19="","",AD15*(1+VLOOKUP(AE$4,'A&Rs'!$M$12:$N$21,2))+IF('A&Rs'!$Y19=AE$4,'A&Rs'!$AA19,0)) -> 2462.7036 | AF15: =IF('A&Rs'!R19="","",AE15*(1+VLOOKUP(AF$4,'A&Rs'!$M$12:$N$21,2))+IF('A&Rs'!$Y19=AF$4,'A&Rs'!$AA19,0)) -> 2487.3306
B16: 13 | D16: =D34 -> 9 | E16: =IF('A&Rs'!R20="","",'A&Rs'!T20) -> 1884 | F16: =IF('A&Rs'!R20="","",E16*(1+VLOOKUP(F$4,'A&Rs'!$M$12:$N$21,2))) -> 1884 | G16: =IF('A&Rs'!R20="","",F16*(1+VLOOKUP(G$4,'A&Rs'!$M$12:$N$21,2))) -> 1940.52 | H16: =IF('A&Rs'!R20="","",G16*(1+VLOOKUP(H$4,'A&Rs'!$M$12:$N$21,2))) -> 1979.3304 | I16: =IF('A&Rs'!R20="","",H16*(1+VLOOKUP(I$4,'A&Rs'!$M$12:$N$21,2))) -> 2038.7103 | J16: =IF('A&Rs'!R20="","",I16*(1+VLOOKUP(J$4,'A&Rs'!$M$12:$N$21,2))) -> 2099.8716 | K16: =IF('A&Rs'!R20="","",J16*(1+VLOOKUP(K$4,'A&Rs'!$M$12:$N$21,2))) -> 2099.8716 | L16: =IF('A&Rs'!R20="","",K16*(1+VLOOKUP(L$4,'A&Rs'!$M$12:$N$21,2))) -> 2120.8703 | M16: =IF('A&Rs'!R20="","",L16*(1+VLOOKUP(M$4,'A&Rs'!$M$12:$N$21,2))) -> 2184.4964 | N16: =IF('A&Rs'!R20="","",M16*(1+VLOOKUP(N$4,'A&Rs'!$M$12:$N$21,2))) -> 2228.1864 | O16: =IF('A&Rs'!R20="","",N16*(1+VLOOKUP(O$4,'A&Rs'!$M$12:$N$21,2))) -> 2250.4682 | P16: =IF('A&Rs'!R20="","",O16*(1+VLOOKUP(P$4,'A&Rs'!$M$12:$N$21,2))) -> 2272.9729 | Q16: =IF('A&Rs'!R20="","",P16*(1+VLOOKUP(Q$4,'A&Rs'!$M$12:$N$21,2))) -> 2295.7027 | S16: =D34 -> 9 | T16: =IF('A&Rs'!R20="","",'A&Rs'!T20) -> 1884 | U16: =IF('A&Rs'!R20="","",T16*(1+VLOOKUP(U$4,'A&Rs'!$M$12:$N$21,2))+IF('A&Rs'!$Y20=U$4,'A&Rs'!$AA20,0)) -> 1884 | V16: =IF('A&Rs'!R20="","",U16*(1+VLOOKUP(V$4,'A&Rs'!$M$12:$N$21,2))+IF('A&Rs'!$Y20=V$4,'A&Rs'!$AA20,0)) -> 2240.52 | W16: =IF('A&Rs'!R20="","",V16*(1+VLOOKUP(W$4,'A&Rs'!$M$12:$N$21,2))+IF('A&Rs'!$Y20=W$4,'A&Rs'!$AA20,0)) -> 2285.3304 | X16: =IF('A&Rs'!R20="","",W16*(1+VLOOKUP(X$4,'A&Rs'!$M$12:$N$21,2))+IF('A&Rs'!$Y20=X$4,'A&Rs'!$AA20,0)) -> 2353.8903 | Y16: =IF('A&Rs'!R20="","",X16*(1+VLOOKUP(Y$4,'A&Rs'!$M$12:$N$21,2))+IF('A&Rs'!$Y20=Y$4,'A&Rs'!$AA20,0)) -> 2424.507 | Z16: =IF('A&Rs'!R20="","",Y16*(1+VLOOKUP(Z$4,'A&Rs'!$M$12:$N$21,2))+IF('A&Rs'!$Y20=Z$4,'A&Rs'!$AA20,0)) -> 2424.507 | AA16: =IF('A&Rs'!R20="","",Z16*(1+VLOOKUP(AA$4,'A&Rs'!$M$12:$N$21,2))+IF('A&Rs'!$Y20=AA$4,'A&Rs'!$AA20,0)) -> 2448.7521 | AB16: =IF('A&Rs'!R20="","",AA16*(1+VLOOKUP(AB$4,'A&Rs'!$M$12:$N$21,2))+IF('A&Rs'!$Y20=AB$4,'A&Rs'!$AA20,0)) -> 2522.2147 | AC16: =IF('A&Rs'!R20="","",AB16*(1+VLOOKUP(AC$4,'A&Rs'!$M$12:$N$21,2))+IF('A&Rs'!$Y20=AC$4,'A&Rs'!$AA20,0)) -> 2572.6589 | AD16: =IF('A&Rs'!R20="","",AC16*(1+VLOOKUP(AD$4,'A&Rs'!$M$12:$N$21,2))+IF('A&Rs'!$Y20=AD$4,'A&Rs'!$AA20,0)) -> 2598.3855 | AE16: =IF('A&Rs'!R20="","",AD16*(1+VLOOKUP(AE$4,'A&Rs'!$M$12:$N$21,2))+IF('A&Rs'!$Y20=AE$4,'A&Rs'!$AA20,0)) -> 2624.3694 | AF16: =IF('A&Rs'!R20="","",AE16*(1+VLOOKUP(AF$4,'A&Rs'!$M$12:$N$21,2))+IF('A&Rs'!$Y20=AF$4,'A&Rs'!$AA20,0)) -> 2650.6131
B17: 14 | D17: =D35 -> 12 | E17: =IF('A&Rs'!R21="","",'A&Rs'!T21) -> 1900 | F17: =IF('A&Rs'!R21="","",E17*(1+VLOOKUP(F$4,'A&Rs'!$M$12:$N$21,2))) -> 1900 | G17: =IF('A&Rs'!R21="","",F17*(1+VLOOKUP(G$4,'A&Rs'!$M$12:$N$21,2))) -> 1957 | H17: =IF('A&Rs'!R21="","",G17*(1+VLOOKUP(H$4,'A&Rs'!$M$12:$N$21,2))) -> 1996.14 | I17: =IF('A&Rs'!R21="","",H17*(1+VLOOKUP(I$4,'A&Rs'!$M$12:$N$21,2))) -> 2056.0242 | J17: =IF('A&Rs'!R21="","",I17*(1+VLOOKUP(J$4,'A&Rs'!$M$12:$N$21,2))) -> 2117.7049 | K17: =IF('A&Rs'!R21="","",J17*(1+VLOOKUP(K$4,'A&Rs'!$M$12:$N$21,2))) -> 2117.7049 | L17: =IF('A&Rs'!R21="","",K17*(1+VLOOKUP(L$4,'A&Rs'!$M$12:$N$21,2))) -> 2138.882 | M17: =IF('A&Rs'!R21="","",L17*(1+VLOOKUP(M$4,'A&Rs'!$M$12:$N$21,2))) -> 2203.0484 | N17: =IF('A&Rs'!R21="","",M17*(1+VLOOKUP(N$4,'A&Rs'!$M$12:$N$21,2))) -> 2247.1094 | O17: =IF('A&Rs'!R21="","",N17*(1+VLOOKUP(O$4,'A&Rs'!$M$12:$N$21,2))) -> 2269.5805 | P17: =IF('A&Rs'!R21="","",O17*(1+VLOOKUP(P$4,'A&Rs'!$M$12:$N$21,2))) -> 2292.2763 | Q17: =IF('A&Rs'!R21="","",P17*(1+VLOOKUP(Q$4,'A&Rs'!$M$12:$N$21,2))) -> 2315.1991 | S17: =D35 -> 12 | T17: =IF('A&Rs'!R21="","",'A&Rs'!T21) -> 1900 | U17: =IF('A&Rs'!R21="","",T17*(1+VLOOKUP(U$4,'A&Rs'!$M$12:$N$21,2))+IF('A&Rs'!$Y21=U$4,'A&Rs'!$AA21,0)) -> 1900 | V17: =IF('A&Rs'!R21="","",U17*(1+VLOOKUP(V$4,'A&Rs'!$M$12:$N$21,2))+IF('A&Rs'!$Y21=V$4,'A&Rs'!$AA21,0)) -> 2257 | W17: =IF('A&Rs'!R21="","",V17*(1+VLOOKUP(W$4,'A&Rs'!$M$12:$N$21,2))+IF('A&Rs'!$Y21=W$4,'A&Rs'!$AA21,0)) -> 2302.14 | X17: =IF('A&Rs'!R21="","",W17*(1+VLOOKUP(X$4,'A&Rs'!$M$12:$N$21,2))+IF('A&Rs'!$Y21=X$4,'A&Rs'!$AA21,0)) -> 2371.2042 | Y17: =IF('A&Rs'!R21="","",X17*(1+VLOOKUP(Y$4,'A&Rs'!$M$12:$N$21,2))+IF('A&Rs'!$Y21=Y$4,'A&Rs'!$AA21,0)) -> 2442.3403 | Z17: =IF('A&Rs'!R21="","",Y17*(1+VLOOKUP(Z$4,'A&Rs'!$M$12:$N$21,2))+IF('A&Rs'!$Y21=Z$4,'A&Rs'!$AA21,0)) -> 2442.3403 | AA17: =IF('A&Rs'!R21="","",Z17*(1+VLOOKUP(AA$4,'A&Rs'!$M$12:$N$21,2))+IF('A&Rs'!$Y21=AA$4,'A&Rs'!$AA21,0)) -> 2466.7637 | AB17: =IF('A&Rs'!R21="","",AA17*(1+VLOOKUP(AB$4,'A&Rs'!$M$12:$N$21,2))+IF('A&Rs'!$Y21=AB$4,'A&Rs'!$AA21,0)) -> 2540.7666 | AC17: =IF('A&Rs'!R21="","",AB17*(1+VLOOKUP(AC$4,'A&Rs'!$M$12:$N$21,2))+IF('A&Rs'!$Y21=AC$4,'A&Rs'!$AA21,0)) -> 2591.582 | AD17: =IF('A&Rs'!R21="","",AC17*(1+VLOOKUP(AD$4,'A&Rs'!$M$12:$N$21,2))+IF('A&Rs'!$Y21=AD$4,'A&Rs'!$AA21,0)) -> 2617.4978 | AE17: =IF('A&Rs'!R21="","",AD17*(1+VLOOKUP(AE$4,'A&Rs'!$M$12:$N$21,2))+IF('A&Rs'!$Y21=AE$4,'A&Rs'!$AA21,0)) -> 2643.6728 | AF17: =IF('A&Rs'!R21="","",AE17*(1+VLOOKUP(AF$4,'A&Rs'!$M$12:$N$21,2))+IF('A&Rs'!$Y21=AF$4,'A&Rs'!$AA21,0)) -> 2670.1095
D20: Rental Gross Revenue | FF20: x
D21: Year | E21: 0 | F21: 1 | G21: 1 | H21: 1 | I21: 1 | J21: 1 | K21: 1 | L21: 1 | M21: 1 | N21: 1 | O21: 1 | P21: 1 | Q21: 1 | R21: =1+F21 -> 2 | S21: =1+G21 -> 2 | T21: =1+H21 -> 2 | U21: =1+I21 -> 2 | V21: =1+J21 -> 2 | W21: =1+K21 -> 2 | X21: =1+L21 -> 2 | Y21: =1+M21 -> 2 | ... FE21: =1+ES21 -> 13
D22: Month in Year | E22: 0 | F22: 1 | G22: 2 | H22: 3 | I22: 4 | J22: 5 | K22: 6 | L22: 7 | M22: 8 | N22: 9 | O22: 10 | P22: 11 | Q22: 12 | R22: 13 | S22: 14 | T22: 15 | U22: 16 | V22: 17 | W22: 18 | X22: 19 | Y22: 20 | Z22: 21 | AA22: 22 | AB22: 23 | AC22: 24 | AD22: 25 | AE22: 26 | AF22: 27 | AG22: 28 | AH22: 29 | AI22: 30 | AJ22: 31 | AK22: 32 | AL22: 33 | AM22: 34 | AN22: 35 | AO22: 36 | AP22: 37 | AQ22: 38 | AR22: 39 | AS22: 40 | AT22: 41 | AU22: 42 | AV22: 43 | AW22: 44 | AX22: 45 | AY22: 46 | AZ22: 47 | BA22: 48 | BB22: 49 | BC22: 50 | BD22: 51 | BE22: 52 | BF22: 53 | BG22: 54 | BH22: 55 | BI22: 56 | BJ22: 57 | BK22: 58 | BL22: 59 | BM22: 60 | BN22: 61 | BO22: 62 | BP22: 63 | BQ22: 64 | BR22: 65 | BS22: 66 | BT22: 67 | BU22: 68 | BV22: 69 | BW22: 70 | BX22: 71 | BY22: 72 | BZ22: 73 | CA22: 74 | CB22: 75 | CC22: 76 | CD22: 77 | CE22: 78 | CF22: 79 | CG22: 80 | CH22: 81 | CI22: 82 | CJ22: 83 | CK22: 84 | CL22: 85 | CM22: 86 | CN22: 87 | CO22: 88 | CP22: 89 | CQ22: 90 | CR22: 91 | CS22: 92 | CT22: 93 | CU22: 94 | CV22: 95 | CW22: 96 | CX22: 97 | CY22: 98 | CZ22: 99 | DA22: 100 | DB22: 101 | DC22: 102 | DD22: 103 | DE22: 104 | DF22: 105 | DG22: 106 | DH22: 107 | DI22: 108 | DJ22: 109 | DK22: 110 | DL22: 111 | DM22: 112 | DN22: 113 | DO22: 114 | DP22: 115 | DQ22: 116 | DR22: 117 | DS22: 118 | DT22: 119 | DU22: 120 | DV22: 121 | DW22: 122 | DX22: 123 | DY22: 124 | DZ22: 125 | EA22: 126 | EB22: 127 | EC22: 128 | ED22: 129 | EE22: 130 | EF22: 131 | EG22: 132 | EH22: 133 | EI22: 134 | EJ22: 135 | EK22: 136 | EL22: 137 | EM22: 138 | EN22: 139 | EO22: 140 | EP22: 141 | EQ22: 142 | ER22: 143 | ES22: 144 | ET22: 145 | EU22: 146 | EV22: 147 | EW22: 148 | EX22: 149 | EY22: 150 | EZ22: 151 | FA22: 152 | FB22: 153 | FC22: 154 | FD22: 155 | FE22: 156 | FF22: x
D23: Month in Year | E23: ='A&Rs'!K10 -> 46174 | F23: =EOMONTH(E23,0)+1 -> 46204 | G23: =EOMONTH(F23,0)+1 -> 46235 | H23: =EOMONTH(G23,0)+1 -> 46266 | I23: =EOMONTH(H23,0)+1 -> 46296 | J23: =EOMONTH(I23,0)+1 -> 46327 | K23: =EOMONTH(J23,0)+1 -> 46357 | L23: =EOMONTH(K23,0)+1 -> 46388 | M23: =EOMONTH(L23,0)+1 -> 46419 | ... FE23: =EOMONTH(FD23,0)+1 -> 50922 | FF23: x
D24: ='A&Rs'!Q10 -> 1 | E24: =E6 -> 1170 | F24: =IF(F$23<'A&Rs'!$V10,HLOOKUP(F$21,$F$4:$Q$17,$B6),IF(AND(F$23>='A&Rs'!$V10,F$23<'A&Rs'!$X10),0,HLOOKUP(F$21,$U$4:$AF$17,$B6))) -> 1170 | G24: =IF(G$23<'A&Rs'!$V10,HLOOKUP(G$21,$F$4:$Q$17,$B6),IF(AND(G$23>='A&Rs'!$V10,G$23<'A&Rs'!$X10),0,HLOOKUP(G$21,$U$4:$AF$17,$B6))) -> 0 | H24: =IF(H$23<'A&Rs'!$V10,HLOOKUP(H$21,$F$4:$Q$17,$B6),IF(AND(H$23>='A&Rs'!$V10,H$23<'A&Rs'!$X10),0,HLOOKUP(H$21,$U$4:$AF$17,$B6))) -> 0 | I24: =IF(I$23<'A&Rs'!$V10,HLOOKUP(I$21,$F$4:$Q$17,$B6),IF(AND(I$23>='A&Rs'!$V10,I$23<'A&Rs'!$X10),0,HLOOKUP(I$21,$U$4:$AF$17,$B6))) -> 1430 | J24: =IF(J$23<'A&Rs'!$V10,HLOOKUP(J$21,$F$4:$Q$17,$B6),IF(AND(J$23>='A&Rs'!$V10,J$23<'A&Rs'!$X10),0,HLOOKUP(J$21,$U$4:$AF$17,$B6))) -> 1430 | K24: =IF(K$23<'A&Rs'!$V10,HLOOKUP(K$21,$F$4:$Q$17,$B6),IF(AND(K$23>='A&Rs'!$V10,K$23<'A&Rs'!$X10),0,HLOOKUP(K$21,$U$4:$AF$17,$B6))) -> 1430 | L24: =IF(L$23<'A&Rs'!$V10,HLOOKUP(L$21,$F$4:$Q$17,$B6),IF(AND(L$23>='A&Rs'!$V10,L$23<'A&Rs'!$X10),0,HLOOKUP(L$21,$U$4:$AF$17,$B6))) -> 1430 | M24: =IF(M$23<'A&Rs'!$V10,HLOOKUP(M$21,$F$4:$Q$17,$B6),IF(AND(M$23>='A&Rs'!$V10,M$23<'A&Rs'!$X10),0,HLOOKUP(M$21,$U$4:$AF$17,$B6))) -> 1430 | ... FE24: =IF(FE$23<'A&Rs'!$V10,HLOOKUP(FE$21,$F$4:$Q$17,$B6),IF(AND(FE$23>='A&Rs'!$V10,FE$23<'A&Rs'!$X10),0,HLOOKUP(FE$21,$U$4:$AF$17,$B6))) -> 1742.4919 | FF24: x
D25: ='A&Rs'!Q11 -> 2 | E25: =E7 -> 1170 | F25: =IF(F$23<'A&Rs'!$V11,HLOOKUP(F$21,$F$4:$Q$17,$B7),IF(AND(F$23>='A&Rs'!$V11,F$23<'A&Rs'!$X11),0,HLOOKUP(F$21,$U$4:$AF$17,$B7))) -> 1170 | G25: =IF(G$23<'A&Rs'!$V11,HLOOKUP(G$21,$F$4:$Q$17,$B7),IF(AND(G$23>='A&Rs'!$V11,G$23<'A&Rs'!$X11),0,HLOOKUP(G$21,$U$4:$AF$17,$B7))) -> 0 | H25: =IF(H$23<'A&Rs'!$V11,HLOOKUP(H$21,$F$4:$Q$17,$B7),IF(AND(H$23>='A&Rs'!$V11,H$23<'A&Rs'!$X11),0,HLOOKUP(H$21,$U$4:$AF$17,$B7))) -> 0 | I25: =IF(I$23<'A&Rs'!$V11,HLOOKUP(I$21,$F$4:$Q$17,$B7),IF(AND(I$23>='A&Rs'!$V11,I$23<'A&Rs'!$X11),0,HLOOKUP(I$21,$U$4:$AF$17,$B7))) -> 1430 | J25: =IF(J$23<'A&Rs'!$V11,HLOOKUP(J$21,$F$4:$Q$17,$B7),IF(AND(J$23>='A&Rs'!$V11,J$23<'A&Rs'!$X11),0,HLOOKUP(J$21,$U$4:$AF$17,$B7))) -> 1430 | K25: =IF(K$23<'A&Rs'!$V11,HLOOKUP(K$21,$F$4:$Q$17,$B7),IF(AND(K$23>='A&Rs'!$V11,K$23<'A&Rs'!$X11),0,HLOOKUP(K$21,$U$4:$AF$17,$B7))) -> 1430 | L25: =IF(L$23<'A&Rs'!$V11,HLOOKUP(L$21,$F$4:$Q$17,$B7),IF(AND(L$23>='A&Rs'!$V11,L$23<'A&Rs'!$X11),0,HLOOKUP(L$21,$U$4:$AF$17,$B7))) -> 1430 | M25: =IF(M$23<'A&Rs'!$V11,HLOOKUP(M$21,$F$4:$Q$17,$B7),IF(AND(M$23>='A&Rs'!$V11,M$23<'A&Rs'!$X11),0,HLOOKUP(M$21,$U$4:$AF$17,$B7))) -> 1430 | ... FE25: =IF(FE$23<'A&Rs'!$V11,HLOOKUP(FE$21,$F$4:$Q$17,$B7),IF(AND(FE$23>='A&Rs'!$V11,FE$23<'A&Rs'!$X11),0,HLOOKUP(FE$21,$U$4:$AF$17,$B7))) -> 1742.4919 | FF25: x
D26: ='A&Rs'!Q12 -> 3 | E26: =E8 -> 1200 | F26: =IF(F$23<'A&Rs'!$V12,HLOOKUP(F$21,$F$4:$Q$17,$B8),IF(AND(F$23>='A&Rs'!$V12,F$23<'A&Rs'!$X12),0,HLOOKUP(F$21,$U$4:$AF$17,$B8))) -> 1200 | G26: =IF(G$23<'A&Rs'!$V12,HLOOKUP(G$21,$F$4:$Q$17,$B8),IF(AND(G$23>='A&Rs'!$V12,G$23<'A&Rs'!$X12),0,HLOOKUP(G$21,$U$4:$AF$17,$B8))) -> 0 | H26: =IF(H$23<'A&Rs'!$V12,HLOOKUP(H$21,$F$4:$Q$17,$B8),IF(AND(H$23>='A&Rs'!$V12,H$23<'A&Rs'!$X12),0,HLOOKUP(H$21,$U$4:$AF$17,$B8))) -> 0 | I26: =IF(I$23<'A&Rs'!$V12,HLOOKUP(I$21,$F$4:$Q$17,$B8),IF(AND(I$23>='A&Rs'!$V12,I$23<'A&Rs'!$X12),0,HLOOKUP(I$21,$U$4:$AF$17,$B8))) -> 1460 | J26: =IF(J$23<'A&Rs'!$V12,HLOOKUP(J$21,$F$4:$Q$17,$B8),IF(AND(J$23>='A&Rs'!$V12,J$23<'A&Rs'!$X12),0,HLOOKUP(J$21,$U$4:$AF$17,$B8))) -> 1460 | K26: =IF(K$23<'A&Rs'!$V12,HLOOKUP(K$21,$F$4:$Q$17,$B8),IF(AND(K$23>='A&Rs'!$V12,K$23<'A&Rs'!$X12),0,HLOOKUP(K$21,$U$4:$AF$17,$B8))) -> 1460 | L26: =IF(L$23<'A&Rs'!$V12,HLOOKUP(L$21,$F$4:$Q$17,$B8),IF(AND(L$23>='A&Rs'!$V12,L$23<'A&Rs'!$X12),0,HLOOKUP(L$21,$U$4:$AF$17,$B8))) -> 1460 | M26: =IF(M$23<'A&Rs'!$V12,HLOOKUP(M$21,$F$4:$Q$17,$B8),IF(AND(M$23>='A&Rs'!$V12,M$23<'A&Rs'!$X12),0,HLOOKUP(M$21,$U$4:$AF$17,$B8))) -> 1460 | ... FE26: =IF(FE$23<'A&Rs'!$V12,HLOOKUP(FE$21,$F$4:$Q$17,$B8),IF(AND(FE$23>='A&Rs'!$V12,FE$23<'A&Rs'!$X12),0,HLOOKUP(FE$21,$U$4:$AF$17,$B8))) -> 1779.0477 | FF26: x
D27: ='A&Rs'!Q13 -> 4 | E27: =E9 -> 1240 | F27: =IF(F$23<'A&Rs'!$V13,HLOOKUP(F$21,$F$4:$Q$17,$B9),IF(AND(F$23>='A&Rs'!$V13,F$23<'A&Rs'!$X13),0,HLOOKUP(F$21,$U$4:$AF$17,$B9))) -> 1240 | G27: =IF(G$23<'A&Rs'!$V13,HLOOKUP(G$21,$F$4:$Q$17,$B9),IF(AND(G$23>='A&Rs'!$V13,G$23<'A&Rs'!$X13),0,HLOOKUP(G$21,$U$4:$AF$17,$B9))) -> 1240 | H27: =IF(H$23<'A&Rs'!$V13,HLOOKUP(H$21,$F$4:$Q$17,$B9),IF(AND(H$23>='A&Rs'!$V13,H$23<'A&Rs'!$X13),0,HLOOKUP(H$21,$U$4:$AF$17,$B9))) -> 1240 | I27: =IF(I$23<'A&Rs'!$V13,HLOOKUP(I$21,$F$4:$Q$17,$B9),IF(AND(I$23>='A&Rs'!$V13,I$23<'A&Rs'!$X13),0,HLOOKUP(I$21,$U$4:$AF$17,$B9))) -> 0 | J27: =IF(J$23<'A&Rs'!$V13,HLOOKUP(J$21,$F$4:$Q$17,$B9),IF(AND(J$23>='A&Rs'!$V13,J$23<'A&Rs'!$X13),0,HLOOKUP(J$21,$U$4:$AF$17,$B9))) -> 0 | K27: =IF(K$23<'A&Rs'!$V13,HLOOKUP(K$21,$F$4:$Q$17,$B9),IF(AND(K$23>='A&Rs'!$V13,K$23<'A&Rs'!$X13),0,HLOOKUP(K$21,$U$4:$AF$17,$B9))) -> 0 | L27: =IF(L$23<'A&Rs'!$V13,HLOOKUP(L$21,$F$4:$Q$17,$B9),IF(AND(L$23>='A&Rs'!$V13,L$23<'A&Rs'!$X13),0,HLOOKUP(L$21,$U$4:$AF$17,$B9))) -> 1500 | M27: =IF(M$23<'A&Rs'!$V13,HLOOKUP(M$21,$F$4:$Q$17,$B9),IF(AND(M$23>='A&Rs'!$V13,M$23<'A&Rs'!$X13),0,HLOOKUP(M$21,$U$4:$AF$17,$B9))) -> 1500 | ... FE27: =IF(FE$23<'A&Rs'!$V13,HLOOKUP(FE$21,$F$4:$Q$17,$B9),IF(AND(FE$23>='A&Rs'!$V13,FE$23<'A&Rs'!$X13),0,HLOOKUP(FE$21,$U$4:$AF$17,$B9))) -> 1827.7887 | FF27: x
D28: ='A&Rs'!Q14 -> 5 | E28: =E10 -> 1312 | F28: =IF(F$23<'A&Rs'!$V14,HLOOKUP(F$21,$F$4:$Q$17,$B10),IF(AND(F$23>='A&Rs'!$V14,F$23<'A&Rs'!$X14),0,HLOOKUP(F$21,$U$4:$AF$17,$B10))) -> 1312 | G28: =IF(G$23<'A&Rs'!$V14,HLOOKUP(G$21,$F$4:$Q$17,$B10),IF(AND(G$23>='A&Rs'!$V14,G$23<'A&Rs'!$X14),0,HLOOKUP(G$21,$U$4:$AF$17,$B10))) -> 1312 | H28: =IF(H$23<'A&Rs'!$V14,HLOOKUP(H$21,$F$4:$Q$17,$B10),IF(AND(H$23>='A&Rs'!$V14,H$23<'A&Rs'!$X14),0,HLOOKUP(H$21,$U$4:$AF$17,$B10))) -> 1312 | I28: =IF(I$23<'A&Rs'!$V14,HLOOKUP(I$21,$F$4:$Q$17,$B10),IF(AND(I$23>='A&Rs'!$V14,I$23<'A&Rs'!$X14),0,HLOOKUP(I$21,$U$4:$AF$17,$B10))) -> 0 | J28: =IF(J$23<'A&Rs'!$V14,HLOOKUP(J$21,$F$4:$Q$17,$B10),IF(AND(J$23>='A&Rs'!$V14,J$23<'A&Rs'!$X14),0,HLOOKUP(J$21,$U$4:$AF$17,$B10))) -> 0 | K28: =IF(K$23<'A&Rs'!$V14,HLOOKUP(K$21,$F$4:$Q$17,$B10),IF(AND(K$23>='A&Rs'!$V14,K$23<'A&Rs'!$X14),0,HLOOKUP(K$21,$U$4:$AF$17,$B10))) -> 0 | L28: =IF(L$23<'A&Rs'!$V14,HLOOKUP(L$21,$F$4:$Q$17,$B10),IF(AND(L$23>='A&Rs'!$V14,L$23<'A&Rs'!$X14),0,HLOOKUP(L$21,$U$4:$AF$17,$B10))) -> 1592 | M28: =IF(M$23<'A&Rs'!$V14,HLOOKUP(M$21,$F$4:$Q$17,$B10),IF(AND(M$23>='A&Rs'!$V14,M$23<'A&Rs'!$X14),0,HLOOKUP(M$21,$U$4:$AF$17,$B10))) -> 1592 | ... FE28: =IF(FE$23<'A&Rs'!$V14,HLOOKUP(FE$21,$F$4:$Q$17,$B10),IF(AND(FE$23>='A&Rs'!$V14,FE$23<'A&Rs'!$X14),0,HLOOKUP(FE$21,$U$4:$AF$17,$B10))) -> 1939.8931 | FF28: x
D29: ='A&Rs'!Q15 -> 6 | E29: =E11 -> 1346 | F29: =IF(F$23<'A&Rs'!$V15,HLOOKUP(F$21,$F$4:$Q$17,$B11),IF(AND(F$23>='A&Rs'!$V15,F$23<'A&Rs'!$X15),0,HLOOKUP(F$21,$U$4:$AF$17,$B11))) -> 1346 | G29: =IF(G$23<'A&Rs'!$V15,HLOOKUP(G$21,$F$4:$Q$17,$B11),IF(AND(G$23>='A&Rs'!$V15,G$23<'A&Rs'!$X15),0,HLOOKUP(G$21,$U$4:$AF$17,$B11))) -> 1346 | H29: =IF(H$23<'A&Rs'!$V15,HLOOKUP(H$21,$F$4:$Q$17,$B11),IF(AND(H$23>='A&Rs'!$V15,H$23<'A&Rs'!$X15),0,HLOOKUP(H$21,$U$4:$AF$17,$B11))) -> 1346 | I29: =IF(I$23<'A&Rs'!$V15,HLOOKUP(I$21,$F$4:$Q$17,$B11),IF(AND(I$23>='A&Rs'!$V15,I$23<'A&Rs'!$X15),0,HLOOKUP(I$21,$U$4:$AF$17,$B11))) -> 1346 | J29: =IF(J$23<'A&Rs'!$V15,HLOOKUP(J$21,$F$4:$Q$17,$B11),IF(AND(J$23>='A&Rs'!$V15,J$23<'A&Rs'!$X15),0,HLOOKUP(J$21,$U$4:$AF$17,$B11))) -> 1346 | K29: =IF(K$23<'A&Rs'!$V15,HLOOKUP(K$21,$F$4:$Q$17,$B11),IF(AND(K$23>='A&Rs'!$V15,K$23<'A&Rs'!$X15),0,HLOOKUP(K$21,$U$4:$AF$17,$B11))) -> 0 | L29: =IF(L$23<'A&Rs'!$V15,HLOOKUP(L$21,$F$4:$Q$17,$B11),IF(AND(L$23>='A&Rs'!$V15,L$23<'A&Rs'!$X15),0,HLOOKUP(L$21,$U$4:$AF$17,$B11))) -> 0 | M29: =IF(M$23<'A&Rs'!$V15,HLOOKUP(M$21,$F$4:$Q$17,$B11),IF(AND(M$23>='A&Rs'!$V15,M$23<'A&Rs'!$X15),0,HLOOKUP(M$21,$U$4:$AF$17,$B11))) -> 0 | ... FE29: =IF(FE$23<'A&Rs'!$V15,HLOOKUP(FE$21,$F$4:$Q$17,$B11),IF(AND(FE$23>='A&Rs'!$V15,FE$23<'A&Rs'!$X15),0,HLOOKUP(FE$21,$U$4:$AF$17,$B11))) -> 1981.323 | FF29: x
D30: ='A&Rs'!Q16 -> 7 | E30: =E12 -> 1413 | F30: =IF(F$23<'A&Rs'!$V16,HLOOKUP(F$21,$F$4:$Q$17,$B12),IF(AND(F$23>='A&Rs'!$V16,F$23<'A&Rs'!$X16),0,HLOOKUP(F$21,$U$4:$AF$17,$B12))) -> 1413 | G30: =IF(G$23<'A&Rs'!$V16,HLOOKUP(G$21,$F$4:$Q$17,$B12),IF(AND(G$23>='A&Rs'!$V16,G$23<'A&Rs'!$X16),0,HLOOKUP(G$21,$U$4:$AF$17,$B12))) -> 1413 | H30: =IF(H$23<'A&Rs'!$V16,HLOOKUP(H$21,$F$4:$Q$17,$B12),IF(AND(H$23>='A&Rs'!$V16,H$23<'A&Rs'!$X16),0,HLOOKUP(H$21,$U$4:$AF$17,$B12))) -> 1413 | I30: =IF(I$23<'A&Rs'!$V16,HLOOKUP(I$21,$F$4:$Q$17,$B12),IF(AND(I$23>='A&Rs'!$V16,I$23<'A&Rs'!$X16),0,HLOOKUP(I$21,$U$4:$AF$17,$B12))) -> 1413 | J30: =IF(J$23<'A&Rs'!$V16,HLOOKUP(J$21,$F$4:$Q$17,$B12),IF(AND(J$23>='A&Rs'!$V16,J$23<'A&Rs'!$X16),0,HLOOKUP(J$21,$U$4:$AF$17,$B12))) -> 1413 | K30: =IF(K$23<'A&Rs'!$V16,HLOOKUP(K$21,$F$4:$Q$17,$B12),IF(AND(K$23>='A&Rs'!$V16,K$23<'A&Rs'!$X16),0,HLOOKUP(K$21,$U$4:$AF$17,$B12))) -> 1413 | L30: =IF(L$23<'A&Rs'!$V16,HLOOKUP(L$21,$F$4:$Q$17,$B12),IF(AND(L$23>='A&Rs'!$V16,L$23<'A&Rs'!$X16),0,HLOOKUP(L$21,$U$4:$AF$17,$B12))) -> 1413 | M30: =IF(M$23<'A&Rs'!$V16,HLOOKUP(M$21,$F$4:$Q$17,$B12),IF(AND(M$23>='A&Rs'!$V16,M$23<'A&Rs'!$X16),0,HLOOKUP(M$21,$U$4:$AF$17,$B12))) -> 0 | ... FE30: =IF(FE$23<'A&Rs'!$V16,HLOOKUP(FE$21,$F$4:$Q$17,$B12),IF(AND(FE$23>='A&Rs'!$V16,FE$23<'A&Rs'!$X16),0,HLOOKUP(FE$21,$U$4:$AF$17,$B12))) -> 2062.9642 | FF30: x
D31: ='A&Rs'!Q17 -> 8 | E31: =E13 -> 1480 | F31: =IF(F$23<'A&Rs'!$V17,HLOOKUP(F$21,$F$4:$Q$17,$B13),IF(AND(F$23>='A&Rs'!$V17,F$23<'A&Rs'!$X17),0,HLOOKUP(F$21,$U$4:$AF$17,$B13))) -> 1480 | G31: =IF(G$23<'A&Rs'!$V17,HLOOKUP(G$21,$F$4:$Q$17,$B13),IF(AND(G$23>='A&Rs'!$V17,G$23<'A&Rs'!$X17),0,HLOOKUP(G$21,$U$4:$AF$17,$B13))) -> 1480 | H31: =IF(H$23<'A&Rs'!$V17,HLOOKUP(H$21,$F$4:$Q$17,$B13),IF(AND(H$23>='A&Rs'!$V17,H$23<'A&Rs'!$X17),0,HLOOKUP(H$21,$U$4:$AF$17,$B13))) -> 1480 | I31: =IF(I$23<'A&Rs'!$V17,HLOOKUP(I$21,$F$4:$Q$17,$B13),IF(AND(I$23>='A&Rs'!$V17,I$23<'A&Rs'!$X17),0,HLOOKUP(I$21,$U$4:$AF$17,$B13))) -> 1480 | J31: =IF(J$23<'A&Rs'!$V17,HLOOKUP(J$21,$F$4:$Q$17,$B13),IF(AND(J$23>='A&Rs'!$V17,J$23<'A&Rs'!$X17),0,HLOOKUP(J$21,$U$4:$AF$17,$B13))) -> 1480 | K31: =IF(K$23<'A&Rs'!$V17,HLOOKUP(K$21,$F$4:$Q$17,$B13),IF(AND(K$23>='A&Rs'!$V17,K$23<'A&Rs'!$X17),0,HLOOKUP(K$21,$U$4:$AF$17,$B13))) -> 1480 | L31: =IF(L$23<'A&Rs'!$V17,HLOOKUP(L$21,$F$4:$Q$17,$B13),IF(AND(L$23>='A&Rs'!$V17,L$23<'A&Rs'!$X17),0,HLOOKUP(L$21,$U$4:$AF$17,$B13))) -> 1480 | M31: =IF(M$23<'A&Rs'!$V17,HLOOKUP(M$21,$F$4:$Q$17,$B13),IF(AND(M$23>='A&Rs'!$V17,M$23<'A&Rs'!$X17),0,HLOOKUP(M$21,$U$4:$AF$17,$B13))) -> 0 | ... FE31: =IF(FE$23<'A&Rs'!$V17,HLOOKUP(FE$21,$F$4:$Q$17,$B13),IF(AND(FE$23>='A&Rs'!$V17,FE$23<'A&Rs'!$X17),0,HLOOKUP(FE$21,$U$4:$AF$17,$B13))) -> 2120.2349 | FF31: x
D32: ='A&Rs'!Q18 -> 11 | E32: =E14 -> 1548 | F32: =IF(F$23<'A&Rs'!$V18,HLOOKUP(F$21,$F$4:$Q$17,$B14),IF(AND(F$23>='A&Rs'!$V18,F$23<'A&Rs'!$X18),0,HLOOKUP(F$21,$U$4:$AF$17,$B14))) -> 1548 | G32: =IF(G$23<'A&Rs'!$V18,HLOOKUP(G$21,$F$4:$Q$17,$B14),IF(AND(G$23>='A&Rs'!$V18,G$23<'A&Rs'!$X18),0,HLOOKUP(G$21,$U$4:$AF$17,$B14))) -> 1548 | H32: =IF(H$23<'A&Rs'!$V18,HLOOKUP(H$21,$F$4:$Q$17,$B14),IF(AND(H$23>='A&Rs'!$V18,H$23<'A&Rs'!$X18),0,HLOOKUP(H$21,$U$4:$AF$17,$B14))) -> 1548 | I32: =IF(I$23<'A&Rs'!$V18,HLOOKUP(I$21,$F$4:$Q$17,$B14),IF(AND(I$23>='A&Rs'!$V18,I$23<'A&Rs'!$X18),0,HLOOKUP(I$21,$U$4:$AF$17,$B14))) -> 1548 | J32: =IF(J$23<'A&Rs'!$V18,HLOOKUP(J$21,$F$4:$Q$17,$B14),IF(AND(J$23>='A&Rs'!$V18,J$23<'A&Rs'!$X18),0,HLOOKUP(J$21,$U$4:$AF$17,$B14))) -> 1548 | K32: =IF(K$23<'A&Rs'!$V18,HLOOKUP(K$21,$F$4:$Q$17,$B14),IF(AND(K$23>='A&Rs'!$V18,K$23<'A&Rs'!$X18),0,HLOOKUP(K$21,$U$4:$AF$17,$B14))) -> 1548 | L32: =IF(L$23<'A&Rs'!$V18,HLOOKUP(L$21,$F$4:$Q$17,$B14),IF(AND(L$23>='A&Rs'!$V18,L$23<'A&Rs'!$X18),0,HLOOKUP(L$21,$U$4:$AF$17,$B14))) -> 1548 | M32: =IF(M$23<'A&Rs'!$V18,HLOOKUP(M$21,$F$4:$Q$17,$B14),IF(AND(M$23>='A&Rs'!$V18,M$23<'A&Rs'!$X18),0,HLOOKUP(M$21,$U$4:$AF$17,$B14))) -> 1548 | ... FE32: =IF(FE$23<'A&Rs'!$V18,HLOOKUP(FE$21,$F$4:$Q$17,$B14),IF(AND(FE$23>='A&Rs'!$V18,FE$23<'A&Rs'!$X18),0,HLOOKUP(FE$21,$U$4:$AF$17,$B14))) -> 2241.1884 | FF32: x
D33: ='A&Rs'!Q19 -> 10 | E33: =E15 -> 1750 | F33: =IF(F$23<'A&Rs'!$V19,HLOOKUP(F$21,$F$4:$Q$17,$B15),IF(AND(F$23>='A&Rs'!$V19,F$23<'A&Rs'!$X19),0,HLOOKUP(F$21,$U$4:$AF$17,$B15))) -> 1750 | G33: =IF(G$23<'A&Rs'!$V19,HLOOKUP(G$21,$F$4:$Q$17,$B15),IF(AND(G$23>='A&Rs'!$V19,G$23<'A&Rs'!$X19),0,HLOOKUP(G$21,$U$4:$AF$17,$B15))) -> 1750 | H33: =IF(H$23<'A&Rs'!$V19,HLOOKUP(H$21,$F$4:$Q$17,$B15),IF(AND(H$23>='A&Rs'!$V19,H$23<'A&Rs'!$X19),0,HLOOKUP(H$21,$U$4:$AF$17,$B15))) -> 1750 | I33: =IF(I$23<'A&Rs'!$V19,HLOOKUP(I$21,$F$4:$Q$17,$B15),IF(AND(I$23>='A&Rs'!$V19,I$23<'A&Rs'!$X19),0,HLOOKUP(I$21,$U$4:$AF$17,$B15))) -> 1750 | J33: =IF(J$23<'A&Rs'!$V19,HLOOKUP(J$21,$F$4:$Q$17,$B15),IF(AND(J$23>='A&Rs'!$V19,J$23<'A&Rs'!$X19),0,HLOOKUP(J$21,$U$4:$AF$17,$B15))) -> 1750 | K33: =IF(K$23<'A&Rs'!$V19,HLOOKUP(K$21,$F$4:$Q$17,$B15),IF(AND(K$23>='A&Rs'!$V19,K$23<'A&Rs'!$X19),0,HLOOKUP(K$21,$U$4:$AF$17,$B15))) -> 1750 | L33: =IF(L$23<'A&Rs'!$V19,HLOOKUP(L$21,$F$4:$Q$17,$B15),IF(AND(L$23>='A&Rs'!$V19,L$23<'A&Rs'!$X19),0,HLOOKUP(L$21,$U$4:$AF$17,$B15))) -> 1750 | M33: =IF(M$23<'A&Rs'!$V19,HLOOKUP(M$21,$F$4:$Q$17,$B15),IF(AND(M$23>='A&Rs'!$V19,M$23<'A&Rs'!$X19),0,HLOOKUP(M$21,$U$4:$AF$17,$B15))) -> 1750 | ... FE33: =IF(FE$23<'A&Rs'!$V19,HLOOKUP(FE$21,$F$4:$Q$17,$B15),IF(AND(FE$23>='A&Rs'!$V19,FE$23<'A&Rs'!$X19),0,HLOOKUP(FE$21,$U$4:$AF$17,$B15))) -> 2487.3306 | FF33: x
D34: ='A&Rs'!Q20 -> 9 | E34: =E16 -> 1884 | F34: =IF(F$23<'A&Rs'!$V20,HLOOKUP(F$21,$F$4:$Q$17,$B16),IF(AND(F$23>='A&Rs'!$V20,F$23<'A&Rs'!$X20),0,HLOOKUP(F$21,$U$4:$AF$17,$B16))) -> 1884 | G34: =IF(G$23<'A&Rs'!$V20,HLOOKUP(G$21,$F$4:$Q$17,$B16),IF(AND(G$23>='A&Rs'!$V20,G$23<'A&Rs'!$X20),0,HLOOKUP(G$21,$U$4:$AF$17,$B16))) -> 1884 | H34: =IF(H$23<'A&Rs'!$V20,HLOOKUP(H$21,$F$4:$Q$17,$B16),IF(AND(H$23>='A&Rs'!$V20,H$23<'A&Rs'!$X20),0,HLOOKUP(H$21,$U$4:$AF$17,$B16))) -> 1884 | I34: =IF(I$23<'A&Rs'!$V20,HLOOKUP(I$21,$F$4:$Q$17,$B16),IF(AND(I$23>='A&Rs'!$V20,I$23<'A&Rs'!$X20),0,HLOOKUP(I$21,$U$4:$AF$17,$B16))) -> 1884 | J34: =IF(J$23<'A&Rs'!$V20,HLOOKUP(J$21,$F$4:$Q$17,$B16),IF(AND(J$23>='A&Rs'!$V20,J$23<'A&Rs'!$X20),0,HLOOKUP(J$21,$U$4:$AF$17,$B16))) -> 1884 | K34: =IF(K$23<'A&Rs'!$V20,HLOOKUP(K$21,$F$4:$Q$17,$B16),IF(AND(K$23>='A&Rs'!$V20,K$23<'A&Rs'!$X20),0,HLOOKUP(K$21,$U$4:$AF$17,$B16))) -> 1884 | L34: =IF(L$23<'A&Rs'!$V20,HLOOKUP(L$21,$F$4:$Q$17,$B16),IF(AND(L$23>='A&Rs'!$V20,L$23<'A&Rs'!$X20),0,HLOOKUP(L$21,$U$4:$AF$17,$B16))) -> 1884 | M34: =IF(M$23<'A&Rs'!$V20,HLOOKUP(M$21,$F$4:$Q$17,$B16),IF(AND(M$23>='A&Rs'!$V20,M$23<'A&Rs'!$X20),0,HLOOKUP(M$21,$U$4:$AF$17,$B16))) -> 1884 | ... FE34: =IF(FE$23<'A&Rs'!$V20,HLOOKUP(FE$21,$F$4:$Q$17,$B16),IF(AND(FE$23>='A&Rs'!$V20,FE$23<'A&Rs'!$X20),0,HLOOKUP(FE$21,$U$4:$AF$17,$B16))) -> 2650.6131 | FF34: x
