Workbook
Name _2_Way_FIBER_RF_Upgrade_Cost_Per_Mile: Assumptions!$B$102
Name _2_Way_Miles_per_Subscriber: Assumptions!$B$103
Name Acquired_Subscribers: Assumptions!$G$6:$L$6
Name Acquisition_Cost_per_subscriber: Assumptions!$G$7:$L$7
Name Advertising_Revenue_per_Sub: Assumptions!$B$107
Name Annual_Reduction_Starting_Year_2: Assumptions!$B$52
Name AR_DOH: Assumptions!$E$10
Name ARPU_Cable: Assumptions!$B$7
Name ARPU_Data: Assumptions!$B$14
Name ARPU_Voice: Assumptions!$B$22
Name ARPU_Voice_Data: Assumptions!$B$23
Name Assets_Acquired_per_Acquisition: Assumptions!$H$13
Name Attrition_Data: Assumptions!$B$15
Name Attrition_Voice: Assumptions!$B$24
Name Cable_Attrition: Assumptions!$B$8
Name Cable_Customer_Acquisition_Cost: Assumptions!$B$9
Name Carrier_Interconnections: Assumptions!$B$57
Name CMTS_Cost_Per_Subscriber: Assumptions!$B$63
Name CMTS_Initial_Capacity_Subs: Assumptions!$B$64
Name CMTS_Initial_Cost: Assumptions!$B$62
Name CMTS_Max_Capacity_Subs: Assumptions!$B$65
Name Commissions_Sales_and_Collections: OPEX!$B$81
Name cost_International_Calls: Assumptions!$B$41
Name Cost_Local_Termination_Off_Net: Assumptions!$B$40
Name Cost_per_Data_Trunk: Assumptions!$B$58
Name Cost_per_Household_Cabling: Assumptions!$B$93
Name Cost_per_Subscriber_Cable: Assumptions!$B$51
Name Cost_per_Voice_Trunk: Assumptions!$B$59
Name Cost_Roaming_Other_Net: Assumptions!$B$42
Name Cost_to_individual_Home: Assumptions!$B$94
Name CPE_Cable_Modem: Assumptions!$B$78
Name CPE_Router: Assumptions!$B$80
Name CPE_Voice_Adaptor: Assumptions!$B$79
Name Data_Customer_Acquisition_cost: Assumptions!$B$16
Name Data_Subscribers_Trunk: Assumptions!$B$55
Name Depreciation_Life_Months: Assumptions!$B$105
Name Edge_Router_Cost: Assumptions!$B$73
Name Edge_Router_Subs: Assumptions!$B$72
Name Ethernet_Radios: Assumptions!$B$86
Name Existing_Subscribers: Assumptions!#REF!
Name Fiber_Cost_per_Mile: Assumptions!$B$71
Name Fiber_Start: Assumptions!$B$99
Name Increase_per_Year: Assumptions!$B$47
Name Installation_Fee_Cable: Assumptions!$B$10
Name Local_Termination_On_Net: Assumptions!$B$43
Name Long_fiber_Cost: Assumptions!$B$97
Name Miles_Long_Fiber: Assumptions!$B$98
Name Minutes_International_Minutes: Assumptions!$B$31
Name Minutes_Roaming: Assumptions!$B$30
Name Minutes_Terminating_Off_Net: Assumptions!$B$32
Name Organic_Sub_Adds: Assumptions!$G$10:$L$10
Name Penetration_per_Households: Assumptions!$B$92
Name Rev_Minute_Roaming: Assumptions!$B$36
Name Rev_Minutes_International_Calls: Assumptions!$B$37
Name Soft_Switch_Cost_Per_Subscriber: Assumptions!$B$67
Name Soft_Switch_Initial_Payment: Assumptions!$B$66
Name Soft_Switch_Maintenance_per_Year: Assumptions!$B$68
Name Subs_Terminating_On_Net: Assumptions!$B$33
Name Termination_Minutes_Subscriber: Assumptions!$B$46
Name Termination_Revenue_Minute: Assumptions!$B$48

Sheet Sources & Uses
B4: Sources and Uses
B5: Sources | C5: US$ | E5: Uses | F5: US$
B6: Line of Credit | C6: 0 | E6: Purchase of XXX | F6: ='Financial Statements & Detail'!C238 -> 5500000
B7: Term Loan | C7: 0 | E7: Startup Equipment | F7: ='Financial Statements & Detail'!C243-'Financial Statements & Detail'!C236 -> 3310158
B8: Mezzanine Debt | C8: 0 | E8: Telecom License | F8: =Assumptions!B88 -> 2000000
B9: Shares for Company Acquired | C9: ='Financial Statements & Detail'!C241 -> 2750000 | E9: Working Capital | F9: 4000000
B10: New Equity | C10: =F11-SUM(C6:C9) -> 12560158 | E10: Closing Costs | F10: 500000
B11: Total | C11: =SUM(C6:C10) -> 15310158 | E11: Total | F11: =SUM(F6:F10) -> 15310158
B13: Values in Blue are from assumptions elsewhere in model; changes on this page to blue values have no affect on model
B14: Values in Black are Hacker's assumptions and flow through the model
B17: Debt financing for subsequent years is on "Financial Statements" tab Row 246
B18: Debt drawdowns row 248 needs to be manually adjusted to change cash position
B20: Assumptions throughout the model are in blue and are included in the Assumptions and OPEX tabs;
B21: a few assumptions are on the Financial Statements tab
B23: Summary Financials and Return Calculations are on the Assumptions Tab
B25: Model is not formatted for printing

Sheet Assumptions
A2: Assumptions, Summary Financials, Return Calculations
A3: US$
G5: Year | H5: 1 | I5: 2 | J5: 3 | K5: 4 | L5: 5
A6: Cable Service | G6: Acquired Subscribers | H6: 11000 | I6: 25000 | J6: 25000 | K6: =J6 -> 25000 | L6: =K6 -> 25000
A7: ARPU | B7: 14.5 | G7: Cost per Subscriber Acquired | H7: 500 | I7: =H7 -> 500 | J7: =I7 -> 500 | K7: =J7 -> 500 | L7: =K7 -> 500
A8: % Attrition | B8: 0.03
A9: Customer Acquisition Cost | B9: 5 | G9: Organic Growth % | H9: 0.3 | I9: 0.3 | J9: 0.2 | K9: =J9 -> 0.2 | L9: =K9 -> 0.2
A10: Installation Fee | B10: 0 | D10: AR DOH | E10: 45 | G10: Organic Sub Adds | H10: =H9*SUM(G$6:$H6) -> 3300 | I10: =I9*SUM($H$6:H6) -> 3300 | J10: =J9*SUM($H$6:I6) -> 7200 | K10: =K9*SUM($H$6:J6) -> 12200 | L10: =L9*SUM($H$6:K6) -> 17200
D11: AP DOH | E11: 30 | G11: New Households Passed | H11: =H10/$B$92 -> 9428.5714 | I11: =I10/$B$92 -> 9428.5714 | J11: =J10/$B$92 -> 20571.429 | K11: =K10/$B$92 -> 34857.143 | L11: =L10/$B$92 -> 49142.857
A12: Data Service
A13: % with Data | B13: 0.35 | G13: Net Asset Value Acquired per Acquisition | H13: 1500000
A14: ARPU | B14: 40 | G14: Purchase Price Paid in New Stock | H14: 0.5
A15: % Attrition | B15: 0.01
A16: Customer Acquisition cost | B16: 5
G18: Financial Summary
A19: Voice Service | H19: 2008 | I19: 2009 | J19: 2010 | K19: 2011 | L19: 2012
A20: % with Voice & Data | B20: 0.2 | H20: 12 Mos. | I20: 12 Mos. | J20: 12 Mos. | K20: 12 Mos. | L20: 12 Mos.
A21: % with Voice | B21: 0.25 | G21: US$ | H21: Forecast | I21: Forecast | J21: Forecast | K21: Forecast | L21: Forecast
A22: ARPU Voice | B22: 20 | G22: Net Sales Revenue | H22: =SUM('Financial Statements & Detail'!C7:N7) -> 6646054.4 | I22: =SUM('Financial Statements & Detail'!O7:Z7) -> 15112344 | J22: =SUM('Financial Statements & Detail'!AA7:AL7) -> 24606907 | K22: =SUM('Financial Statements & Detail'!AM7:AX7) -> 33275575 | L22: =SUM('Financial Statements & Detail'!AY7:BJ7) -> 41637140
A23: ARPU Voice/Data | B23: =ARPU_Data+ARPU_Voice-10 -> 50 | G23: Gross Profit | H23: =SUM('Financial Statements & Detail'!C9:N9) -> 1455661.7 | I23: =SUM('Financial Statements & Detail'!O9:Z9) -> 3714097.3 | J23: =SUM('Financial Statements & Detail'!AA9:AL9) -> 7988762.2 | K23: =SUM('Financial Statements & Detail'!AM9:AX9) -> 12167563 | L23: =SUM('Financial Statements & Detail'!AY9:BJ9) -> 16200254
A24: Attrition | B24: 0.025 | G24: Operating Expenses | H24: =SUM('Financial Statements & Detail'!C29:N29) -> 1751202.9 | I24: =SUM('Financial Statements & Detail'!O29:Z29) -> 2190930.3 | J24: =SUM('Financial Statements & Detail'!AA29:AL29) -> 2671888.7 | K24: =SUM('Financial Statements & Detail'!AM29:AX29) -> 3264436.4 | L24: =SUM('Financial Statements & Detail'!AY29:BJ29) -> 4201056.7
A25: Customer Acquisition cost | B25: 10 | G25: Operating Income | H25: =SUM('Financial Statements & Detail'!C31:N31) -> -295541.16 | I25: =SUM('Financial Statements & Detail'!O31:Z31) -> 1523167 | J25: =SUM('Financial Statements & Detail'!AA31:AL31) -> 5316873.5 | K25: =SUM('Financial Statements & Detail'!AM31:AX31) -> 8903126.9 | L25: =SUM('Financial Statements & Detail'!AY31:BJ31) -> 11999197
A26: Existing Subscribers | B26: 0 | G26: Interest Expense | H26: =SUM('Financial Statements & Detail'!C34:N34) -> 0 | I26: =SUM('Financial Statements & Detail'!O34:Z34) -> 1411666.7 | J26: =SUM('Financial Statements & Detail'!AA34:AL34) -> 2371875 | K26: =SUM('Financial Statements & Detail'!AM34:AX34) -> 2497105 | L26: =SUM('Financial Statements & Detail'!AY34:BJ34) -> 2476045.4
G27: Pre-Tax Income | H27: =SUM('Financial Statements & Detail'!C37:N37) -> -295541.16 | I27: =SUM('Financial Statements & Detail'!O37:Z37) -> 111500.36 | J27: =SUM('Financial Statements & Detail'!AA37:AL37) -> 2944998.5 | K27: =SUM('Financial Statements & Detail'!AM37:AX37) -> 6406021.9 | L27: =SUM('Financial Statements & Detail'!AY37:BJ37) -> 9523151.7
A28: Voice Minutes Subscriber/Month | G28: EBITDA | H28: =SUM('Financial Statements & Detail'!C41:N41) -> 766227.76 | I28: =SUM('Financial Statements & Detail'!O41:Z41) -> 4802456.6 | J28: =SUM('Financial Statements & Detail'!AA41:AL41) -> 10303491 | K28: =SUM('Financial Statements & Detail'!AM41:AX41) -> 15776083 | L28: =SUM('Financial Statements & Detail'!AY41:BJ41) -> 20995276
A29: Total Call Minutes per Month | B29: 400
A30: Subs_Roaming Other Networks Minutes | B30: 1e-06 | G30: % Growth Revenue | H30: na | I30: =I22/H22-1 -> 1.2738821 | J30: =J22/I22-1 -> 0.62826544 | K30: =K22/J22-1 -> 0.35228595 | L30: =L22/K22-1 -> 0.25128235
A31: Subs-International Minutes | B31: 40 | G31: % Gross Profit/Revenue | H31: =H23/H22 -> 0.21902645 | I31: =I23/I22 -> 0.2457658 | J31: =J23/J22 -> 0.32465527 | K31: =K23/K22 -> 0.3656605 | L31: =L23/L22 -> 0.38908181
A32: Subs-Terminating Off Net Minutes | B32: =B29*0.8 -> 320 | G32: % EBITDA/Revenue | H32: =H28/H22 -> 0.11529062 | I32: =I28/I22 -> 0.3177837 | J32: =J28/J22 -> 0.41872354 | K32: =K28/K22 -> 0.47410401 | L32: =L28/L22 -> 0.50424396
A33: Subs-Terminating On Net Minutes | B33: =B29-Minutes_International_Minutes-Minutes_Terminating_Off_Net -> 40
G34: Accounts Receivable | H34: ='Financial Statements & Detail'!N47 -> 898814.59 | I34: ='Financial Statements & Detail'!Z47 -> 2221391 | J34: ='Financial Statements & Detail'!AL47 -> 3338039.6 | K34: ='Financial Statements & Detail'!AX47 -> 4401318 | L34: ='Financial Statements & Detail'!BJ47 -> 5432450.2
A35: Voice Revenue/Minute | G35: Inventory | H35: ='Financial Statements & Detail'!N48 -> 456008.98 | I35: ='Financial Statements & Detail'!Z48 -> 352651.91 | J35: ='Financial Statements & Detail'!AL48 -> 363385.97 | K35: ='Financial Statements & Detail'!AX48 -> 395197.53 | L35: ='Financial Statements & Detail'!BJ48 -> 484828.9
A36: Subs_Roaming Other Networks | B36: =Minutes_Roaming -> 1e-06 | G36: Working Capital | H36: ='Financial Statements & Detail'!N89 -> 3779935.3 | I36: ='Financial Statements & Detail'!Z89 -> 2938564.3 | J36: ='Financial Statements & Detail'!AL89 -> 3863780.1 | K36: ='Financial Statements & Detail'!AX89 -> 2865333.1 | L36: ='Financial Statements & Detail'!BJ89 -> 4940948.4
A37: Subs-International Calls | B37: 0.1 | G37: PP&E | H37: ='Financial Statements & Detail'!N56 -> 4734681.5 | I37: ='Financial Statements & Detail'!Z56 -> 14545444 | J37: ='Financial Statements & Detail'!AL56 -> 18436387 | K37: ='Financial Statements & Detail'!AX56 -> 21522269 | L37: ='Financial Statements & Detail'!BJ56 -> 23704067
A39: Voice Minute Costs | G39: AR & Inventory Financing | H39: ='Financial Statements & Detail'!N64 -> 0 | I39: ='Financial Statements & Detail'!Z64 -> 0 | J39: ='Financial Statements & Detail'!AL64 -> 0 | K39: ='Financial Statements & Detail'!AX64 -> 0 | L39: ='Financial Statements & Detail'!BJ64 -> 0
A40: Local Termination-Off Net | B40: 0.02 | G40: Total Funded Debt | H40: ='Financial Statements & Detail'!N91 -> 0 | I40: ='Financial Statements & Detail'!Z91 -> 14000000 | J40: ='Financial Statements & Detail'!AL91 -> 20500000 | K40: ='Financial Statements & Detail'!AX91 -> 20302083 | L40: ='Financial Statements & Detail'!BJ91 -> 20118273
A41: International Calls | B41: 0.008 | G41: Related Party Debt | H41: ='Financial Statements & Detail'!N73 -> 0 | I41: ='Financial Statements & Detail'!Z73 -> 0 | J41: ='Financial Statements & Detail'!AL73 -> 0 | K41: ='Financial Statements & Detail'!AX73 -> 0 | L41: ='Financial Statements & Detail'!BJ73 -> 0
A42: Roaming Other Net | B42: 0.015 | G42: Total Debt | H42: =SUM(H39:H41) -> 0 | I42: =SUM(I39:I41) -> 14000000 | J42: =SUM(J39:J41) -> 20500000 | K42: =SUM(K39:K41) -> 20302083 | L42: =SUM(L39:L41) -> 20118273
A43: Local Termination-On Net | B43: =IF(B88>0,0,0.009) -> 0 | G43: Equity | H43: ='Financial Statements & Detail'!N84 -> 15014617 | I43: ='Financial Statements & Detail'!Z84 -> 21192342 | J43: ='Financial Statements & Detail'!AL84 -> 29356591 | K43: ='Financial Statements & Detail'!AX84 -> 39770505 | L43: ='Financial Statements & Detail'!BJ84 -> 52210554
A45: Termination Revenue Non-subscribers | G45: Current Ratio | H45: ='Financial Statements & Detail'!N90 -> 11.048707 | I45: ='Financial Statements & Detail'!Z90 -> 1.833624 | J45: ='Financial Statements & Detail'!AL90 -> 1.7046557 | K45: ='Financial Statements & Detail'!AX90 -> 1.4966766 | L45: ='Financial Statements & Detail'!BJ90 -> 1.8256522
...

Sheet Financial Statements & Detail
A2: P&L, Balance Sheet, Debt Schedule
A3: Revenue and COS Detail
A4: US$
A5: Debt Schedule Row 246 | C5: 1 | D5: 1 | E5: 1 | F5: 1 | G5: 1 | H5: 1 | I5: 1 | J5: 1 | K5: 1 | L5: 1 | M5: 1 | N5: 1 | O5: 2 | P5: 2 | Q5: 2 | R5: 2 | S5: 2 | T5: 2 | U5: 2 | V5: 2 | W5: 2 | X5: 2 | Y5: 2 | Z5: 2 | AA5: 3 | AB5: 3 | AC5: 3 | AD5: 3 | AE5: 3 | AF5: 3 | AG5: 3 | AH5: 3 | AI5: 3 | AJ5: 3 | AK5: 3 | AL5: 3 | AM5: 4 | AN5: 4 | AO5: 4 | AP5: 4 | AQ5: 4 | AR5: 4 | AS5: 4 | AT5: 4 | AU5: 4 | AV5: 4 | AW5: 4 | AX5: 4 | AY5: 5 | AZ5: 5 | BA5: 5 | BB5: 5 | BC5: 5 | BD5: 5 | BE5: 5 | BF5: 5 | BG5: 5 | BH5: 5 | BI5: 5 | BJ5: 5
C6: 39455 | D6: 39486 | E6: 39515 | F6: 39546 | G6: 39576 | H6: 39607 | I6: 39637 | J6: 39668 | K6: 39699 | L6: 39729 | M6: 39760 | N6: 39790 | O6: 39821 | P6: 39852 | Q6: 39880 | R6: 39911 | S6: 39941 | T6: 39972 | U6: 40002 | V6: 40033 | W6: 40064 | X6: 40094 | Y6: 40125 | Z6: 40155 | AA6: 40186 | AB6: 40217 | AC6: 40245 | AD6: 40276 | AE6: 40306 | AF6: 40337 | AG6: 40367 | AH6: 40398 | AI6: 40429 | AJ6: 40459 | AK6: 40490 | AL6: 40520 | AM6: 40551 | AN6: 40582 | AO6: 40610 | AP6: 40641 | AQ6: 40671 | AR6: 40702 | AS6: 40732 | AT6: 40763 | AU6: 40794 | AV6: 40824 | AW6: 40855 | AX6: 40885 | AY6: 40916 | AZ6: 40947 | BA6: 40976 | BB6: 41007 | BC6: 41037 | BD6: 41068 | BE6: 41098 | BF6: 41129 | BG6: 41160 | BH6: 41190 | BI6: 41221 | BJ6: 41251
A7: Revenue | C7: =C139 -> 503622.63 | D7: =D139 -> 513695.08 | E7: =E139 -> 523465.36 | F7: =F139 -> 532942.53 | G7: =G139 -> 542135.38 | H7: =H139 -> 551052.45 | I7: =I139 -> 559702.01 | J7: =J139 -> 568092.08 | ... BJ7: =BJ139 -> 3621633.5
A8: Cost of Sales | C8: =C176 -> 391354.63 | D8: =D176 -> 398631.82 | E8: =E176 -> 411531.1 | F8: =F176 -> 418265.87 | G8: =G176 -> 424841.08 | H8: =H176 -> 431261.51 | I8: =I176 -> 437531.81 | J8: =J176 -> 443656.47 | ... BJ8: =BJ176 -> 2248484.6
A9: Gross Margin | C9: =C7-C8 -> 112268 | D9: =D7-D8 -> 115063.26 | E9: =E7-E8 -> 111934.26 | F9: =F7-F8 -> 114676.65 | G9: =G7-G8 -> 117294.3 | H9: =H7-H8 -> 119790.94 | I9: =I7-I8 -> 122170.2 | J9: =J7-J8 -> 124435.61 | ... BJ9: =BJ7-BJ8 -> 1373148.9
A11: Operating Expenses
A12: Advertising & Promotion | C12: =OPEX!C12 -> 79420 | D12: =OPEX!D12 -> 2935.9 | E12: =OPEX!E12 -> 2889.073 | F12: =OPEX!F12 -> 2843.6508 | G12: =OPEX!G12 -> 2799.5913 | H12: =OPEX!H12 -> 2756.8535 | I12: =OPEX!I12 -> 2715.3979 | J12: =OPEX!J12 -> 2675.186 | ... BJ12: =OPEX!BJ12 -> 7166.6667
A13: Auto | C13: =OPEX!C13 -> 0 | D13: =OPEX!D13 -> 0 | E13: =OPEX!E13 -> 0 | F13: =OPEX!F13 -> 0 | G13: =OPEX!G13 -> 0 | H13: =OPEX!H13 -> 0 | I13: =OPEX!I13 -> 0 | J13: =OPEX!J13 -> 0 | ... BJ13: =OPEX!BJ13 -> 0
A14: Bad Debts | C14: =OPEX!C14 -> 0 | D14: =OPEX!D14 -> 0 | E14: =OPEX!E14 -> 0 | F14: =OPEX!F14 -> 0 | G14: =OPEX!G14 -> 0 | H14: =OPEX!H14 -> 0 | I14: =OPEX!I14 -> 0 | J14: =OPEX!J14 -> 0 | ... BJ14: =OPEX!BJ14 -> 0
A15: Bank Service Charges | C15: =OPEX!C15 -> 0 | D15: =OPEX!D15 -> 0 | E15: =OPEX!E15 -> 0 | F15: =OPEX!F15 -> 0 | G15: =OPEX!G15 -> 0 | H15: =OPEX!H15 -> 0 | I15: =OPEX!I15 -> 0 | J15: =OPEX!J15 -> 0 | ... BJ15: =OPEX!BJ15 -> 0
A16: Consultants | C16: =OPEX!C16 -> 0 | D16: =OPEX!D16 -> 0 | E16: =OPEX!E16 -> 0 | F16: =OPEX!F16 -> 0 | G16: =OPEX!G16 -> 0 | H16: =OPEX!H16 -> 0 | I16: =OPEX!I16 -> 0 | J16: =OPEX!J16 -> 0 | ... BJ16: =OPEX!BJ16 -> 0
A17: Employee Benefits | C17: =OPEX!C17 -> 13946.25 | D17: =OPEX!D17 -> 13983.75 | E17: =OPEX!E17 -> 13983.75 | F17: =OPEX!F17 -> 14021.25 | G17: =OPEX!G17 -> 14021.25 | H17: =OPEX!H17 -> 14178.75 | I17: =OPEX!I17 -> 14216.25 | J17: =OPEX!J17 -> 14216.25 | ... BJ17: =OPEX!BJ17 -> 24448.75
A18: Equipment Leases | C18: =OPEX!C18 -> 0 | D18: =OPEX!D18 -> 0 | E18: =OPEX!E18 -> 0 | F18: =OPEX!F18 -> 0 | G18: =OPEX!G18 -> 0 | H18: =OPEX!H18 -> 0 | I18: =OPEX!I18 -> 0 | J18: =OPEX!J18 -> 0 | ... BJ18: =OPEX!BJ18 -> 0
A19: Insurance | C19: =OPEX!C19 -> 0 | D19: =OPEX!D19 -> 0 | E19: =OPEX!E19 -> 0 | F19: =OPEX!F19 -> 0 | G19: =OPEX!G19 -> 0 | H19: =OPEX!H19 -> 0 | I19: =OPEX!I19 -> 0 | J19: =OPEX!J19 -> 0 | ... BJ19: =OPEX!BJ19 -> 0
A20: Legal | C20: =OPEX!C20 -> 0 | D20: =OPEX!D20 -> 0 | E20: =OPEX!E20 -> 0 | F20: =OPEX!F20 -> 0 | G20: =OPEX!G20 -> 0 | H20: =OPEX!H20 -> 0 | I20: =OPEX!I20 -> 0 | J20: =OPEX!J20 -> 0 | ... BJ20: =OPEX!BJ20 -> 0
A21: Office Rent | C21: =OPEX!C21 -> 10000 | D21: =OPEX!D21 -> 10000 | E21: =OPEX!E21 -> 10000 | F21: =OPEX!F21 -> 10000 | G21: =OPEX!G21 -> 10000 | H21: =OPEX!H21 -> 10000 | I21: =OPEX!I21 -> 10000 | J21: =OPEX!J21 -> 10000 | ... BJ21: =OPEX!BJ21 -> 80000
A22: Office Supplies | C22: =OPEX!C22 -> 1500 | D22: =OPEX!D22 -> 1500 | E22: =OPEX!E22 -> 1500 | F22: =OPEX!F22 -> 1500 | G22: =OPEX!G22 -> 1500 | H22: =OPEX!H22 -> 1500 | I22: =OPEX!I22 -> 1500 | J22: =OPEX!J22 -> 1500 | ... BJ22: =OPEX!BJ22 -> 24000
A23: Professional Fees | B23: Summary Financials and Return Calculations are on the Assumptions Tab | C23: =OPEX!C23 -> 2000 | D23: =OPEX!D23 -> 2000 | E23: =OPEX!E23 -> 2000 | F23: =OPEX!F23 -> 2000 | G23: =OPEX!G23 -> 2000 | H23: =OPEX!H23 -> 2000 | I23: =OPEX!I23 -> 2000 | J23: =OPEX!J23 -> 2000 | ... BJ23: =OPEX!BJ23 -> 6000
A24: Salaries | C24: =OPEX!C24 -> 92975 | D24: =OPEX!D24 -> 93225 | E24: =OPEX!E24 -> 93225 | F24: =OPEX!F24 -> 93475 | G24: =OPEX!G24 -> 93475 | H24: =OPEX!H24 -> 94525 | I24: =OPEX!I24 -> 94775 | J24: =OPEX!J24 -> 94775 | ... BJ24: =OPEX!BJ24 -> 162991.67
A25: Subscription/Membership | C25: =OPEX!C25 -> 0 | D25: =OPEX!D25 -> 0 | E25: =OPEX!E25 -> 0 | F25: =OPEX!F25 -> 0 | G25: =OPEX!G25 -> 0 | H25: =OPEX!H25 -> 0 | I25: =OPEX!I25 -> 0 | J25: =OPEX!J25 -> 0 | ... BJ25: =OPEX!BJ25 -> 0
A26: Telephone | C26: =OPEX!C26 -> 0 | D26: =OPEX!D26 -> 0 | E26: =OPEX!E26 -> 0 | F26: =OPEX!F26 -> 0 | G26: =OPEX!G26 -> 0 | H26: =OPEX!H26 -> 0 | I26: =OPEX!I26 -> 0 | J26: =OPEX!J26 -> 0 | ... BJ26: =OPEX!BJ26 -> 0
A27: Travel & Entertainmnet | C27: =OPEX!C27 -> 5000 | D27: =OPEX!D27 -> 5000 | E27: =OPEX!E27 -> 5000 | F27: =OPEX!F27 -> 5000 | G27: =OPEX!G27 -> 5000 | H27: =OPEX!H27 -> 5000 | I27: =OPEX!I27 -> 5000 | J27: =OPEX!J27 -> 5000 | ... BJ27: =OPEX!BJ27 -> 25312.5
A28: Other | C28: =OPEX!C28 -> 10000 | D28: =OPEX!D28 -> 10000 | E28: =OPEX!E28 -> 10000 | F28: =OPEX!F28 -> 10000 | G28: =OPEX!G28 -> 10000 | H28: =OPEX!H28 -> 10000 | I28: =OPEX!I28 -> 10000 | J28: =OPEX!J28 -> 10000 | ... BJ28: =OPEX!BJ28 -> 10000
A29: Total | C29: =SUM(C12:C28) -> 214841.25 | D29: =SUM(D12:D28) -> 138644.65 | E29: =SUM(E12:E28) -> 138597.82 | F29: =SUM(F12:F28) -> 138839.9 | G29: =SUM(G12:G28) -> 138795.84 | H29: =SUM(H12:H28) -> 139960.6 | I29: =SUM(I12:I28) -> 140206.65 | J29: =SUM(J12:J28) -> 140166.44 | ... BJ29: =SUM(BJ12:BJ28) -> 339919.58
A31: Operating Income | C31: =C9-C29 -> -102573.25 | D31: =D9-D29 -> -23581.395 | E31: =E9-E29 -> -26663.564 | F31: =F9-F29 -> -24163.246 | G31: =G9-G29 -> -21501.54 | H31: =H9-H29 -> -20169.663 | I31: =I9-I29 -> -18036.445 | J31: =J9-J29 -> -15730.826 | ... BJ31: =BJ9-BJ29 -> 1033229.3
A33: Other Expenses
A34: Interest Expense | C34: =C258 -> 0 | D34: =D258 -> 0 | E34: =E258 -> 0 | F34: =F258 -> 0 | G34: =G258 -> 0 | H34: =H258 -> 0 | I34: =I258 -> 0 | J34: =J258 -> 0 | ... BJ34: =BJ258 -> 188377.35
A35: Total | C35: =C34 -> 0 | D35: =D34 -> 0 | E35: =E34 -> 0 | F35: =F34 -> 0 | G35: =G34 -> 0 | H35: =H34 -> 0 | I35: =I34 -> 0 | J35: =J34 -> 0 | ... BJ35: =BJ34 -> 188377.35
A37: Income Before Taxes | C37: =C31-C35 -> -102573.25 | D37: =D31-D35 -> -23581.395 | E37: =E31-E35 -> -26663.564 | F37: =F31-F35 -> -24163.246 | G37: =G31-G35 -> -21501.54 | H37: =H31-H35 -> -20169.663 | I37: =I31-I35 -> -18036.445 | J37: =J31-J35 -> -15730.826 | ... BJ37: =BJ31-BJ35 -> 844851.95
A38: Income Taxes | B38: 0.35 | C38: =MAX(C37*0.35,0) -> 0 | D38: =MAX(D37*0.35,0) -> 0 | E38: =MAX(E37*0.35,0) -> 0 | F38: =MAX(F37*0.35,0) -> 0 | G38: =MAX(G37*0.35,0) -> 0 | H38: =MAX(H37*0.35,0) -> 0 | I38: =MAX(I37*0.35,0) -> 0 | J38: =MAX(J37*0.35,0) -> 0 | ... BJ38: =MAX(BJ37*0.35,0) -> 295698.18
A39: Net Income | C39: =C37-C38 -> -102573.25 | D39: =D37-D38 -> -23581.395 | E39: =E37-E38 -> -26663.564 | F39: =F37-F38 -> -24163.246 | G39: =G37-G38 -> -21501.54 | H39: =H37-H38 -> -20169.663 | I39: =I37-I38 -> -18036.445 | J39: =J37-J38 -> -15730.826 | ... BJ39: =BJ37-BJ38 -> 549153.77
A41: EBITDA | C41: =C31+C244 -> -22403.95 | D41: =D31+D244 -> 58271.375 | E41: =E31+E244 -> 56694.486 | F41: =F31+F244 -> 60688.909 | G41: =G31+G244 -> 64833.879 | H41: =H31+H244 -> 67638.503 | I41: =I31+I244 -> 71234.269 | J41: =J31+J244 -> 74992.541 | ... BJ41: =BJ31+BJ244 -> 1848242.3
A43: Balance Sheet
A44: Assets
A45: Current Assets
A46: Cash | C46: =Cashflow!C41 -> 3179582.7 | D46: =Cashflow!D41 -> 3083639 | E46: =Cashflow!E41 -> 3035337.8 | F46: =Cashflow!F41 -> 2992285.7 | G46: =Cashflow!G41 -> 2954312.5 | H46: =Cashflow!H41 -> 2920792.9 | I46: =Cashflow!I41 -> 2891423 | J46: =Cashflow!J41 -> 2866651.1 | ... BJ46: =Cashflow!BJ41 -> 5007966.9
A47: Accounts Receivable | C47: =C247 -> 755433.94 | D47: =D247 -> 770542.62 | E47: =E247 -> 785198.03 | F47: =F247 -> 799413.79 | G47: =G247 -> 813203.07 | H47: =H247 -> 826578.68 | I47: =I247 -> 839553.01 | J47: =J247 -> 852138.12 | ... BJ47: =BJ247 -> 5432450.2
...

Sheet Cashflow
A2: Cash Flow Statement
A3: US$
C6: 39455 | D6: 39486 | E6: 39515 | F6: 39546 | G6: 39576 | H6: 39607 | I6: 39637 | J6: 39668 | K6: 39699 | L6: 39729 | M6: 39760 | N6: 39790 | O6: 39821 | P6: 39852 | Q6: 39880 | R6: 39911 | S6: 39941 | T6: 39972 | U6: 40002 | V6: 40033 | W6: 40064 | X6: 40094 | Y6: 40125 | Z6: 40155 | AA6: 40186 | AB6: 40217 | AC6: 40245 | AD6: 40276 | AE6: 40306 | AF6: 40337 | AG6: 40367 | AH6: 40398 | AI6: 40429 | AJ6: 40459 | AK6: 40490 | AL6: 40520 | AM6: 40551 | AN6: 40582 | AO6: 40610 | AP6: 40641 | AQ6: 40671 | AR6: 40702 | AS6: 40732 | AT6: 40763 | AU6: 40794 | AV6: 40824 | AW6: 40855 | AX6: 40885 | AY6: 40916 | AZ6: 40947 | BA6: 40976 | BB6: 41007 | BC6: 41037 | BD6: 41068 | BE6: 41098 | BF6: 41129 | BG6: 41160 | BH6: 41190 | BI6: 41221 | BJ6: 41251
A8: Cash provided by (used in)
A10: Operating activities
A11: Net income (loss) for the period | C11: ='Financial Statements & Detail'!C83 -> -102573.25 | D11: ='Financial Statements & Detail'!D83 -> -23581.395 | E11: ='Financial Statements & Detail'!E83 -> -26663.564 | F11: ='Financial Statements & Detail'!F83 -> -24163.246 | G11: ='Financial Statements & Detail'!G83 -> -21501.54 | H11: ='Financial Statements & Detail'!H83 -> -20169.663 | I11: ='Financial Statements & Detail'!I83 -> -18036.445 | J11: ='Financial Statements & Detail'!J83 -> -15730.826 | ... BJ11: ='Financial Statements & Detail'!BJ83 -> 549153.77
A12: Non-cash transactions
A13: Depreciation | C13: ='Financial Statements & Detail'!C244 -> 80169.301 | D13: ='Financial Statements & Detail'!D244 -> 81852.77 | E13: ='Financial Statements & Detail'!E244 -> 83358.051 | F13: ='Financial Statements & Detail'!F244 -> 84852.155 | G13: ='Financial Statements & Detail'!G244 -> 86335.419 | H13: ='Financial Statements & Detail'!H244 -> 87808.166 | I13: ='Financial Statements & Detail'!I244 -> 89270.714 | J13: ='Financial Statements & Detail'!J244 -> 90723.367 | ... BJ13: ='Financial Statements & Detail'!BJ244 -> 815012.99
A14: Amortization | C14: 0 | D14: 0 | E14: 0 | F14: 0 | G14: 0 | H14: 0 | I14: 0 | J14: 0 | K14: 0 | L14: 0 | M14: 0 | N14: 0 | O14: 0 | P14: 0 | Q14: 0 | R14: 0 | S14: 0 | T14: 0 | U14: 0 | V14: 0 | W14: 0 | X14: 0 | Y14: 0 | Z14: 0 | AA14: 0 | AB14: 0 | AC14: 0 | AD14: 0 | AE14: 0 | AF14: 0 | AG14: 0 | AH14: 0 | AI14: 0 | AJ14: 0 | AK14: 0 | AL14: 0 | AM14: 0 | AN14: 0 | AO14: 0 | AP14: 0 | AQ14: 0 | AR14: 0 | AS14: 0 | AT14: 0 | AU14: 0 | AV14: 0 | AW14: 0 | AX14: 0 | AY14: 0 | AZ14: 0 | BA14: 0 | BB14: 0 | BC14: 0 | BD14: 0 | BE14: 0 | BF14: 0 | BG14: 0 | BH14: 0 | BI14: 0 | BJ14: 0
A15: Non-cash interest accrued | C15: 0 | D15: 0 | E15: 0 | F15: 0 | G15: 0 | H15: 0 | I15: 0 | J15: 0 | K15: 0 | L15: 0 | M15: 0 | N15: 0 | O15: 0 | P15: 0 | Q15: 0 | R15: 0 | S15: 0 | T15: 0 | U15: 0 | V15: 0 | W15: 0 | X15: 0 | Y15: 0 | Z15: 0 | AA15: 0 | AB15: 0 | AC15: 0 | AD15: 0 | AE15: 0 | AF15: 0 | AG15: 0 | AH15: 0 | AI15: 0 | AJ15: 0 | AK15: 0 | AL15: 0 | AM15: 0 | AN15: 0 | AO15: 0 | AP15: 0 | AQ15: 0 | AR15: 0 | AS15: 0 | AT15: 0 | AU15: 0 | AV15: 0 | AW15: 0 | AX15: 0 | AY15: 0 | AZ15: 0 | BA15: 0 | BB15: 0 | BC15: 0 | BD15: 0 | BE15: 0 | BF15: 0 | BG15: 0 | BH15: 0 | BI15: 0 | BJ15: 0
A16: Sub-total | C16: =SUM(C13:C15) -> 80169.301 | D16: =SUM(D13:D15) -> 81852.77 | E16: =SUM(E13:E15) -> 83358.051 | F16: =SUM(F13:F15) -> 84852.155 | G16: =SUM(G13:G15) -> 86335.419 | H16: =SUM(H13:H15) -> 87808.166 | I16: =SUM(I13:I15) -> 89270.714 | J16: =SUM(J13:J15) -> 90723.367 | ... BJ16: =SUM(BJ13:BJ15) -> 815012.99
A17: Changes in assets and liabilities
A18: Accounts receivable | C18: ='Financial Statements & Detail'!B47-'Financial Statements & Detail'!C47 -> -755433.94 | D18: ='Financial Statements & Detail'!C47-'Financial Statements & Detail'!D47 -> -15108.679 | E18: ='Financial Statements & Detail'!D47-'Financial Statements & Detail'!E47 -> -14655.418 | F18: ='Financial Statements & Detail'!E47-'Financial Statements & Detail'!F47 -> -14215.756 | G18: ='Financial Statements & Detail'!F47-'Financial Statements & Detail'!G47 -> -13789.283 | H18: ='Financial Statements & Detail'!G47-'Financial Statements & Detail'!H47 -> -13375.605 | I18: ='Financial Statements & Detail'!H47-'Financial Statements & Detail'!I47 -> -12974.337 | J18: ='Financial Statements & Detail'!I47-'Financial Statements & Detail'!J47 -> -12585.106 | ... BJ18: ='Financial Statements & Detail'!BI47-'Financial Statements & Detail'!BJ47 -> 66429.796
A19: Inventories | C19: ='Financial Statements & Detail'!B48-'Financial Statements & Detail'!C48 -> -191924.09 | D19: ='Financial Statements & Detail'!C48-'Financial Statements & Detail'!D48 -> 432.72281 | E19: ='Financial Statements & Detail'!D48-'Financial Statements & Detail'!E48 -> 419.74113 | F19: ='Financial Statements & Detail'!E48-'Financial Statements & Detail'!F48 -> 407.14889 | G19: ='Financial Statements & Detail'!F48-'Financial Statements & Detail'!G48 -> 394.93443 | H19: ='Financial Statements & Detail'!G48-'Financial Statements & Detail'!H48 -> 383.08639 | I19: ='Financial Statements & Detail'!H48-'Financial Statements & Detail'!I48 -> 371.5938 | J19: ='Financial Statements & Detail'!I48-'Financial Statements & Detail'!J48 -> 360.44599 | ... BJ19: ='Financial Statements & Detail'!BI48-'Financial Statements & Detail'!BJ48 -> 0
A20: Prepaid expenses | C20: ='Financial Statements & Detail'!B49-'Financial Statements & Detail'!C49 -> 0 | D20: ='Financial Statements & Detail'!C49-'Financial Statements & Detail'!D49 -> 0 | E20: ='Financial Statements & Detail'!D49-'Financial Statements & Detail'!E49 -> 0 | F20: ='Financial Statements & Detail'!E49-'Financial Statements & Detail'!F49 -> 0 | G20: ='Financial Statements & Detail'!F49-'Financial Statements & Detail'!G49 -> 0 | H20: ='Financial Statements & Detail'!G49-'Financial Statements & Detail'!H49 -> 0 | I20: ='Financial Statements & Detail'!H49-'Financial Statements & Detail'!I49 -> 0 | J20: ='Financial Statements & Detail'!I49-'Financial Statements & Detail'!J49 -> 0 | ... BJ20: ='Financial Statements & Detail'!BI49-'Financial Statements & Detail'!BJ49 -> 0
A21: Other Assets | C21: ='Financial Statements & Detail'!B58-'Financial Statements & Detail'!C58 -> -6500000 | D21: ='Financial Statements & Detail'!C58-'Financial Statements & Detail'!D58 -> 0 | E21: ='Financial Statements & Detail'!D58-'Financial Statements & Detail'!E58 -> 0 | F21: ='Financial Statements & Detail'!E58-'Financial Statements & Detail'!F58 -> 0 | G21: ='Financial Statements & Detail'!F58-'Financial Statements & Detail'!G58 -> 0 | H21: ='Financial Statements & Detail'!G58-'Financial Statements & Detail'!H58 -> 0 | I21: ='Financial Statements & Detail'!H58-'Financial Statements & Detail'!I58 -> 0 | J21: ='Financial Statements & Detail'!I58-'Financial Statements & Detail'!J58 -> 0 | ... BJ21: ='Financial Statements & Detail'!BI58-'Financial Statements & Detail'!BJ58 -> 0
A22: Accounts payable | C22: ='Financial Statements & Detail'!C66-'Financial Statements & Detail'!B66 -> 41924.094 | D22: ='Financial Statements & Detail'!D66-'Financial Statements & Detail'!C66 -> -432.72281 | E22: ='Financial Statements & Detail'!E66-'Financial Statements & Detail'!D66 -> -419.74113 | F22: ='Financial Statements & Detail'!F66-'Financial Statements & Detail'!E66 -> -407.14889 | G22: ='Financial Statements & Detail'!G66-'Financial Statements & Detail'!F66 -> -394.93443 | H22: ='Financial Statements & Detail'!H66-'Financial Statements & Detail'!G66 -> -383.08639 | I22: ='Financial Statements & Detail'!I66-'Financial Statements & Detail'!H66 -> -371.5938 | J22: ='Financial Statements & Detail'!J66-'Financial Statements & Detail'!I66 -> -360.44599 | ... BJ22: ='Financial Statements & Detail'!BJ66-'Financial Statements & Detail'!BI66 -> 0
A23: Accrued expenses | C23: ='Financial Statements & Detail'!C67-'Financial Statements & Detail'!B67 -> 107420.62 | D23: ='Financial Statements & Detail'!D67-'Financial Statements & Detail'!C67 -> -38098.3 | E23: ='Financial Statements & Detail'!E67-'Financial Statements & Detail'!D67 -> -23.4135 | F23: ='Financial Statements & Detail'!F67-'Financial Statements & Detail'!E67 -> 121.03891 | G23: ='Financial Statements & Detail'!G67-'Financial Statements & Detail'!F67 -> -22.029762 | H23: ='Financial Statements & Detail'!H67-'Financial Statements & Detail'!G67 -> 582.38113 | I23: ='Financial Statements & Detail'!I67-'Financial Statements & Detail'!H67 -> 123.0222 | J23: ='Financial Statements & Detail'!J67-'Financial Statements & Detail'!I67 -> -20.105969 | ... BJ23: ='Financial Statements & Detail'!BJ67-'Financial Statements & Detail'!BI67 -> -287.5
A24: Income taxes payable | C24: ='Financial Statements & Detail'!C68-'Financial Statements & Detail'!B68 -> 0 | D24: ='Financial Statements & Detail'!D68-'Financial Statements & Detail'!C68 -> 0 | E24: ='Financial Statements & Detail'!E68-'Financial Statements & Detail'!D68 -> 0 | F24: ='Financial Statements & Detail'!F68-'Financial Statements & Detail'!E68 -> 0 | G24: ='Financial Statements & Detail'!G68-'Financial Statements & Detail'!F68 -> 0 | H24: ='Financial Statements & Detail'!H68-'Financial Statements & Detail'!G68 -> 0 | I24: ='Financial Statements & Detail'!I68-'Financial Statements & Detail'!H68 -> 0 | J24: ='Financial Statements & Detail'!J68-'Financial Statements & Detail'!I68 -> 0 | ... BJ24: ='Financial Statements & Detail'!BJ68-'Financial Statements & Detail'!BI68 -> -9366.0789
A25: Sub-total | C25: =SUM(C18:C24) -> -7298013.3 | D25: =SUM(D18:D24) -> -53206.979 | E25: =SUM(E18:E24) -> -14678.832 | F25: =SUM(F18:F24) -> -14094.717 | G25: =SUM(G18:G24) -> -13811.313 | H25: =SUM(H18:H24) -> -12793.224 | I25: =SUM(I18:I24) -> -12851.314 | J25: =SUM(J18:J24) -> -12605.212 | ... BJ25: =SUM(BJ18:BJ24) -> 56776.217
A26: Total Operating Activities | C26: =C11+C16+C25 -> -7320417.3 | D26: =D11+D16+D25 -> 5064.3962 | E26: =E11+E16+E25 -> 42015.655 | F26: =F11+F16+F25 -> 46594.192 | G26: =G11+G16+G25 -> 51022.566 | H26: =H11+H16+H25 -> 54845.28 | I26: =I11+I16+I25 -> 58382.955 | J26: =J11+J16+J25 -> 62387.329 | ... BJ26: =BJ11+BJ16+BJ25 -> 1420943 | BK26: =SUM(AY26:BJ26) -> 6281825.3
A28: Investing Activities
A29: Purchase of PPE | C29: ='Financial Statements & Detail'!B54-'Financial Statements & Detail'!C54 -> -4810158 | D29: ='Financial Statements & Detail'!C54-'Financial Statements & Detail'!D54 -> -101008.16 | E29: ='Financial Statements & Detail'!D54-'Financial Statements & Detail'!E54 -> -90316.844 | F29: ='Financial Statements & Detail'!E54-'Financial Statements & Detail'!F54 -> -89646.268 | G29: ='Financial Statements & Detail'!F54-'Financial Statements & Detail'!G54 -> -88995.808 | H29: ='Financial Statements & Detail'!G54-'Financial Statements & Detail'!H54 -> -88364.863 | I29: ='Financial Statements & Detail'!H54-'Financial Statements & Detail'!I54 -> -87752.845 | J29: ='Financial Statements & Detail'!I54-'Financial Statements & Detail'!J54 -> -87159.188 | ... BJ29: ='Financial Statements & Detail'!BI54-'Financial Statements & Detail'!BJ54 -> -344238.1
A30: Leasehold improvements | C30: 0 | D30: 0 | E30: 0 | F30: 0 | G30: 0 | H30: 0 | I30: 0 | J30: 0 | K30: 0 | L30: 0 | M30: 0 | N30: 0 | O30: 0 | P30: 0 | Q30: 0 | R30: 0 | S30: 0 | T30: 0 | U30: 0 | V30: 0 | W30: 0 | X30: 0 | Y30: 0 | Z30: 0 | AA30: 0 | AB30: 0 | AC30: 0 | AD30: 0 | AE30: 0 | AF30: 0 | AG30: 0 | AH30: 0 | AI30: 0 | AJ30: 0 | AK30: 0 | AL30: 0 | AM30: 0 | AN30: 0 | AO30: 0 | AP30: 0 | AQ30: 0 | AR30: 0 | AS30: 0 | AT30: 0 | AU30: 0 | AV30: 0 | AW30: 0 | AX30: 0 | AY30: 0 | AZ30: 0 | BA30: 0 | BB30: 0 | BC30: 0 | BD30: 0 | BE30: 0 | BF30: 0 | BG30: 0 | BH30: 0 | BI30: 0 | BJ30: 0
A31: Total | C31: =SUM(C29:C30) -> -4810158 | D31: =SUM(D29:D30) -> -101008.16 | E31: =SUM(E29:E30) -> -90316.844 | F31: =SUM(F29:F30) -> -89646.268 | G31: =SUM(G29:G30) -> -88995.808 | H31: =SUM(H29:H30) -> -88364.863 | I31: =SUM(I29:I30) -> -87752.845 | J31: =SUM(J29:J30) -> -87159.188 | ... BJ31: =SUM(BJ29:BJ30) -> -344238.1 | BK31: =SUM(AY31:BJ31) -> -11177877
A32: Financing activities
A33: Line of credit | C33: ='Financial Statements & Detail'!C64-'Financial Statements & Detail'!B64 -> 0 | D33: ='Financial Statements & Detail'!D64-'Financial Statements & Detail'!C64 -> 0 | E33: ='Financial Statements & Detail'!E64-'Financial Statements & Detail'!D64 -> 0 | F33: ='Financial Statements & Detail'!F64-'Financial Statements & Detail'!E64 -> 0 | G33: ='Financial Statements & Detail'!G64-'Financial Statements & Detail'!F64 -> 0 | H33: ='Financial Statements & Detail'!H64-'Financial Statements & Detail'!G64 -> 0 | I33: ='Financial Statements & Detail'!I64-'Financial Statements & Detail'!H64 -> 0 | J33: ='Financial Statements & Detail'!J64-'Financial Statements & Detail'!I64 -> 0 | ... BJ33: ='Financial Statements & Detail'!BJ64-'Financial Statements & Detail'!BI64 -> 0
A34: Long Term Debt | C34: ='Financial Statements & Detail'!C65+'Financial Statements & Detail'!C72-'Financial Statements & Detail'!B65-'Financial Statements & Detail'!B72 -> 0 | D34: ='Financial Statements & Detail'!D65+'Financial Statements & Detail'!D72-'Financial Statements & Detail'!C65-'Financial Statements & Detail'!C72 -> 0 | E34: ='Financial Statements & Detail'!E65+'Financial Statements & Detail'!E72-'Financial Statements & Detail'!D65-'Financial Statements & Detail'!D72 -> 0 | F34: ='Financial Statements & Detail'!F65+'Financial Statements & Detail'!F72-'Financial Statements & Detail'!E65-'Financial Statements & Detail'!E72 -> 0 | G34: ='Financial Statements & Detail'!G65+'Financial Statements & Detail'!G72-'Financial Statements & Detail'!F65-'Financial Statements & Detail'!F72 -> 0 | H34: ='Financial Statements & Detail'!H65+'Financial Statements & Detail'!H72-'Financial Statements & Detail'!G65-'Financial Statements & Detail'!G72 -> 0 | I34: ='Financial Statements & Detail'!I65+'Financial Statements & Detail'!I72-'Financial Statements & Detail'!H65-'Financial Statements & Detail'!H72 -> 0 | J34: ='Financial Statements & Detail'!J65+'Financial Statements & Detail'!J72-'Financial Statements & Detail'!I65-'Financial Statements & Detail'!I72 -> 0 | ... BJ34: ='Financial Statements & Detail'!BJ65+'Financial Statements & Detail'!BJ72-'Financial Statements & Detail'!BI65-'Financial Statements & Detail'!BI72 -> -431984.23
A35: Proceeds from stock | C35: ='Financial Statements & Detail'!C78-'Financial Statements & Detail'!B78 -> 15310158 | D35: ='Financial Statements & Detail'!D78-'Financial Statements & Detail'!C78 -> 0 | E35: ='Financial Statements & Detail'!E78-'Financial Statements & Detail'!D78 -> 0 | F35: ='Financial Statements & Detail'!F78-'Financial Statements & Detail'!E78 -> 0 | G35: ='Financial Statements & Detail'!G78-'Financial Statements & Detail'!F78 -> 0 | H35: ='Financial Statements & Detail'!H78-'Financial Statements & Detail'!G78 -> 0 | I35: ='Financial Statements & Detail'!I78-'Financial Statements & Detail'!H78 -> 0 | J35: ='Financial Statements & Detail'!J78-'Financial Statements & Detail'!I78 -> 0 | ... BJ35: ='Financial Statements & Detail'!BJ78-'Financial Statements & Detail'!BI78 -> 0
A36: Due to shareholders | C36: ='Financial Statements & Detail'!C73-'Financial Statements & Detail'!B73 -> 0 | D36: ='Financial Statements & Detail'!D73-'Financial Statements & Detail'!C73 -> 0 | E36: ='Financial Statements & Detail'!E73-'Financial Statements & Detail'!D73 -> 0 | F36: ='Financial Statements & Detail'!F73-'Financial Statements & Detail'!E73 -> 0 | G36: ='Financial Statements & Detail'!G73-'Financial Statements & Detail'!F73 -> 0 | H36: ='Financial Statements & Detail'!H73-'Financial Statements & Detail'!G73 -> 0 | I36: ='Financial Statements & Detail'!I73-'Financial Statements & Detail'!H73 -> 0 | J36: ='Financial Statements & Detail'!J73-'Financial Statements & Detail'!I73 -> 0 | ... BJ36: ='Financial Statements & Detail'!BJ73-'Financial Statements & Detail'!BI73 -> 0
A37: Total | C37: =SUM(C33:C36) -> 15310158 | D37: =SUM(D33:D36) -> 0 | E37: =SUM(E33:E36) -> 0 | F37: =SUM(F33:F36) -> 0 | G37: =SUM(G33:G36) -> 0 | H37: =SUM(H33:H36) -> 0 | I37: =SUM(I33:I36) -> 0 | J37: =SUM(J33:J36) -> 0 | ... BJ37: =SUM(BJ33:BJ36) -> -431984.23
A39: Increase (decrease) in cash during period | C39: =C26+C31+C37 -> 3179582.7 | D39: =D26+D31+D37 -> -95943.765 | E39: =E26+E31+E37 -> -48301.19 | F39: =F26+F31+F37 -> -43052.075 | G39: =G26+G31+G37 -> -37973.243 | H39: =H26+H31+H37 -> -33519.583 | I39: =I26+I31+I37 -> -29369.891 | J39: =J26+J31+J37 -> -24771.86 | ... BJ39: =BJ26+BJ31+BJ37 -> 644720.65
A40: Cash beginning of period | C40: 0 | D40: =C41 -> 3179582.7 | E40: =D41 -> 3083639 | F40: =E41 -> 3035337.8 | G40: =F41 -> 2992285.7 | H40: =G41 -> 2954312.5 | I40: =H41 -> 2920792.9 | J40: =I41 -> 2891423 | K40: =J41 -> 2866651.1 | ... BJ40: =BI41 -> 4363246.3
A41: Cash end of period | C41: =SUM(C39:C40) -> 3179582.7 | D41: =SUM(D39:D40) -> 3083639 | E41: =SUM(E39:E40) -> 3035337.8 | F41: =SUM(F39:F40) -> 2992285.7 | G41: =SUM(G39:G40) -> 2954312.5 | H41: =SUM(H39:H40) -> 2920792.9 | I41: =SUM(I39:I40) -> 2891423 | J41: =SUM(J39:J40) -> 2866651.1 | ... BJ41: =SUM(BJ39:BJ40) -> 5007966.9

Sheet OPEX
A2: OPEX
A3: US$
C6: 39455 | D6: 39486 | E6: 39515 | F6: 39546 | G6: 39576 | H6: 39607 | I6: 39637 | J6: 39668 | K6: 39699 | L6: 39729 | M6: 39760 | N6: 39790 | O6: 39821 | P6: 39852 | Q6: 39880 | R6: 39911 | S6: 39941 | T6: 39972 | U6: 40002 | V6: 40033 | W6: 40064 | X6: 40094 | Y6: 40125 | Z6: 40155 | AA6: 40186 | AB6: 40217 | AC6: 40245 | AD6: 40276 | AE6: 40306 | AF6: 40337 | AG6: 40367 | AH6: 40398 | AI6: 40429 | AJ6: 40459 | AK6: 40490 | AL6: 40520 | AM6: 40551 | AN6: 40582 | AO6: 40610 | AP6: 40641 | AQ6: 40671 | AR6: 40702 | AS6: 40732 | AT6: 40763 | AU6: 40794 | AV6: 40824 | AW6: 40855 | AX6: 40885 | AY6: 40916 | AZ6: 40947 | BA6: 40976 | BB6: 41007 | BC6: 41037 | BD6: 41068 | BE6: 41098 | BF6: 41129 | BG6: 41160 | BH6: 41190 | BI6: 41221 | BJ6: 41251
A11: Operating Expenses
A12: Advertising & Promotion | C12: =C99 -> 79420 | D12: =D99 -> 2935.9 | E12: =E99 -> 2889.073 | F12: =F99 -> 2843.6508 | G12: =G99 -> 2799.5913 | H12: =H99 -> 2756.8535 | I12: =I99 -> 2715.3979 | J12: =J99 -> 2675.186 | ... BJ12: =BJ99 -> 7166.6667
A13: Auto | C13: 0 | D13: 0 | E13: 0 | F13: 0 | G13: 0 | H13: 0 | I13: 0 | J13: 0 | K13: 0 | L13: 0 | M13: 0 | N13: 0 | O13: 0 | P13: 0 | Q13: 0 | R13: 0 | S13: 0 | T13: 0 | U13: 0 | V13: 0 | W13: 0 | X13: 0 | Y13: 0 | Z13: 0 | AA13: 0 | AB13: 0 | AC13: 0 | AD13: 0 | AE13: 0 | AF13: 0 | AG13: 0 | AH13: 0 | AI13: 0 | AJ13: 0 | AK13: 0 | AL13: 0 | AM13: 0 | AN13: 0 | AO13: 0 | AP13: 0 | AQ13: 0 | AR13: 0 | AS13: 0 | AT13: 0 | AU13: 0 | AV13: 0 | AW13: 0 | AX13: 0 | AY13: 0 | AZ13: 0 | BA13: 0 | BB13: 0 | BC13: 0 | BD13: 0 | BE13: 0 | BF13: 0 | BG13: 0 | BH13: 0 | BI13: 0 | BJ13: 0
A14: Bad Debts | C14: 0 | D14: 0 | E14: 0 | F14: 0 | G14: 0 | H14: 0 | I14: 0 | J14: 0 | K14: 0 | L14: 0 | M14: 0 | N14: 0 | O14: 0 | P14: 0 | Q14: 0 | R14: 0 | S14: 0 | T14: 0 | U14: 0 | V14: 0 | W14: 0 | X14: 0 | Y14: 0 | Z14: 0 | AA14: 0 | AB14: 0 | AC14: 0 | AD14: 0 | AE14: 0 | AF14: 0 | AG14: 0 | AH14: 0 | AI14: 0 | AJ14: 0 | AK14: 0 | AL14: 0 | AM14: 0 | AN14: 0 | AO14: 0 | AP14: 0 | AQ14: 0 | AR14: 0 | AS14: 0 | AT14: 0 | AU14: 0 | AV14: 0 | AW14: 0 | AX14: 0 | AY14: 0 | AZ14: 0 | BA14: 0 | BB14: 0 | BC14: 0 | BD14: 0 | BE14: 0 | BF14: 0 | BG14: 0 | BH14: 0 | BI14: 0 | BJ14: 0
A15: Bank Service Charges | C15: 0 | D15: 0 | E15: 0 | F15: 0 | G15: 0 | H15: 0 | I15: 0 | J15: 0 | K15: 0 | L15: 0 | M15: 0 | N15: 0 | O15: 0 | P15: 0 | Q15: 0 | R15: 0 | S15: 0 | T15: 0 | U15: 0 | V15: 0 | W15: 0 | X15: 0 | Y15: 0 | Z15: 0 | AA15: 0 | AB15: 0 | AC15: 0 | AD15: 0 | AE15: 0 | AF15: 0 | AG15: 0 | AH15: 0 | AI15: 0 | AJ15: 0 | AK15: 0 | AL15: 0 | AM15: 0 | AN15: 0 | AO15: 0 | AP15: 0 | AQ15: 0 | AR15: 0 | AS15: 0 | AT15: 0 | AU15: 0 | AV15: 0 | AW15: 0 | AX15: 0 | AY15: 0 | AZ15: 0 | BA15: 0 | BB15: 0 | BC15: 0 | BD15: 0 | BE15: 0 | BF15: 0 | BG15: 0 | BH15: 0 | BI15: 0 | BJ15: 0
A16: Consultants | C16: 0 | D16: 0 | E16: 0 | F16: 0 | G16: 0 | H16: 0 | I16: 0 | J16: 0 | K16: 0 | L16: 0 | M16: 0 | N16: 0 | O16: 0 | P16: 0 | Q16: 0 | R16: 0 | S16: 0 | T16: 0 | U16: 0 | V16: 0 | W16: 0 | X16: 0 | Y16: 0 | Z16: 0 | AA16: 0 | AB16: 0 | AC16: 0 | AD16: 0 | AE16: 0 | AF16: 0 | AG16: 0 | AH16: 0 | AI16: 0 | AJ16: 0 | AK16: 0 | AL16: 0 | AM16: 0 | AN16: 0 | AO16: 0 | AP16: 0 | AQ16: 0 | AR16: 0 | AS16: 0 | AT16: 0 | AU16: 0 | AV16: 0 | AW16: 0 | AX16: 0 | AY16: 0 | AZ16: 0 | BA16: 0 | BB16: 0 | BC16: 0 | BD16: 0 | BE16: 0 | BF16: 0 | BG16: 0 | BH16: 0 | BI16: 0 | BJ16: 0
A17: Employee Benefits | C17: =C79 -> 13946.25 | D17: =D79 -> 13983.75 | E17: =E79 -> 13983.75 | F17: =F79 -> 14021.25 | G17: =G79 -> 14021.25 | H17: =H79 -> 14178.75 | I17: =I79 -> 14216.25 | J17: =J79 -> 14216.25 | ... BJ17: =BJ79 -> 24448.75
A18: Equipment Leases | C18: 0 | D18: 0 | E18: 0 | F18: 0 | G18: 0 | H18: 0 | I18: 0 | J18: 0 | K18: 0 | L18: 0 | M18: 0 | N18: 0 | O18: 0 | P18: 0 | Q18: 0 | R18: 0 | S18: 0 | T18: 0 | U18: 0 | V18: 0 | W18: 0 | X18: 0 | Y18: 0 | Z18: 0 | AA18: 0 | AB18: 0 | AC18: 0 | AD18: 0 | AE18: 0 | AF18: 0 | AG18: 0 | AH18: 0 | AI18: 0 | AJ18: 0 | AK18: 0 | AL18: 0 | AM18: 0 | AN18: 0 | AO18: 0 | AP18: 0 | AQ18: 0 | AR18: 0 | AS18: 0 | AT18: 0 | AU18: 0 | AV18: 0 | AW18: 0 | AX18: 0 | AY18: 0 | AZ18: 0 | BA18: 0 | BB18: 0 | BC18: 0 | BD18: 0 | BE18: 0 | BF18: 0 | BG18: 0 | BH18: 0 | BI18: 0 | BJ18: 0
A19: Insurance | C19: =C103 -> 0 | D19: =D103 -> 0 | E19: =E103 -> 0 | F19: =F103 -> 0 | G19: =G103 -> 0 | H19: =H103 -> 0 | I19: =I103 -> 0 | J19: =J103 -> 0 | ... BJ19: =BJ103 -> 0
A20: Legal | C20: 0 | D20: 0 | E20: 0 | F20: 0 | G20: 0 | H20: 0 | I20: 0 | J20: 0 | K20: 0 | L20: 0 | M20: 0 | N20: 0 | O20: 0 | P20: 0 | Q20: 0 | R20: 0 | S20: 0 | T20: 0 | U20: 0 | V20: 0 | W20: 0 | X20: 0 | Y20: 0 | Z20: 0 | AA20: 0 | AB20: 0 | AC20: 0 | AD20: 0 | AE20: 0 | AF20: 0 | AG20: 0 | AH20: 0 | AI20: 0 | AJ20: 0 | AK20: 0 | AL20: 0 | AM20: 0 | AN20: 0 | AO20: 0 | AP20: 0 | AQ20: 0 | AR20: 0 | AS20: 0 | AT20: 0 | AU20: 0 | AV20: 0 | AW20: 0 | AX20: 0 | AY20: 0 | AZ20: 0 | BA20: 0 | BB20: 0 | BC20: 0 | BD20: 0 | BE20: 0 | BF20: 0 | BG20: 0 | BH20: 0 | BI20: 0 | BJ20: 0
A21: Office Rent | C21: =C104 -> 10000 | D21: =D104 -> 10000 | E21: =E104 -> 10000 | F21: =F104 -> 10000 | G21: =G104 -> 10000 | H21: =H104 -> 10000 | I21: =I104 -> 10000 | J21: =J104 -> 10000 | ... BJ21: =BJ104 -> 80000
A22: Office Supplies | C22: =C105 -> 1500 | D22: =D105 -> 1500 | E22: =E105 -> 1500 | F22: =F105 -> 1500 | G22: =G105 -> 1500 | H22: =H105 -> 1500 | I22: =I105 -> 1500 | J22: =J105 -> 1500 | ... BJ22: =BJ105 -> 24000
A23: Professional Fees | C23: =C101 -> 2000 | D23: =D101 -> 2000 | E23: =E101 -> 2000 | F23: =F101 -> 2000 | G23: =G101 -> 2000 | H23: =H101 -> 2000 | I23: =I101 -> 2000 | J23: =J101 -> 2000 | ... BJ23: =BJ101 -> 6000
A24: Salaries | C24: =C77 -> 92975 | D24: =D77 -> 93225 | E24: =E77 -> 93225 | F24: =F77 -> 93475 | G24: =G77 -> 93475 | H24: =H77 -> 94525 | I24: =I77 -> 94775 | J24: =J77 -> 94775 | ... BJ24: =BJ77 -> 162991.67
A25: Subscription/Membership | C25: 0 | D25: 0 | E25: 0 | F25: 0 | G25: 0 | H25: 0 | I25: 0 | J25: 0 | K25: 0 | L25: 0 | M25: 0 | N25: 0 | O25: 0 | P25: 0 | Q25: 0 | R25: 0 | S25: 0 | T25: 0 | U25: 0 | V25: 0 | W25: 0 | X25: 0 | Y25: 0 | Z25: 0 | AA25: 0 | AB25: 0 | AC25: 0 | AD25: 0 | AE25: 0 | AF25: 0 | AG25: 0 | AH25: 0 | AI25: 0 | AJ25: 0 | AK25: 0 | AL25: 0 | AM25: 0 | AN25: 0 | AO25: 0 | AP25: 0 | AQ25: 0 | AR25: 0 | AS25: 0 | AT25: 0 | AU25: 0 | AV25: 0 | AW25: 0 | AX25: 0 | AY25: 0 | AZ25: 0 | BA25: 0 | BB25: 0 | BC25: 0 | BD25: 0 | BE25: 0 | BF25: 0 | BG25: 0 | BH25: 0 | BI25: 0 | BJ25: 0
A26: Telephone | C26: 0 | D26: 0 | E26: 0 | F26: 0 | G26: 0 | H26: 0 | I26: 0 | J26: 0 | K26: 0 | L26: 0 | M26: 0 | N26: 0 | O26: 0 | P26: 0 | Q26: 0 | R26: 0 | S26: 0 | T26: 0 | U26: 0 | V26: 0 | W26: 0 | X26: 0 | Y26: 0 | Z26: 0 | AA26: 0 | AB26: 0 | AC26: 0 | AD26: 0 | AE26: 0 | AF26: 0 | AG26: 0 | AH26: 0 | AI26: 0 | AJ26: 0 | AK26: 0 | AL26: 0 | AM26: 0 | AN26: 0 | AO26: 0 | AP26: 0 | AQ26: 0 | AR26: 0 | AS26: 0 | AT26: 0 | AU26: 0 | AV26: 0 | AW26: 0 | AX26: 0 | AY26: 0 | AZ26: 0 | BA26: 0 | BB26: 0 | BC26: 0 | BD26: 0 | BE26: 0 | BF26: 0 | BG26: 0 | BH26: 0 | BI26: 0 | BJ26: 0
A27: Travel & Entertainmnet | C27: =C102 -> 5000 | D27: =D102 -> 5000 | E27: =E102 -> 5000 | F27: =F102 -> 5000 | G27: =G102 -> 5000 | H27: =H102 -> 5000 | I27: =I102 -> 5000 | J27: =J102 -> 5000 | ... BJ27: =BJ102 -> 25312.5
A28: Other | C28: 10000 | D28: 10000 | E28: 10000 | F28: 10000 | G28: 10000 | H28: 10000 | I28: 10000 | J28: 10000 | K28: 10000 | L28: 10000 | M28: 10000 | N28: 10000 | O28: 10000 | P28: 10000 | Q28: 10000 | R28: 10000 | S28: 10000 | T28: 10000 | U28: 10000 | V28: 10000 | W28: 10000 | X28: 10000 | Y28: 10000 | Z28: 10000 | AA28: 10000 | AB28: 10000 | AC28: 10000 | AD28: 10000 | AE28: 10000 | AF28: 10000 | AG28: 10000 | AH28: 10000 | AI28: 10000 | AJ28: 10000 | AK28: 10000 | AL28: 10000 | AM28: 10000 | AN28: 10000 | AO28: 10000 | AP28: 10000 | AQ28: 10000 | AR28: 10000 | AS28: 10000 | AT28: 10000 | AU28: 10000 | AV28: 10000 | AW28: 10000 | AX28: 10000 | AY28: 10000 | AZ28: 10000 | BA28: 10000 | BB28: 10000 | BC28: 10000 | BD28: 10000 | BE28: 10000 | BF28: 10000 | BG28: 10000 | BH28: 10000 | BI28: 10000 | BJ28: 10000
A29: Total | C29: =SUM(C12:C28) -> 214841.25 | D29: =SUM(D12:D28) -> 138644.65 | E29: =SUM(E12:E28) -> 138597.82 | F29: =SUM(F12:F28) -> 138839.9 | G29: =SUM(G12:G28) -> 138795.84 | H29: =SUM(H12:H28) -> 139960.6 | I29: =SUM(I12:I28) -> 140206.65 | J29: =SUM(J12:J28) -> 140166.44 | ... BJ29: =SUM(BJ12:BJ28) -> 339919.58
A31: Detail OPEX
A32: ='Financial Statements & Detail'!A109 -> Total Opening Subscribers-Cable | B32: ='Financial Statements & Detail'!B109 -> 0 | C32: ='Financial Statements & Detail'!C109 -> 11000 | D32: ='Financial Statements & Detail'!D109 -> 11220 | E32: ='Financial Statements & Detail'!E109 -> 11433.4 | F32: ='Financial Statements & Detail'!F109 -> 11640.398 | G32: ='Financial Statements & Detail'!G109 -> 11841.186 | H32: ='Financial Statements & Detail'!H109 -> 12035.95 | ... BJ32: ='Financial Statements & Detail'!BJ109 -> 79021.517
A34: Staffing
A35: Engineers Headend | C35: 9 | D35: 9 | E35: 9 | F35: 9 | G35: 9 | H35: 9 | I35: 9 | J35: 9 | K35: 9 | L35: 9 | M35: 9 | N35: 9 | O35: 9 | P35: 9 | Q35: 9 | R35: 9 | S35: 9 | T35: 9 | U35: 9 | V35: 9 | W35: 9 | X35: 9 | Y35: 9 | Z35: 9 | AA35: 9 | AB35: 9 | AC35: 9 | AD35: 9 | AE35: 9 | AF35: 9 | AG35: 9 | AH35: 9 | AI35: 9 | AJ35: 9 | AK35: 9 | AL35: 9 | AM35: 9 | AN35: 9 | AO35: 9 | AP35: 9 | AQ35: 9 | AR35: 9 | AS35: 9 | AT35: 9 | AU35: 9 | AV35: 9 | AW35: 9 | AX35: 9 | AY35: 9 | AZ35: 9 | BA35: 9 | BB35: 9 | BC35: 9 | BD35: 9 | BE35: 9 | BF35: 9 | BG35: 9 | BH35: 9 | BI35: 9 | BJ35: 9
A36: Salary per Month | C36: =4500/12 -> 375 | D36: =4500/12 -> 375 | E36: =4500/12 -> 375 | F36: =4500/12 -> 375 | G36: =4500/12 -> 375 | H36: =4500/12 -> 375 | I36: =4500/12 -> 375 | J36: =4500/12 -> 375 | ... BJ36: =4500/12 -> 375
A37: Cost | C37: =C35*C36 -> 3375 | D37: =D35*D36 -> 3375 | E37: =E35*E36 -> 3375 | F37: =F35*F36 -> 3375 | G37: =G35*G36 -> 3375 | H37: =H35*H36 -> 3375 | I37: =I35*I36 -> 3375 | J37: =J35*J36 -> 3375 | ... BJ37: =BJ35*BJ36 -> 3375
A39: Field Techs | C39: =ROUNDUP(C32/550,0) -> 20 | D39: =ROUNDUP(D32/550,0) -> 21 | E39: =ROUNDUP(E32/550,0) -> 21 | F39: =ROUNDUP(F32/550,0) -> 22 | G39: =ROUNDUP(G32/550,0) -> 22 | H39: =ROUNDUP(H32/550,0) -> 22 | I39: =ROUNDUP(I32/550,0) -> 23 | J39: =ROUNDUP(J32/550,0) -> 23 | ... BJ39: =ROUNDUP(BJ32/550,0) -> 144
A40: Salary per Month | C40: =3000/12 -> 250 | D40: =3000/12 -> 250 | E40: =3000/12 -> 250 | F40: =3000/12 -> 250 | G40: =3000/12 -> 250 | H40: =3000/12 -> 250 | I40: =3000/12 -> 250 | J40: =3000/12 -> 250 | ... BJ40: =3000/12 -> 250
A41: Cost | C41: =C39*C40 -> 5000 | D41: =D39*D40 -> 5250 | E41: =E39*E40 -> 5250 | F41: =F39*F40 -> 5500 | G41: =G39*G40 -> 5500 | H41: =H39*H40 -> 5500 | I41: =I39*I40 -> 5750 | J41: =J39*J40 -> 5750 | ... BJ41: =BJ39*BJ40 -> 36000
A43: Customer Service | C43: =ROUNDUP(C32/2000,0) -> 6 | D43: =ROUNDUP(D32/2000,0) -> 6 | E43: =ROUNDUP(E32/2000,0) -> 6 | F43: =ROUNDUP(F32/2000,0) -> 6 | G43: =ROUNDUP(G32/2000,0) -> 6 | H43: =ROUNDUP(H32/2000,0) -> 7 | I43: =ROUNDUP(I32/2000,0) -> 7 | J43: =ROUNDUP(J32/2000,0) -> 7 | ... BJ43: =ROUNDUP(BJ32/2000,0) -> 40
A44: Salary per Month | C44: 200 | D44: 200 | E44: 200 | F44: 200 | G44: 200 | H44: 200 | I44: 200 | J44: 200 | K44: 200 | L44: 200 | M44: 200 | N44: 200 | O44: 200 | P44: 200 | Q44: 200 | R44: 200 | S44: 200 | T44: 200 | U44: 200 | V44: 200 | W44: 200 | X44: 200 | Y44: 200 | Z44: 200 | AA44: 200 | AB44: 200 | AC44: 200 | AD44: 200 | AE44: 200 | AF44: 200 | AG44: 200 | AH44: 200 | AI44: 200 | AJ44: 200 | AK44: 200 | AL44: 200 | AM44: 200 | AN44: 200 | AO44: 200 | AP44: 200 | AQ44: 200 | AR44: 200 | AS44: 200 | AT44: 200 | AU44: 200 | AV44: 200 | AW44: 200 | AX44: 200 | AY44: 200 | AZ44: 200 | BA44: 200 | BB44: 200 | BC44: 200 | BD44: 200 | BE44: 200 | BF44: 200 | BG44: 200 | BH44: 200 | BI44: 200 | BJ44: 200
A45: Cost | C45: =C43*C44 -> 1200 | D45: =D43*D44 -> 1200 | E45: =E43*E44 -> 1200 | F45: =F43*F44 -> 1200 | G45: =G43*G44 -> 1200 | H45: =H43*H44 -> 1400 | I45: =I43*I44 -> 1400 | J45: =J43*J44 -> 1400 | ... BJ45: =BJ43*BJ44 -> 8000
A47: Lab Testing | C47: 8 | D47: 8 | E47: 8 | F47: 8 | G47: 8 | H47: 8 | I47: 8 | J47: 8 | K47: 8 | L47: 8 | M47: 8 | N47: 8 | O47: 8 | P47: 8 | Q47: 8 | R47: 8 | S47: 8 | T47: 8 | U47: 8 | V47: 8 | W47: 8 | X47: 8 | Y47: 8 | Z47: 8 | AA47: 8 | AB47: 8 | AC47: 8 | AD47: 8 | AE47: 8 | AF47: 8 | AG47: 8 | AH47: 8 | AI47: 8 | AJ47: 8 | AK47: 8 | AL47: 8 | AM47: 8 | AN47: 8 | AO47: 8 | AP47: 8 | AQ47: 8 | AR47: 8 | AS47: 8 | AT47: 8 | AU47: 8 | AV47: 8 | AW47: 8 | AX47: 8 | AY47: 8 | AZ47: 8 | BA47: 8 | BB47: 8 | BC47: 8 | BD47: 8 | BE47: 8 | BF47: 8 | BG47: 8 | BH47: 8 | BI47: 8 | BJ47: 8
A48: Salary per Month | C48: 200 | D48: 200 | E48: 200 | F48: 200 | G48: 200 | H48: 200 | I48: 200 | J48: 200 | K48: 200 | L48: 200 | M48: 200 | N48: 200 | O48: 200 | P48: 200 | Q48: 200 | R48: 200 | S48: 200 | T48: 200 | U48: 200 | V48: 200 | W48: 200 | X48: 200 | Y48: 200 | Z48: 200 | AA48: 200 | AB48: 200 | AC48: 200 | AD48: 200 | AE48: 200 | AF48: 200 | AG48: 200 | AH48: 200 | AI48: 200 | AJ48: 200 | AK48: 200 | AL48: 200 | AM48: 200 | AN48: 200 | AO48: 200 | AP48: 200 | AQ48: 200 | AR48: 200 | AS48: 200 | AT48: 200 | AU48: 200 | AV48: 200 | AW48: 200 | AX48: 200 | AY48: 200 | AZ48: 200 | BA48: 200 | BB48: 200 | BC48: 200 | BD48: 200 | BE48: 200 | BF48: 200 | BG48: 200 | BH48: 200 | BI48: 200 | BJ48: 200
A49: Cost | C49: =C47*C48 -> 1600 | D49: =D47*D48 -> 1600 | E49: =E47*E48 -> 1600 | F49: =F47*F48 -> 1600 | G49: =G47*G48 -> 1600 | H49: =H47*H48 -> 1600 | I49: =I47*I48 -> 1600 | J49: =J47*J48 -> 1600 | ... BJ49: =BJ47*BJ48 -> 1600
A51: Accounting/Collections | C51: =ROUNDUP(C32/2000,0) -> 6 | D51: =ROUNDUP(D32/2000,0) -> 6 | E51: =ROUNDUP(E32/2000,0) -> 6 | F51: =ROUNDUP(F32/2000,0) -> 6 | G51: =ROUNDUP(G32/2000,0) -> 6 | H51: =ROUNDUP(H32/2000,0) -> 7 | I51: =ROUNDUP(I32/2000,0) -> 7 | J51: =ROUNDUP(J32/2000,0) -> 7 | ... BJ51: =ROUNDUP(BJ32/2000,0) -> 40
A52: Salary per Month | C52: 250 | D52: 250 | E52: 250 | F52: 250 | G52: 250 | H52: 250 | I52: 250 | J52: 250 | K52: 250 | L52: 250 | M52: 250 | N52: 250 | O52: 250 | P52: 250 | Q52: 250 | R52: 250 | S52: 250 | T52: 250 | U52: 250 | V52: 250 | W52: 250 | X52: 250 | Y52: 250 | Z52: 250 | AA52: 250 | AB52: 250 | AC52: 250 | AD52: 250 | AE52: 250 | AF52: 250 | AG52: 250 | AH52: 250 | AI52: 250 | AJ52: 250 | AK52: 250 | AL52: 250 | AM52: 250 | AN52: 250 | AO52: 250 | AP52: 250 | AQ52: 250 | AR52: 250 | AS52: 250 | AT52: 250 | AU52: 250 | AV52: 250 | AW52: 250 | AX52: 250 | AY52: 250 | AZ52: 250 | BA52: 250 | BB52: 250 | BC52: 250 | BD52: 250 | BE52: 250 | BF52: 250 | BG52: 250 | BH52: 250 | BI52: 250 | BJ52: 250
A53: Cost | C53: =C51*C52 -> 1500 | D53: =D51*D52 -> 1500 | E53: =E51*E52 -> 1500 | F53: =F51*F52 -> 1500 | G53: =G51*G52 -> 1500 | H53: =H51*H52 -> 1750 | I53: =I51*I52 -> 1750 | J53: =J51*J52 -> 1750 | ... BJ53: =BJ51*BJ52 -> 10000
...

Sheet Sheet6

Sheet Sheet7

Sheet Sheet8
